pyxis: importing docker image: doduo2.umcn.nl#rubenvdw/train_monai:v1.3
pyxis: imported docker image: doduo2.umcn.nl#rubenvdw/train_monai:v1.3
[I 2024-11-04 09:26:02.970 ServerApp] Package jupyterlab took 0.0000s to import
[I 2024-11-04 09:26:02.980 ServerApp] Package jupyter_lsp took 0.0095s to import
[W 2024-11-04 09:26:02.980 ServerApp] A `_jupyter_server_extension_points` function was not found in jupyter_lsp. Instead, a `_jupyter_server_extension_paths` function was found and will be used for now. This function name will be deprecated in future releases of Jupyter Server.
[I 2024-11-04 09:26:02.984 ServerApp] Package jupyter_server_terminals took 0.0039s to import
[I 2024-11-04 09:26:02.984 ServerApp] Package notebook_shim took 0.0000s to import
[W 2024-11-04 09:26:02.984 ServerApp] A `_jupyter_server_extension_points` function was not found in notebook_shim. Instead, a `_jupyter_server_extension_paths` function was found and will be used for now. This function name will be deprecated in future releases of Jupyter Server.
[I 2024-11-04 09:26:02.985 ServerApp] jupyter_lsp | extension was successfully linked.
[I 2024-11-04 09:26:02.988 ServerApp] jupyter_server_terminals | extension was successfully linked.
[I 2024-11-04 09:26:02.993 ServerApp] jupyterlab | extension was successfully linked.
[I 2024-11-04 09:26:03.221 ServerApp] notebook_shim | extension was successfully linked.
[I 2024-11-04 09:26:03.235 ServerApp] notebook_shim | extension was successfully loaded.
[I 2024-11-04 09:26:03.238 ServerApp] jupyter_lsp | extension was successfully loaded.
[I 2024-11-04 09:26:03.239 ServerApp] jupyter_server_terminals | extension was successfully loaded.
[I 2024-11-04 09:26:03.240 LabApp] JupyterLab extension loaded from /usr/local/lib/python3.11/site-packages/jupyterlab
[I 2024-11-04 09:26:03.240 LabApp] JupyterLab application directory is /usr/local/share/jupyter/lab
[I 2024-11-04 09:26:03.240 LabApp] Extension Manager is 'pypi'.
[I 2024-11-04 09:26:03.242 ServerApp] jupyterlab | extension was successfully loaded.
[I 2024-11-04 09:26:03.243 ServerApp] Serving notebooks from local directory: /data/diag/rubenvdw/nnunetv2/nnUNet
[I 2024-11-04 09:26:03.243 ServerApp] Jupyter Server 2.5.0 is running at:
[I 2024-11-04 09:26:03.243 ServerApp] http://dlc-arceus:8888/lab?token=47fd42dc6e1af8c1d5e86a4c0f5eb44986cf27d284c11963
[I 2024-11-04 09:26:03.243 ServerApp]     http://127.0.0.1:8888/lab?token=47fd42dc6e1af8c1d5e86a4c0f5eb44986cf27d284c11963
[I 2024-11-04 09:26:03.243 ServerApp] Use Control-C to stop this server and shut down all kernels (twice to skip confirmation).
[C 2024-11-04 09:26:03.323 ServerApp] 
    
    To access the server, open this file in a browser:
        file:///home/joskevanderzande/.local/share/jupyter/runtime/jpserver-1167816-open.html
    Or copy and paste one of these URLs:
        http://dlc-arceus:8888/lab?token=47fd42dc6e1af8c1d5e86a4c0f5eb44986cf27d284c11963
        http://127.0.0.1:8888/lab?token=47fd42dc6e1af8c1d5e86a4c0f5eb44986cf27d284c11963
[I 2024-11-04 09:26:03.345 ServerApp] Skipped non-installed server(s): bash-language-server, dockerfile-language-server-nodejs, javascript-typescript-langserver, jedi-language-server, julia-language-server, pyright, python-language-server, python-lsp-server, r-languageserver, sql-language-server, texlab, typescript-language-server, unified-language-server, vscode-css-languageserver-bin, vscode-html-languageserver-bin, vscode-json-languageserver-bin, yaml-language-server
[I 2024-11-04 09:26:12.014 LabApp] Generating new user for token-authenticated request: 555fb6ac53bf4e10ba9b6608c1a279b6
0.00s - Debugger warning: It seems that frozen modules are being used, which may
0.00s - make the debugger miss breakpoints. Please pass -Xfrozen_modules=off
0.00s - to python to disable frozen modules.
0.00s - Note: Debugging will proceed. Set PYDEVD_DISABLE_FILE_VALIDATION=1 to disable this validation.
[W 2024-11-04 09:26:14.232 LabApp] Could not determine jupyterlab build status without nodejs
[W 2024-11-04 09:26:14.445 ServerApp] 404 GET /api/contents/Untitled1.ipynb?content=0&1730712374468 (10.76.5.169): No such file or directory: Untitled1.ipynb
[W 2024-11-04 09:26:14.446 ServerApp] wrote error: 'No such file or directory: Untitled1.ipynb'
    Traceback (most recent call last):
      File "/usr/local/lib/python3.11/site-packages/tornado/web.py", line 1786, in _execute
        result = await result
                 ^^^^^^^^^^^^
      File "/usr/local/lib/python3.11/site-packages/jupyter_server/services/contents/handlers.py", line 121, in get
        model = await ensure_async(
                ^^^^^^^^^^^^^^^^^^^
      File "/usr/local/lib/python3.11/site-packages/jupyter_core/utils/__init__.py", line 182, in ensure_async
        result = await obj
                 ^^^^^^^^^
      File "/usr/local/lib/python3.11/site-packages/jupyter_server/services/contents/filemanager.py", line 877, in get
        raise web.HTTPError(404, "No such file or directory: %s" % path)
    tornado.web.HTTPError: HTTP 404: Not Found (No such file or directory: Untitled1.ipynb)
[W 2024-11-04 09:26:14.447 ServerApp] 404 GET /api/contents/Untitled1.ipynb?content=0&1730712374468 (555fb6ac53bf4e10ba9b6608c1a279b6@10.76.5.169) 4.42ms referer=http://dlc-arceus:8888/lab
[I 2024-11-04 09:26:16.789 ServerApp] New terminal with automatic name: 1
slurmstepd: error: *** JOB 106200 ON dlc-arceus CANCELLED AT 2024-11-04T09:29:09 ***
[W 2024-11-04 09:29:13.676 ServerApp] 404 GET /api/contents?content=1&1730712553696 (10.76.5.169): No such file or directory: 
[W 2024-11-04 09:29:13.676 ServerApp] wrote error: 'No such file or directory: '
    Traceback (most recent call last):
      File "/usr/local/lib/python3.11/site-packages/tornado/web.py", line 1786, in _execute
      File "/usr/local/lib/python3.11/site-packages/jupyter_server/services/contents/handlers.py", line 121, in get
        model = await ensure_async(
                ^^^^^^^^^^^^^^^^^^^
      File "/usr/local/lib/python3.11/site-packages/jupyter_core/utils/__init__.py", line 182, in ensure_async
      File "/usr/local/lib/python3.11/site-packages/jupyter_server/services/contents/filemanager.py", line 877, in get
        raise web.HTTPError(404, "No such file or directory: %s" % path)
    tornado.web.HTTPError: HTTP 404: Not Found (No such file or directory: )
[W 2024-11-04 09:29:13.678 ServerApp] 404 GET /api/contents?content=1&1730712553696 (555fb6ac53bf4e10ba9b6608c1a279b6@10.76.5.169) 2.70ms referer=http://dlc-arceus:8888/lab
[W 2024-11-04 09:29:13.715 ServerApp] 404 GET /api/contents?content=1&1730712553735 (10.76.5.169): No such file or directory: 
[W 2024-11-04 09:29:13.715 ServerApp] wrote error: 'No such file or directory: '
    Traceback (most recent call last):
      File "/usr/local/lib/python3.11/site-packages/tornado/web.py", line 1786, in _execute
      File "/usr/local/lib/python3.11/site-packages/jupyter_server/services/contents/handlers.py", line 121, in get
        model = await ensure_async(
                ^^^^^^^^^^^^^^^^^^^
      File "/usr/local/lib/python3.11/site-packages/jupyter_core/utils/__init__.py", line 182, in ensure_async
      File "/usr/local/lib/python3.11/site-packages/jupyter_server/services/contents/filemanager.py", line 877, in get
        raise web.HTTPError(404, "No such file or directory: %s" % path)
    tornado.web.HTTPError: HTTP 404: Not Found (No such file or directory: )
[W 2024-11-04 09:29:13.716 ServerApp] 404 GET /api/contents?content=1&1730712553735 (555fb6ac53bf4e10ba9b6608c1a279b6@10.76.5.169) 1.97ms referer=http://dlc-arceus:8888/lab
[W 2024-11-04 09:29:13.742 ServerApp] 404 GET /api/contents?content=1&1730712553762 (10.76.5.169): No such file or directory: 
[W 2024-11-04 09:29:13.749 ServerApp] wrote error: 'No such file or directory: '
    Traceback (most recent call last):
      File "/usr/local/lib/python3.11/site-packages/tornado/web.py", line 1786, in _execute
      File "/usr/local/lib/python3.11/site-packages/jupyter_server/services/contents/handlers.py", line 121, in get
        model = await ensure_async(
                ^^^^^^^^^^^^^^^^^^^
      File "/usr/local/lib/python3.11/site-packages/jupyter_core/utils/__init__.py", line 182, in ensure_async
      File "/usr/local/lib/python3.11/site-packages/jupyter_server/services/contents/filemanager.py", line 877, in get
        raise web.HTTPError(404, "No such file or directory: %s" % path)
    tornado.web.HTTPError: HTTP 404: Not Found (No such file or directory: )
[W 2024-11-04 09:29:13.754 ServerApp] 404 GET /api/contents?content=1&1730712553762 (555fb6ac53bf4e10ba9b6608c1a279b6@10.76.5.169) 12.78ms referer=http://dlc-arceus:8888/lab
[W 2024-11-04 09:29:13.774 ServerApp] 404 GET /api/contents?content=1&1730712553794 (10.76.5.169): No such file or directory: 
[W 2024-11-04 09:29:13.774 ServerApp] wrote error: 'No such file or directory: '
    Traceback (most recent call last):
      File "/usr/local/lib/python3.11/site-packages/tornado/web.py", line 1786, in _execute
      File "/usr/local/lib/python3.11/site-packages/jupyter_server/services/contents/handlers.py", line 121, in get
        model = await ensure_async(
                ^^^^^^^^^^^^^^^^^^^
      File "/usr/local/lib/python3.11/site-packages/jupyter_core/utils/__init__.py", line 182, in ensure_async
      File "/usr/local/lib/python3.11/site-packages/jupyter_server/services/contents/filemanager.py", line 877, in get
        raise web.HTTPError(404, "No such file or directory: %s" % path)
    tornado.web.HTTPError: HTTP 404: Not Found (No such file or directory: )
[W 2024-11-04 09:29:13.776 ServerApp] 404 GET /api/contents?content=1&1730712553794 (555fb6ac53bf4e10ba9b6608c1a279b6@10.76.5.169) 2.19ms referer=http://dlc-arceus:8888/lab
[W 2024-11-04 09:29:13.796 ServerApp] 404 GET /api/contents?content=1&1730712553818 (10.76.5.169): No such file or directory: 
[W 2024-11-04 09:29:13.797 ServerApp] wrote error: 'No such file or directory: '
    Traceback (most recent call last):
      File "/usr/local/lib/python3.11/site-packages/tornado/web.py", line 1786, in _execute
      File "/usr/local/lib/python3.11/site-packages/jupyter_server/services/contents/handlers.py", line 121, in get
        model = await ensure_async(
                ^^^^^^^^^^^^^^^^^^^
      File "/usr/local/lib/python3.11/site-packages/jupyter_core/utils/__init__.py", line 182, in ensure_async
      File "/usr/local/lib/python3.11/site-packages/jupyter_server/services/contents/filemanager.py", line 877, in get
        raise web.HTTPError(404, "No such file or directory: %s" % path)
    tornado.web.HTTPError: HTTP 404: Not Found (No such file or directory: )
[W 2024-11-04 09:29:13.797 ServerApp] 404 GET /api/contents?content=1&1730712553818 (555fb6ac53bf4e10ba9b6608c1a279b6@10.76.5.169) 1.49ms referer=http://dlc-arceus:8888/lab
[W 2024-11-04 09:29:13.824 ServerApp] 404 GET /api/contents?content=1&1730712553844 (10.76.5.169): No such file or directory: 
[W 2024-11-04 09:29:13.824 ServerApp] wrote error: 'No such file or directory: '
    Traceback (most recent call last):
      File "/usr/local/lib/python3.11/site-packages/tornado/web.py", line 1786, in _execute
      File "/usr/local/lib/python3.11/site-packages/jupyter_server/services/contents/handlers.py", line 121, in get
        model = await ensure_async(
                ^^^^^^^^^^^^^^^^^^^
      File "/usr/local/lib/python3.11/site-packages/jupyter_core/utils/__init__.py", line 182, in ensure_async
      File "/usr/local/lib/python3.11/site-packages/jupyter_server/services/contents/filemanager.py", line 877, in get
        raise web.HTTPError(404, "No such file or directory: %s" % path)
    tornado.web.HTTPError: HTTP 404: Not Found (No such file or directory: )
[W 2024-11-04 09:29:13.825 ServerApp] 404 GET /api/contents?content=1&1730712553844 (555fb6ac53bf4e10ba9b6608c1a279b6@10.76.5.169) 1.52ms referer=http://dlc-arceus:8888/lab
[W 2024-11-04 09:29:13.845 ServerApp] 404 GET /api/contents?content=1&1730712553866 (10.76.5.169): No such file or directory: 
[W 2024-11-04 09:29:13.846 ServerApp] wrote error: 'No such file or directory: '
    Traceback (most recent call last):
      File "/usr/local/lib/python3.11/site-packages/tornado/web.py", line 1786, in _execute
      File "/usr/local/lib/python3.11/site-packages/jupyter_server/services/contents/handlers.py", line 121, in get
        model = await ensure_async(
                ^^^^^^^^^^^^^^^^^^^
      File "/usr/local/lib/python3.11/site-packages/jupyter_core/utils/__init__.py", line 182, in ensure_async
      File "/usr/local/lib/python3.11/site-packages/jupyter_server/services/contents/filemanager.py", line 877, in get
        raise web.HTTPError(404, "No such file or directory: %s" % path)
    tornado.web.HTTPError: HTTP 404: Not Found (No such file or directory: )
[W 2024-11-04 09:29:13.846 ServerApp] 404 GET /api/contents?content=1&1730712553866 (555fb6ac53bf4e10ba9b6608c1a279b6@10.76.5.169) 1.64ms referer=http://dlc-arceus:8888/lab
[W 2024-11-04 09:29:13.867 ServerApp] 404 GET /api/contents?content=1&1730712553887 (10.76.5.169): No such file or directory: 
[W 2024-11-04 09:29:13.868 ServerApp] wrote error: 'No such file or directory: '
    Traceback (most recent call last):
      File "/usr/local/lib/python3.11/site-packages/tornado/web.py", line 1786, in _execute
      File "/usr/local/lib/python3.11/site-packages/jupyter_server/services/contents/handlers.py", line 121, in get
        model = await ensure_async(
                ^^^^^^^^^^^^^^^^^^^
      File "/usr/local/lib/python3.11/site-packages/jupyter_core/utils/__init__.py", line 182, in ensure_async
      File "/usr/local/lib/python3.11/site-packages/jupyter_server/services/contents/filemanager.py", line 877, in get
        raise web.HTTPError(404, "No such file or directory: %s" % path)
    tornado.web.HTTPError: HTTP 404: Not Found (No such file or directory: )
[W 2024-11-04 09:29:13.868 ServerApp] 404 GET /api/contents?content=1&1730712553887 (555fb6ac53bf4e10ba9b6608c1a279b6@10.76.5.169) 1.65ms referer=http://dlc-arceus:8888/lab
[W 2024-11-04 09:29:13.892 ServerApp] 404 GET /api/contents?content=1&1730712553910 (10.76.5.169): No such file or directory: 
[W 2024-11-04 09:29:13.892 ServerApp] wrote error: 'No such file or directory: '
    Traceback (most recent call last):
      File "/usr/local/lib/python3.11/site-packages/tornado/web.py", line 1786, in _execute
      File "/usr/local/lib/python3.11/site-packages/jupyter_server/services/contents/handlers.py", line 121, in get
        model = await ensure_async(
                ^^^^^^^^^^^^^^^^^^^
      File "/usr/local/lib/python3.11/site-packages/jupyter_core/utils/__init__.py", line 182, in ensure_async
      File "/usr/local/lib/python3.11/site-packages/jupyter_server/services/contents/filemanager.py", line 877, in get
        raise web.HTTPError(404, "No such file or directory: %s" % path)
    tornado.web.HTTPError: HTTP 404: Not Found (No such file or directory: )
[W 2024-11-04 09:29:13.893 ServerApp] 404 GET /api/contents?content=1&1730712553910 (555fb6ac53bf4e10ba9b6608c1a279b6@10.76.5.169) 1.72ms referer=http://dlc-arceus:8888/lab
[W 2024-11-04 09:29:13.912 ServerApp] 404 GET /api/contents?content=1&1730712553934 (10.76.5.169): No such file or directory: 
[W 2024-11-04 09:29:13.913 ServerApp] wrote error: 'No such file or directory: '
    Traceback (most recent call last):
      File "/usr/local/lib/python3.11/site-packages/tornado/web.py", line 1786, in _execute
      File "/usr/local/lib/python3.11/site-packages/jupyter_server/services/contents/handlers.py", line 121, in get
        model = await ensure_async(
                ^^^^^^^^^^^^^^^^^^^
      File "/usr/local/lib/python3.11/site-packages/jupyter_core/utils/__init__.py", line 182, in ensure_async
      File "/usr/local/lib/python3.11/site-packages/jupyter_server/services/contents/filemanager.py", line 877, in get
        raise web.HTTPError(404, "No such file or directory: %s" % path)
    tornado.web.HTTPError: HTTP 404: Not Found (No such file or directory: )
[W 2024-11-04 09:29:13.914 ServerApp] 404 GET /api/contents?content=1&1730712553934 (555fb6ac53bf4e10ba9b6608c1a279b6@10.76.5.169) 1.65ms referer=http://dlc-arceus:8888/lab
[W 2024-11-04 09:29:13.932 ServerApp] 404 GET /api/contents?content=1&1730712553954 (10.76.5.169): No such file or directory: 
[W 2024-11-04 09:29:13.933 ServerApp] wrote error: 'No such file or directory: '
    Traceback (most recent call last):
      File "/usr/local/lib/python3.11/site-packages/tornado/web.py", line 1786, in _execute
      File "/usr/local/lib/python3.11/site-packages/jupyter_server/services/contents/handlers.py", line 121, in get
        model = await ensure_async(
                ^^^^^^^^^^^^^^^^^^^
      File "/usr/local/lib/python3.11/site-packages/jupyter_core/utils/__init__.py", line 182, in ensure_async
      File "/usr/local/lib/python3.11/site-packages/jupyter_server/services/contents/filemanager.py", line 877, in get
        raise web.HTTPError(404, "No such file or directory: %s" % path)
    tornado.web.HTTPError: HTTP 404: Not Found (No such file or directory: )
[W 2024-11-04 09:29:13.933 ServerApp] 404 GET /api/contents?content=1&1730712553954 (555fb6ac53bf4e10ba9b6608c1a279b6@10.76.5.169) 1.45ms referer=http://dlc-arceus:8888/lab
[W 2024-11-04 09:29:13.952 ServerApp] 404 GET /api/contents?content=1&1730712553974 (10.76.5.169): No such file or directory: 
[W 2024-11-04 09:29:13.952 ServerApp] wrote error: 'No such file or directory: '
    Traceback (most recent call last):
      File "/usr/local/lib/python3.11/site-packages/tornado/web.py", line 1786, in _execute
      File "/usr/local/lib/python3.11/site-packages/jupyter_server/services/contents/handlers.py", line 121, in get
        model = await ensure_async(
                ^^^^^^^^^^^^^^^^^^^
      File "/usr/local/lib/python3.11/site-packages/jupyter_core/utils/__init__.py", line 182, in ensure_async
      File "/usr/local/lib/python3.11/site-packages/jupyter_server/services/contents/filemanager.py", line 877, in get
        raise web.HTTPError(404, "No such file or directory: %s" % path)
    tornado.web.HTTPError: HTTP 404: Not Found (No such file or directory: )
[W 2024-11-04 09:29:13.953 ServerApp] 404 GET /api/contents?content=1&1730712553974 (555fb6ac53bf4e10ba9b6608c1a279b6@10.76.5.169) 1.67ms referer=http://dlc-arceus:8888/lab
[W 2024-11-04 09:29:13.978 ServerApp] 404 GET /api/contents?content=1&1730712553998 (10.76.5.169): No such file or directory: 
[W 2024-11-04 09:29:13.978 ServerApp] wrote error: 'No such file or directory: '
    Traceback (most recent call last):
      File "/usr/local/lib/python3.11/site-packages/tornado/web.py", line 1786, in _execute
      File "/usr/local/lib/python3.11/site-packages/jupyter_server/services/contents/handlers.py", line 121, in get
        model = await ensure_async(
                ^^^^^^^^^^^^^^^^^^^
      File "/usr/local/lib/python3.11/site-packages/jupyter_core/utils/__init__.py", line 182, in ensure_async
      File "/usr/local/lib/python3.11/site-packages/jupyter_server/services/contents/filemanager.py", line 877, in get
        raise web.HTTPError(404, "No such file or directory: %s" % path)
    tornado.web.HTTPError: HTTP 404: Not Found (No such file or directory: )
[W 2024-11-04 09:29:13.979 ServerApp] 404 GET /api/contents?content=1&1730712553998 (555fb6ac53bf4e10ba9b6608c1a279b6@10.76.5.169) 1.53ms referer=http://dlc-arceus:8888/lab
[W 2024-11-04 09:29:13.998 ServerApp] 404 GET /api/contents?content=1&1730712554020 (10.76.5.169): No such file or directory: 
[W 2024-11-04 09:29:13.999 ServerApp] wrote error: 'No such file or directory: '
    Traceback (most recent call last):
      File "/usr/local/lib/python3.11/site-packages/tornado/web.py", line 1786, in _execute
      File "/usr/local/lib/python3.11/site-packages/jupyter_server/services/contents/handlers.py", line 121, in get
        model = await ensure_async(
                ^^^^^^^^^^^^^^^^^^^
      File "/usr/local/lib/python3.11/site-packages/jupyter_core/utils/__init__.py", line 182, in ensure_async
      File "/usr/local/lib/python3.11/site-packages/jupyter_server/services/contents/filemanager.py", line 877, in get
        raise web.HTTPError(404, "No such file or directory: %s" % path)
    tornado.web.HTTPError: HTTP 404: Not Found (No such file or directory: )
[W 2024-11-04 09:29:13.999 ServerApp] 404 GET /api/contents?content=1&1730712554020 (555fb6ac53bf4e10ba9b6608c1a279b6@10.76.5.169) 1.77ms referer=http://dlc-arceus:8888/lab
[W 2024-11-04 09:29:14.017 ServerApp] 404 GET /api/contents?content=1&1730712554039 (10.76.5.169): No such file or directory: 
[W 2024-11-04 09:29:14.017 ServerApp] wrote error: 'No such file or directory: '
    Traceback (most recent call last):
      File "/usr/local/lib/python3.11/site-packages/tornado/web.py", line 1786, in _execute
      File "/usr/local/lib/python3.11/site-packages/jupyter_server/services/contents/handlers.py", line 121, in get
        model = await ensure_async(
                ^^^^^^^^^^^^^^^^^^^
      File "/usr/local/lib/python3.11/site-packages/jupyter_core/utils/__init__.py", line 182, in ensure_async
      File "/usr/local/lib/python3.11/site-packages/jupyter_server/services/contents/filemanager.py", line 877, in get
        raise web.HTTPError(404, "No such file or directory: %s" % path)
    tornado.web.HTTPError: HTTP 404: Not Found (No such file or directory: )
[W 2024-11-04 09:29:14.018 ServerApp] 404 GET /api/contents?content=1&1730712554039 (555fb6ac53bf4e10ba9b6608c1a279b6@10.76.5.169) 1.40ms referer=http://dlc-arceus:8888/lab
[W 2024-11-04 09:29:14.034 ServerApp] 404 GET /api/contents?content=1&1730712554057 (10.76.5.169): No such file or directory: 
[W 2024-11-04 09:29:14.034 ServerApp] wrote error: 'No such file or directory: '
    Traceback (most recent call last):
      File "/usr/local/lib/python3.11/site-packages/tornado/web.py", line 1786, in _execute
      File "/usr/local/lib/python3.11/site-packages/jupyter_server/services/contents/handlers.py", line 121, in get
        model = await ensure_async(
                ^^^^^^^^^^^^^^^^^^^
      File "/usr/local/lib/python3.11/site-packages/jupyter_core/utils/__init__.py", line 182, in ensure_async
      File "/usr/local/lib/python3.11/site-packages/jupyter_server/services/contents/filemanager.py", line 877, in get
        raise web.HTTPError(404, "No such file or directory: %s" % path)
    tornado.web.HTTPError: HTTP 404: Not Found (No such file or directory: )
[W 2024-11-04 09:29:14.035 ServerApp] 404 GET /api/contents?content=1&1730712554057 (555fb6ac53bf4e10ba9b6608c1a279b6@10.76.5.169) 1.45ms referer=http://dlc-arceus:8888/lab
[W 2024-11-04 09:29:14.051 ServerApp] 404 GET /api/contents?content=1&1730712554073 (10.76.5.169): No such file or directory: 
[W 2024-11-04 09:29:14.052 ServerApp] wrote error: 'No such file or directory: '
    Traceback (most recent call last):
      File "/usr/local/lib/python3.11/site-packages/tornado/web.py", line 1786, in _execute
      File "/usr/local/lib/python3.11/site-packages/jupyter_server/services/contents/handlers.py", line 121, in get
        model = await ensure_async(
                ^^^^^^^^^^^^^^^^^^^
      File "/usr/local/lib/python3.11/site-packages/jupyter_core/utils/__init__.py", line 182, in ensure_async
      File "/usr/local/lib/python3.11/site-packages/jupyter_server/services/contents/filemanager.py", line 877, in get
        raise web.HTTPError(404, "No such file or directory: %s" % path)
    tornado.web.HTTPError: HTTP 404: Not Found (No such file or directory: )
[W 2024-11-04 09:29:14.052 ServerApp] 404 GET /api/contents?content=1&1730712554073 (555fb6ac53bf4e10ba9b6608c1a279b6@10.76.5.169) 1.36ms referer=http://dlc-arceus:8888/lab
[W 2024-11-04 09:29:14.090 ServerApp] 404 GET /api/contents?content=1&1730712554105 (10.76.5.169): No such file or directory: 
[W 2024-11-04 09:29:14.090 ServerApp] wrote error: 'No such file or directory: '
    Traceback (most recent call last):
      File "/usr/local/lib/python3.11/site-packages/tornado/web.py", line 1786, in _execute
      File "/usr/local/lib/python3.11/site-packages/jupyter_server/services/contents/handlers.py", line 121, in get
        model = await ensure_async(
                ^^^^^^^^^^^^^^^^^^^
      File "/usr/local/lib/python3.11/site-packages/jupyter_core/utils/__init__.py", line 182, in ensure_async
      File "/usr/local/lib/python3.11/site-packages/jupyter_server/services/contents/filemanager.py", line 877, in get
        raise web.HTTPError(404, "No such file or directory: %s" % path)
    tornado.web.HTTPError: HTTP 404: Not Found (No such file or directory: )
[W 2024-11-04 09:29:14.091 ServerApp] 404 GET /api/contents?content=1&1730712554105 (555fb6ac53bf4e10ba9b6608c1a279b6@10.76.5.169) 1.89ms referer=http://dlc-arceus:8888/lab
[W 2024-11-04 09:29:14.112 ServerApp] 404 GET /api/contents?content=1&1730712554134 (10.76.5.169): No such file or directory: 
[W 2024-11-04 09:29:14.112 ServerApp] wrote error: 'No such file or directory: '
    Traceback (most recent call last):
      File "/usr/local/lib/python3.11/site-packages/tornado/web.py", line 1786, in _execute
      File "/usr/local/lib/python3.11/site-packages/jupyter_server/services/contents/handlers.py", line 121, in get
        model = await ensure_async(
                ^^^^^^^^^^^^^^^^^^^
      File "/usr/local/lib/python3.11/site-packages/jupyter_core/utils/__init__.py", line 182, in ensure_async
      File "/usr/local/lib/python3.11/site-packages/jupyter_server/services/contents/filemanager.py", line 877, in get
        raise web.HTTPError(404, "No such file or directory: %s" % path)
    tornado.web.HTTPError: HTTP 404: Not Found (No such file or directory: )
[W 2024-11-04 09:29:14.113 ServerApp] 404 GET /api/contents?content=1&1730712554134 (555fb6ac53bf4e10ba9b6608c1a279b6@10.76.5.169) 1.54ms referer=http://dlc-arceus:8888/lab
[W 2024-11-04 09:29:14.151 ServerApp] 404 GET /api/contents?content=1&1730712554174 (10.76.5.169): No such file or directory: 
[W 2024-11-04 09:29:14.152 ServerApp] wrote error: 'No such file or directory: '
    Traceback (most recent call last):
      File "/usr/local/lib/python3.11/site-packages/tornado/web.py", line 1786, in _execute
      File "/usr/local/lib/python3.11/site-packages/jupyter_server/services/contents/handlers.py", line 121, in get
        model = await ensure_async(
                ^^^^^^^^^^^^^^^^^^^
      File "/usr/local/lib/python3.11/site-packages/jupyter_core/utils/__init__.py", line 182, in ensure_async
      File "/usr/local/lib/python3.11/site-packages/jupyter_server/services/contents/filemanager.py", line 877, in get
        raise web.HTTPError(404, "No such file or directory: %s" % path)
    tornado.web.HTTPError: HTTP 404: Not Found (No such file or directory: )
[W 2024-11-04 09:29:14.153 ServerApp] 404 GET /api/contents?content=1&1730712554174 (555fb6ac53bf4e10ba9b6608c1a279b6@10.76.5.169) 1.79ms referer=http://dlc-arceus:8888/lab
[W 2024-11-04 09:29:14.182 ServerApp] 404 GET /api/contents?content=1&1730712554205 (10.76.5.169): No such file or directory: 
[W 2024-11-04 09:29:14.183 ServerApp] wrote error: 'No such file or directory: '
    Traceback (most recent call last):
      File "/usr/local/lib/python3.11/site-packages/tornado/web.py", line 1786, in _execute
      File "/usr/local/lib/python3.11/site-packages/jupyter_server/services/contents/handlers.py", line 121, in get
        model = await ensure_async(
                ^^^^^^^^^^^^^^^^^^^
      File "/usr/local/lib/python3.11/site-packages/jupyter_core/utils/__init__.py", line 182, in ensure_async
      File "/usr/local/lib/python3.11/site-packages/jupyter_server/services/contents/filemanager.py", line 877, in get
        raise web.HTTPError(404, "No such file or directory: %s" % path)
    tornado.web.HTTPError: HTTP 404: Not Found (No such file or directory: )
[W 2024-11-04 09:29:14.184 ServerApp] 404 GET /api/contents?content=1&1730712554205 (555fb6ac53bf4e10ba9b6608c1a279b6@10.76.5.169) 1.70ms referer=http://dlc-arceus:8888/lab
[W 2024-11-04 09:29:14.206 ServerApp] 404 GET /api/contents?content=1&1730712554228 (10.76.5.169): No such file or directory: 
[W 2024-11-04 09:29:14.206 ServerApp] wrote error: 'No such file or directory: '
    Traceback (most recent call last):
      File "/usr/local/lib/python3.11/site-packages/tornado/web.py", line 1786, in _execute
      File "/usr/local/lib/python3.11/site-packages/jupyter_server/services/contents/handlers.py", line 121, in get
        model = await ensure_async(
                ^^^^^^^^^^^^^^^^^^^
      File "/usr/local/lib/python3.11/site-packages/jupyter_core/utils/__init__.py", line 182, in ensure_async
      File "/usr/local/lib/python3.11/site-packages/jupyter_server/services/contents/filemanager.py", line 877, in get
        raise web.HTTPError(404, "No such file or directory: %s" % path)
    tornado.web.HTTPError: HTTP 404: Not Found (No such file or directory: )
[W 2024-11-04 09:29:14.207 ServerApp] 404 GET /api/contents?content=1&1730712554228 (555fb6ac53bf4e10ba9b6608c1a279b6@10.76.5.169) 1.64ms referer=http://dlc-arceus:8888/lab
[W 2024-11-04 09:29:14.224 ServerApp] 404 GET /api/contents?content=1&1730712554245 (10.76.5.169): No such file or directory: 
[W 2024-11-04 09:29:14.225 ServerApp] wrote error: 'No such file or directory: '
    Traceback (most recent call last):
      File "/usr/local/lib/python3.11/site-packages/tornado/web.py", line 1786, in _execute
      File "/usr/local/lib/python3.11/site-packages/jupyter_server/services/contents/handlers.py", line 121, in get
        model = await ensure_async(
                ^^^^^^^^^^^^^^^^^^^
      File "/usr/local/lib/python3.11/site-packages/jupyter_core/utils/__init__.py", line 182, in ensure_async
      File "/usr/local/lib/python3.11/site-packages/jupyter_server/services/contents/filemanager.py", line 877, in get
        raise web.HTTPError(404, "No such file or directory: %s" % path)
    tornado.web.HTTPError: HTTP 404: Not Found (No such file or directory: )
[W 2024-11-04 09:29:14.226 ServerApp] 404 GET /api/contents?content=1&1730712554245 (555fb6ac53bf4e10ba9b6608c1a279b6@10.76.5.169) 1.62ms referer=http://dlc-arceus:8888/lab
[W 2024-11-04 09:29:14.242 ServerApp] 404 GET /api/contents?content=1&1730712554264 (10.76.5.169): No such file or directory: 
[W 2024-11-04 09:29:14.243 ServerApp] wrote error: 'No such file or directory: '
    Traceback (most recent call last):
      File "/usr/local/lib/python3.11/site-packages/tornado/web.py", line 1786, in _execute
      File "/usr/local/lib/python3.11/site-packages/jupyter_server/services/contents/handlers.py", line 121, in get
        model = await ensure_async(
                ^^^^^^^^^^^^^^^^^^^
      File "/usr/local/lib/python3.11/site-packages/jupyter_core/utils/__init__.py", line 182, in ensure_async
      File "/usr/local/lib/python3.11/site-packages/jupyter_server/services/contents/filemanager.py", line 877, in get
        raise web.HTTPError(404, "No such file or directory: %s" % path)
    tornado.web.HTTPError: HTTP 404: Not Found (No such file or directory: )
[W 2024-11-04 09:29:14.244 ServerApp] 404 GET /api/contents?content=1&1730712554264 (555fb6ac53bf4e10ba9b6608c1a279b6@10.76.5.169) 2.00ms referer=http://dlc-arceus:8888/lab
[W 2024-11-04 09:29:14.265 ServerApp] 404 GET /api/contents?content=1&1730712554286 (10.76.5.169): No such file or directory: 
[W 2024-11-04 09:29:14.265 ServerApp] wrote error: 'No such file or directory: '
    Traceback (most recent call last):
      File "/usr/local/lib/python3.11/site-packages/tornado/web.py", line 1786, in _execute
      File "/usr/local/lib/python3.11/site-packages/jupyter_server/services/contents/handlers.py", line 121, in get
        model = await ensure_async(
                ^^^^^^^^^^^^^^^^^^^
      File "/usr/local/lib/python3.11/site-packages/jupyter_core/utils/__init__.py", line 182, in ensure_async
      File "/usr/local/lib/python3.11/site-packages/jupyter_server/services/contents/filemanager.py", line 877, in get
        raise web.HTTPError(404, "No such file or directory: %s" % path)
    tornado.web.HTTPError: HTTP 404: Not Found (No such file or directory: )
[W 2024-11-04 09:29:14.266 ServerApp] 404 GET /api/contents?content=1&1730712554286 (555fb6ac53bf4e10ba9b6608c1a279b6@10.76.5.169) 1.69ms referer=http://dlc-arceus:8888/lab
[W 2024-11-04 09:29:14.287 ServerApp] 404 GET /api/contents?content=1&1730712554309 (10.76.5.169): No such file or directory: 
[W 2024-11-04 09:29:14.288 ServerApp] wrote error: 'No such file or directory: '
    Traceback (most recent call last):
      File "/usr/local/lib/python3.11/site-packages/tornado/web.py", line 1786, in _execute
      File "/usr/local/lib/python3.11/site-packages/jupyter_server/services/contents/handlers.py", line 121, in get
        model = await ensure_async(
                ^^^^^^^^^^^^^^^^^^^
      File "/usr/local/lib/python3.11/site-packages/jupyter_core/utils/__init__.py", line 182, in ensure_async
      File "/usr/local/lib/python3.11/site-packages/jupyter_server/services/contents/filemanager.py", line 877, in get
        raise web.HTTPError(404, "No such file or directory: %s" % path)
    tornado.web.HTTPError: HTTP 404: Not Found (No such file or directory: )
[W 2024-11-04 09:29:14.289 ServerApp] 404 GET /api/contents?content=1&1730712554309 (555fb6ac53bf4e10ba9b6608c1a279b6@10.76.5.169) 1.85ms referer=http://dlc-arceus:8888/lab
[W 2024-11-04 09:29:14.309 ServerApp] 404 GET /api/contents?content=1&1730712554330 (10.76.5.169): No such file or directory: 
[W 2024-11-04 09:29:14.310 ServerApp] wrote error: 'No such file or directory: '
    Traceback (most recent call last):
      File "/usr/local/lib/python3.11/site-packages/tornado/web.py", line 1786, in _execute
      File "/usr/local/lib/python3.11/site-packages/jupyter_server/services/contents/handlers.py", line 121, in get
        model = await ensure_async(
                ^^^^^^^^^^^^^^^^^^^
      File "/usr/local/lib/python3.11/site-packages/jupyter_core/utils/__init__.py", line 182, in ensure_async
      File "/usr/local/lib/python3.11/site-packages/jupyter_server/services/contents/filemanager.py", line 877, in get
        raise web.HTTPError(404, "No such file or directory: %s" % path)
    tornado.web.HTTPError: HTTP 404: Not Found (No such file or directory: )
[W 2024-11-04 09:29:14.311 ServerApp] 404 GET /api/contents?content=1&1730712554330 (555fb6ac53bf4e10ba9b6608c1a279b6@10.76.5.169) 2.16ms referer=http://dlc-arceus:8888/lab
[W 2024-11-04 09:29:14.333 ServerApp] 404 GET /api/contents?content=1&1730712554352 (10.76.5.169): No such file or directory: 
[W 2024-11-04 09:29:14.333 ServerApp] wrote error: 'No such file or directory: '
    Traceback (most recent call last):
      File "/usr/local/lib/python3.11/site-packages/tornado/web.py", line 1786, in _execute
      File "/usr/local/lib/python3.11/site-packages/jupyter_server/services/contents/handlers.py", line 121, in get
        model = await ensure_async(
                ^^^^^^^^^^^^^^^^^^^
      File "/usr/local/lib/python3.11/site-packages/jupyter_core/utils/__init__.py", line 182, in ensure_async
      File "/usr/local/lib/python3.11/site-packages/jupyter_server/services/contents/filemanager.py", line 877, in get
        raise web.HTTPError(404, "No such file or directory: %s" % path)
    tornado.web.HTTPError: HTTP 404: Not Found (No such file or directory: )
[W 2024-11-04 09:29:14.334 ServerApp] 404 GET /api/contents?content=1&1730712554352 (555fb6ac53bf4e10ba9b6608c1a279b6@10.76.5.169) 1.86ms referer=http://dlc-arceus:8888/lab
[W 2024-11-04 09:29:14.355 ServerApp] 404 GET /api/contents?content=1&1730712554377 (10.76.5.169): No such file or directory: 
[W 2024-11-04 09:29:14.356 ServerApp] wrote error: 'No such file or directory: '
    Traceback (most recent call last):
      File "/usr/local/lib/python3.11/site-packages/tornado/web.py", line 1786, in _execute
      File "/usr/local/lib/python3.11/site-packages/jupyter_server/services/contents/handlers.py", line 121, in get
        model = await ensure_async(
                ^^^^^^^^^^^^^^^^^^^
      File "/usr/local/lib/python3.11/site-packages/jupyter_core/utils/__init__.py", line 182, in ensure_async
      File "/usr/local/lib/python3.11/site-packages/jupyter_server/services/contents/filemanager.py", line 877, in get
        raise web.HTTPError(404, "No such file or directory: %s" % path)
    tornado.web.HTTPError: HTTP 404: Not Found (No such file or directory: )
[W 2024-11-04 09:29:14.356 ServerApp] 404 GET /api/contents?content=1&1730712554377 (555fb6ac53bf4e10ba9b6608c1a279b6@10.76.5.169) 1.83ms referer=http://dlc-arceus:8888/lab
[W 2024-11-04 09:29:14.379 ServerApp] 404 GET /api/contents?content=1&1730712554400 (10.76.5.169): No such file or directory: 
[W 2024-11-04 09:29:14.382 ServerApp] wrote error: 'No such file or directory: '
    Traceback (most recent call last):
      File "/usr/local/lib/python3.11/site-packages/tornado/web.py", line 1786, in _execute
      File "/usr/local/lib/python3.11/site-packages/jupyter_server/services/contents/handlers.py", line 121, in get
        model = await ensure_async(
                ^^^^^^^^^^^^^^^^^^^
      File "/usr/local/lib/python3.11/site-packages/jupyter_core/utils/__init__.py", line 182, in ensure_async
      File "/usr/local/lib/python3.11/site-packages/jupyter_server/services/contents/filemanager.py", line 877, in get
        raise web.HTTPError(404, "No such file or directory: %s" % path)
    tornado.web.HTTPError: HTTP 404: Not Found (No such file or directory: )
[W 2024-11-04 09:29:14.383 ServerApp] 404 GET /api/contents?content=1&1730712554400 (555fb6ac53bf4e10ba9b6608c1a279b6@10.76.5.169) 4.43ms referer=http://dlc-arceus:8888/lab
[W 2024-11-04 09:29:14.405 ServerApp] 404 GET /api/contents?content=1&1730712554426 (10.76.5.169): No such file or directory: 
[W 2024-11-04 09:29:14.405 ServerApp] wrote error: 'No such file or directory: '
    Traceback (most recent call last):
      File "/usr/local/lib/python3.11/site-packages/tornado/web.py", line 1786, in _execute
      File "/usr/local/lib/python3.11/site-packages/jupyter_server/services/contents/handlers.py", line 121, in get
        model = await ensure_async(
                ^^^^^^^^^^^^^^^^^^^
      File "/usr/local/lib/python3.11/site-packages/jupyter_core/utils/__init__.py", line 182, in ensure_async
      File "/usr/local/lib/python3.11/site-packages/jupyter_server/services/contents/filemanager.py", line 877, in get
        raise web.HTTPError(404, "No such file or directory: %s" % path)
    tornado.web.HTTPError: HTTP 404: Not Found (No such file or directory: )
[W 2024-11-04 09:29:14.406 ServerApp] 404 GET /api/contents?content=1&1730712554426 (555fb6ac53bf4e10ba9b6608c1a279b6@10.76.5.169) 1.90ms referer=http://dlc-arceus:8888/lab
[W 2024-11-04 09:29:14.428 ServerApp] 404 GET /api/contents?content=1&1730712554447 (10.76.5.169): No such file or directory: 
[W 2024-11-04 09:29:14.432 ServerApp] wrote error: 'No such file or directory: '
    Traceback (most recent call last):
      File "/usr/local/lib/python3.11/site-packages/tornado/web.py", line 1786, in _execute
      File "/usr/local/lib/python3.11/site-packages/jupyter_server/services/contents/handlers.py", line 121, in get
        model = await ensure_async(
                ^^^^^^^^^^^^^^^^^^^
      File "/usr/local/lib/python3.11/site-packages/jupyter_core/utils/__init__.py", line 182, in ensure_async
      File "/usr/local/lib/python3.11/site-packages/jupyter_server/services/contents/filemanager.py", line 877, in get
        raise web.HTTPError(404, "No such file or directory: %s" % path)
    tornado.web.HTTPError: HTTP 404: Not Found (No such file or directory: )
[W 2024-11-04 09:29:14.440 ServerApp] 404 GET /api/contents?content=1&1730712554447 (555fb6ac53bf4e10ba9b6608c1a279b6@10.76.5.169) 12.34ms referer=http://dlc-arceus:8888/lab
[W 2024-11-04 09:29:14.461 ServerApp] 404 GET /api/contents?content=1&1730712554479 (10.76.5.169): No such file or directory: 
[W 2024-11-04 09:29:14.461 ServerApp] wrote error: 'No such file or directory: '
    Traceback (most recent call last):
      File "/usr/local/lib/python3.11/site-packages/tornado/web.py", line 1786, in _execute
      File "/usr/local/lib/python3.11/site-packages/jupyter_server/services/contents/handlers.py", line 121, in get
        model = await ensure_async(
                ^^^^^^^^^^^^^^^^^^^
      File "/usr/local/lib/python3.11/site-packages/jupyter_core/utils/__init__.py", line 182, in ensure_async
      File "/usr/local/lib/python3.11/site-packages/jupyter_server/services/contents/filemanager.py", line 877, in get
        raise web.HTTPError(404, "No such file or directory: %s" % path)
    tornado.web.HTTPError: HTTP 404: Not Found (No such file or directory: )
[W 2024-11-04 09:29:14.462 ServerApp] 404 GET /api/contents?content=1&1730712554479 (555fb6ac53bf4e10ba9b6608c1a279b6@10.76.5.169) 1.85ms referer=http://dlc-arceus:8888/lab
[W 2024-11-04 09:29:14.483 ServerApp] 404 GET /api/contents?content=1&1730712554503 (10.76.5.169): No such file or directory: 
[W 2024-11-04 09:29:14.483 ServerApp] wrote error: 'No such file or directory: '
    Traceback (most recent call last):
      File "/usr/local/lib/python3.11/site-packages/tornado/web.py", line 1786, in _execute
      File "/usr/local/lib/python3.11/site-packages/jupyter_server/services/contents/handlers.py", line 121, in get
        model = await ensure_async(
                ^^^^^^^^^^^^^^^^^^^
      File "/usr/local/lib/python3.11/site-packages/jupyter_core/utils/__init__.py", line 182, in ensure_async
      File "/usr/local/lib/python3.11/site-packages/jupyter_server/services/contents/filemanager.py", line 877, in get
        raise web.HTTPError(404, "No such file or directory: %s" % path)
    tornado.web.HTTPError: HTTP 404: Not Found (No such file or directory: )
[W 2024-11-04 09:29:14.484 ServerApp] 404 GET /api/contents?content=1&1730712554503 (555fb6ac53bf4e10ba9b6608c1a279b6@10.76.5.169) 1.96ms referer=http://dlc-arceus:8888/lab
[W 2024-11-04 09:29:14.504 ServerApp] 404 GET /api/contents?content=1&1730712554525 (10.76.5.169): No such file or directory: 
[W 2024-11-04 09:29:14.504 ServerApp] wrote error: 'No such file or directory: '
    Traceback (most recent call last):
      File "/usr/local/lib/python3.11/site-packages/tornado/web.py", line 1786, in _execute
      File "/usr/local/lib/python3.11/site-packages/jupyter_server/services/contents/handlers.py", line 121, in get
        model = await ensure_async(
                ^^^^^^^^^^^^^^^^^^^
      File "/usr/local/lib/python3.11/site-packages/jupyter_core/utils/__init__.py", line 182, in ensure_async
      File "/usr/local/lib/python3.11/site-packages/jupyter_server/services/contents/filemanager.py", line 877, in get
        raise web.HTTPError(404, "No such file or directory: %s" % path)
    tornado.web.HTTPError: HTTP 404: Not Found (No such file or directory: )
[W 2024-11-04 09:29:14.505 ServerApp] 404 GET /api/contents?content=1&1730712554525 (555fb6ac53bf4e10ba9b6608c1a279b6@10.76.5.169) 1.64ms referer=http://dlc-arceus:8888/lab
[W 2024-11-04 09:29:14.523 ServerApp] 404 GET /api/contents?content=1&1730712554545 (10.76.5.169): No such file or directory: 
[W 2024-11-04 09:29:14.523 ServerApp] wrote error: 'No such file or directory: '
    Traceback (most recent call last):
      File "/usr/local/lib/python3.11/site-packages/tornado/web.py", line 1786, in _execute
      File "/usr/local/lib/python3.11/site-packages/jupyter_server/services/contents/handlers.py", line 121, in get
        model = await ensure_async(
                ^^^^^^^^^^^^^^^^^^^
      File "/usr/local/lib/python3.11/site-packages/jupyter_core/utils/__init__.py", line 182, in ensure_async
      File "/usr/local/lib/python3.11/site-packages/jupyter_server/services/contents/filemanager.py", line 877, in get
        raise web.HTTPError(404, "No such file or directory: %s" % path)
    tornado.web.HTTPError: HTTP 404: Not Found (No such file or directory: )
[W 2024-11-04 09:29:14.524 ServerApp] 404 GET /api/contents?content=1&1730712554545 (555fb6ac53bf4e10ba9b6608c1a279b6@10.76.5.169) 1.72ms referer=http://dlc-arceus:8888/lab
[W 2024-11-04 09:29:14.544 ServerApp] 404 GET /api/contents?content=1&1730712554565 (10.76.5.169): No such file or directory: 
[W 2024-11-04 09:29:14.544 ServerApp] wrote error: 'No such file or directory: '
    Traceback (most recent call last):
      File "/usr/local/lib/python3.11/site-packages/tornado/web.py", line 1786, in _execute
      File "/usr/local/lib/python3.11/site-packages/jupyter_server/services/contents/handlers.py", line 121, in get
      File "/usr/local/lib/python3.11/site-packages/jupyter_core/utils/__init__.py", line 182, in ensure_async
      File "/usr/local/lib/python3.11/site-packages/jupyter_server/services/contents/filemanager.py", line 877, in get
    tornado.web.HTTPError: HTTP 404: Not Found (No such file or directory: )
[W 2024-11-04 09:29:14.545 ServerApp] 404 GET /api/contents?content=1&1730712554565 (555fb6ac53bf4e10ba9b6608c1a279b6@10.76.5.169) 1.47ms referer=http://dlc-arceus:8888/lab
[W 2024-11-04 09:29:14.564 ServerApp] 404 GET /api/contents?content=1&1730712554586 (10.76.5.169): No such file or directory: 
[W 2024-11-04 09:29:14.565 ServerApp] wrote error: 'No such file or directory: '
    Traceback (most recent call last):
      File "/usr/local/lib/python3.11/site-packages/tornado/web.py", line 1786, in _execute
      File "/usr/local/lib/python3.11/site-packages/jupyter_server/services/contents/handlers.py", line 121, in get
      File "/usr/local/lib/python3.11/site-packages/jupyter_core/utils/__init__.py", line 182, in ensure_async
      File "/usr/local/lib/python3.11/site-packages/jupyter_server/services/contents/filemanager.py", line 877, in get
    tornado.web.HTTPError: HTTP 404: Not Found (No such file or directory: )
[W 2024-11-04 09:29:14.566 ServerApp] 404 GET /api/contents?content=1&1730712554586 (555fb6ac53bf4e10ba9b6608c1a279b6@10.76.5.169) 1.69ms referer=http://dlc-arceus:8888/lab
[W 2024-11-04 09:29:14.584 ServerApp] 404 GET /api/contents?content=1&1730712554606 (10.76.5.169): No such file or directory: 
[W 2024-11-04 09:29:14.585 ServerApp] wrote error: 'No such file or directory: '
    Traceback (most recent call last):
      File "/usr/local/lib/python3.11/site-packages/tornado/web.py", line 1786, in _execute
      File "/usr/local/lib/python3.11/site-packages/jupyter_server/services/contents/handlers.py", line 121, in get
      File "/usr/local/lib/python3.11/site-packages/jupyter_core/utils/__init__.py", line 182, in ensure_async
      File "/usr/local/lib/python3.11/site-packages/jupyter_server/services/contents/filemanager.py", line 877, in get
    tornado.web.HTTPError: HTTP 404: Not Found (No such file or directory: )
[W 2024-11-04 09:29:14.585 ServerApp] 404 GET /api/contents?content=1&1730712554606 (555fb6ac53bf4e10ba9b6608c1a279b6@10.76.5.169) 1.38ms referer=http://dlc-arceus:8888/lab
[W 2024-11-04 09:29:14.606 ServerApp] 404 GET /api/contents?content=1&1730712554627 (10.76.5.169): No such file or directory: 
[W 2024-11-04 09:29:14.608 ServerApp] wrote error: 'No such file or directory: '
    Traceback (most recent call last):
      File "/usr/local/lib/python3.11/site-packages/tornado/web.py", line 1786, in _execute
      File "/usr/local/lib/python3.11/site-packages/jupyter_server/services/contents/handlers.py", line 121, in get
      File "/usr/local/lib/python3.11/site-packages/jupyter_core/utils/__init__.py", line 182, in ensure_async
      File "/usr/local/lib/python3.11/site-packages/jupyter_server/services/contents/filemanager.py", line 877, in get
    tornado.web.HTTPError: HTTP 404: Not Found (No such file or directory: )
[W 2024-11-04 09:29:14.608 ServerApp] 404 GET /api/contents?content=1&1730712554627 (555fb6ac53bf4e10ba9b6608c1a279b6@10.76.5.169) 2.45ms referer=http://dlc-arceus:8888/lab
[W 2024-11-04 09:29:14.627 ServerApp] 404 GET /api/contents?content=1&1730712554648 (10.76.5.169): No such file or directory: 
[W 2024-11-04 09:29:14.628 ServerApp] wrote error: 'No such file or directory: '
    Traceback (most recent call last):
      File "/usr/local/lib/python3.11/site-packages/tornado/web.py", line 1786, in _execute
      File "/usr/local/lib/python3.11/site-packages/jupyter_server/services/contents/handlers.py", line 121, in get
      File "/usr/local/lib/python3.11/site-packages/jupyter_core/utils/__init__.py", line 182, in ensure_async
      File "/usr/local/lib/python3.11/site-packages/jupyter_server/services/contents/filemanager.py", line 877, in get
    tornado.web.HTTPError: HTTP 404: Not Found (No such file or directory: )
[W 2024-11-04 09:29:14.628 ServerApp] 404 GET /api/contents?content=1&1730712554648 (555fb6ac53bf4e10ba9b6608c1a279b6@10.76.5.169) 1.40ms referer=http://dlc-arceus:8888/lab
[W 2024-11-04 09:29:14.650 ServerApp] 404 GET /api/contents?content=1&1730712554671 (10.76.5.169): No such file or directory: 
[W 2024-11-04 09:29:14.650 ServerApp] wrote error: 'No such file or directory: '
    Traceback (most recent call last):
      File "/usr/local/lib/python3.11/site-packages/tornado/web.py", line 1786, in _execute
      File "/usr/local/lib/python3.11/site-packages/jupyter_server/services/contents/handlers.py", line 121, in get
      File "/usr/local/lib/python3.11/site-packages/jupyter_core/utils/__init__.py", line 182, in ensure_async
      File "/usr/local/lib/python3.11/site-packages/jupyter_server/services/contents/filemanager.py", line 877, in get
    tornado.web.HTTPError: HTTP 404: Not Found (No such file or directory: )
[W 2024-11-04 09:29:14.651 ServerApp] 404 GET /api/contents?content=1&1730712554671 (555fb6ac53bf4e10ba9b6608c1a279b6@10.76.5.169) 1.59ms referer=http://dlc-arceus:8888/lab
[W 2024-11-04 09:29:14.671 ServerApp] 404 GET /api/contents?content=1&1730712554692 (10.76.5.169): No such file or directory: 
[W 2024-11-04 09:29:14.671 ServerApp] wrote error: 'No such file or directory: '
    Traceback (most recent call last):
      File "/usr/local/lib/python3.11/site-packages/tornado/web.py", line 1786, in _execute
      File "/usr/local/lib/python3.11/site-packages/jupyter_server/services/contents/handlers.py", line 121, in get
      File "/usr/local/lib/python3.11/site-packages/jupyter_core/utils/__init__.py", line 182, in ensure_async
      File "/usr/local/lib/python3.11/site-packages/jupyter_server/services/contents/filemanager.py", line 877, in get
    tornado.web.HTTPError: HTTP 404: Not Found (No such file or directory: )
[W 2024-11-04 09:29:14.673 ServerApp] 404 GET /api/contents?content=1&1730712554692 (555fb6ac53bf4e10ba9b6608c1a279b6@10.76.5.169) 2.56ms referer=http://dlc-arceus:8888/lab
[W 2024-11-04 09:29:14.692 ServerApp] 404 GET /api/contents?content=1&1730712554714 (10.76.5.169): No such file or directory: 
[W 2024-11-04 09:29:14.693 ServerApp] wrote error: 'No such file or directory: '
    Traceback (most recent call last):
      File "/usr/local/lib/python3.11/site-packages/tornado/web.py", line 1786, in _execute
      File "/usr/local/lib/python3.11/site-packages/jupyter_server/services/contents/handlers.py", line 121, in get
      File "/usr/local/lib/python3.11/site-packages/jupyter_core/utils/__init__.py", line 182, in ensure_async
      File "/usr/local/lib/python3.11/site-packages/jupyter_server/services/contents/filemanager.py", line 877, in get
    tornado.web.HTTPError: HTTP 404: Not Found (No such file or directory: )
[W 2024-11-04 09:29:14.694 ServerApp] 404 GET /api/contents?content=1&1730712554714 (555fb6ac53bf4e10ba9b6608c1a279b6@10.76.5.169) 1.75ms referer=http://dlc-arceus:8888/lab
[W 2024-11-04 09:29:14.709 ServerApp] 404 GET /api/contents?content=1&1730712554732 (10.76.5.169): No such file or directory: 
[W 2024-11-04 09:29:14.710 ServerApp] wrote error: 'No such file or directory: '
    Traceback (most recent call last):
      File "/usr/local/lib/python3.11/site-packages/tornado/web.py", line 1786, in _execute
      File "/usr/local/lib/python3.11/site-packages/jupyter_server/services/contents/handlers.py", line 121, in get
      File "/usr/local/lib/python3.11/site-packages/jupyter_core/utils/__init__.py", line 182, in ensure_async
      File "/usr/local/lib/python3.11/site-packages/jupyter_server/services/contents/filemanager.py", line 877, in get
    tornado.web.HTTPError: HTTP 404: Not Found (No such file or directory: )
[W 2024-11-04 09:29:14.711 ServerApp] 404 GET /api/contents?content=1&1730712554732 (555fb6ac53bf4e10ba9b6608c1a279b6@10.76.5.169) 1.47ms referer=http://dlc-arceus:8888/lab
[W 2024-11-04 09:29:14.729 ServerApp] 404 GET /api/contents?content=1&1730712554748 (10.76.5.169): No such file or directory: 
[W 2024-11-04 09:29:14.729 ServerApp] wrote error: 'No such file or directory: '
    Traceback (most recent call last):
      File "/usr/local/lib/python3.11/site-packages/tornado/web.py", line 1786, in _execute
      File "/usr/local/lib/python3.11/site-packages/jupyter_server/services/contents/handlers.py", line 121, in get
      File "/usr/local/lib/python3.11/site-packages/jupyter_core/utils/__init__.py", line 182, in ensure_async
      File "/usr/local/lib/python3.11/site-packages/jupyter_server/services/contents/filemanager.py", line 877, in get
    tornado.web.HTTPError: HTTP 404: Not Found (No such file or directory: )
[W 2024-11-04 09:29:14.730 ServerApp] 404 GET /api/contents?content=1&1730712554748 (555fb6ac53bf4e10ba9b6608c1a279b6@10.76.5.169) 1.42ms referer=http://dlc-arceus:8888/lab
[W 2024-11-04 09:29:14.752 ServerApp] 404 GET /api/contents?content=1&1730712554771 (10.76.5.169): No such file or directory: 
[W 2024-11-04 09:29:14.753 ServerApp] wrote error: 'No such file or directory: '
    Traceback (most recent call last):
      File "/usr/local/lib/python3.11/site-packages/tornado/web.py", line 1786, in _execute
      File "/usr/local/lib/python3.11/site-packages/jupyter_server/services/contents/handlers.py", line 121, in get
      File "/usr/local/lib/python3.11/site-packages/jupyter_core/utils/__init__.py", line 182, in ensure_async
      File "/usr/local/lib/python3.11/site-packages/jupyter_server/services/contents/filemanager.py", line 877, in get
    tornado.web.HTTPError: HTTP 404: Not Found (No such file or directory: )
[W 2024-11-04 09:29:14.753 ServerApp] 404 GET /api/contents?content=1&1730712554771 (555fb6ac53bf4e10ba9b6608c1a279b6@10.76.5.169) 2.10ms referer=http://dlc-arceus:8888/lab
[W 2024-11-04 09:29:14.777 ServerApp] 404 GET /api/contents?content=1&1730712554794 (10.76.5.169): No such file or directory: 
[W 2024-11-04 09:29:14.777 ServerApp] wrote error: 'No such file or directory: '
    Traceback (most recent call last):
      File "/usr/local/lib/python3.11/site-packages/tornado/web.py", line 1786, in _execute
      File "/usr/local/lib/python3.11/site-packages/jupyter_server/services/contents/handlers.py", line 121, in get
      File "/usr/local/lib/python3.11/site-packages/jupyter_core/utils/__init__.py", line 182, in ensure_async
      File "/usr/local/lib/python3.11/site-packages/jupyter_server/services/contents/filemanager.py", line 877, in get
    tornado.web.HTTPError: HTTP 404: Not Found (No such file or directory: )
[W 2024-11-04 09:29:14.778 ServerApp] 404 GET /api/contents?content=1&1730712554794 (555fb6ac53bf4e10ba9b6608c1a279b6@10.76.5.169) 1.57ms referer=http://dlc-arceus:8888/lab
[W 2024-11-04 09:29:14.801 ServerApp] 404 GET /api/contents?content=1&1730712554821 (10.76.5.169): No such file or directory: 
[W 2024-11-04 09:29:14.801 ServerApp] wrote error: 'No such file or directory: '
    Traceback (most recent call last):
      File "/usr/local/lib/python3.11/site-packages/tornado/web.py", line 1786, in _execute
      File "/usr/local/lib/python3.11/site-packages/jupyter_server/services/contents/handlers.py", line 121, in get
      File "/usr/local/lib/python3.11/site-packages/jupyter_core/utils/__init__.py", line 182, in ensure_async
      File "/usr/local/lib/python3.11/site-packages/jupyter_server/services/contents/filemanager.py", line 877, in get
    tornado.web.HTTPError: HTTP 404: Not Found (No such file or directory: )
[W 2024-11-04 09:29:14.802 ServerApp] 404 GET /api/contents?content=1&1730712554821 (555fb6ac53bf4e10ba9b6608c1a279b6@10.76.5.169) 1.50ms referer=http://dlc-arceus:8888/lab
[W 2024-11-04 09:29:14.826 ServerApp] 404 GET /api/contents?content=1&1730712554844 (10.76.5.169): No such file or directory: 
[W 2024-11-04 09:29:14.826 ServerApp] wrote error: 'No such file or directory: '
    Traceback (most recent call last):
      File "/usr/local/lib/python3.11/site-packages/tornado/web.py", line 1786, in _execute
      File "/usr/local/lib/python3.11/site-packages/jupyter_server/services/contents/handlers.py", line 121, in get
      File "/usr/local/lib/python3.11/site-packages/jupyter_core/utils/__init__.py", line 182, in ensure_async
      File "/usr/local/lib/python3.11/site-packages/jupyter_server/services/contents/filemanager.py", line 877, in get
    tornado.web.HTTPError: HTTP 404: Not Found (No such file or directory: )
[W 2024-11-04 09:29:14.827 ServerApp] 404 GET /api/contents?content=1&1730712554844 (555fb6ac53bf4e10ba9b6608c1a279b6@10.76.5.169) 1.62ms referer=http://dlc-arceus:8888/lab
[W 2024-11-04 09:29:14.845 ServerApp] 404 GET /api/contents?content=1&1730712554867 (10.76.5.169): No such file or directory: 
[W 2024-11-04 09:29:14.846 ServerApp] wrote error: 'No such file or directory: '
    Traceback (most recent call last):
      File "/usr/local/lib/python3.11/site-packages/tornado/web.py", line 1786, in _execute
      File "/usr/local/lib/python3.11/site-packages/jupyter_server/services/contents/handlers.py", line 121, in get
      File "/usr/local/lib/python3.11/site-packages/jupyter_core/utils/__init__.py", line 182, in ensure_async
      File "/usr/local/lib/python3.11/site-packages/jupyter_server/services/contents/filemanager.py", line 877, in get
    tornado.web.HTTPError: HTTP 404: Not Found (No such file or directory: )
[W 2024-11-04 09:29:14.846 ServerApp] 404 GET /api/contents?content=1&1730712554867 (555fb6ac53bf4e10ba9b6608c1a279b6@10.76.5.169) 1.60ms referer=http://dlc-arceus:8888/lab
[W 2024-11-04 09:29:14.869 ServerApp] 404 GET /api/contents?content=1&1730712554888 (10.76.5.169): No such file or directory: 
[W 2024-11-04 09:29:14.870 ServerApp] wrote error: 'No such file or directory: '
    Traceback (most recent call last):
      File "/usr/local/lib/python3.11/site-packages/tornado/web.py", line 1786, in _execute
      File "/usr/local/lib/python3.11/site-packages/jupyter_server/services/contents/handlers.py", line 121, in get
      File "/usr/local/lib/python3.11/site-packages/jupyter_core/utils/__init__.py", line 182, in ensure_async
      File "/usr/local/lib/python3.11/site-packages/jupyter_server/services/contents/filemanager.py", line 877, in get
    tornado.web.HTTPError: HTTP 404: Not Found (No such file or directory: )
[W 2024-11-04 09:29:14.870 ServerApp] 404 GET /api/contents?content=1&1730712554888 (555fb6ac53bf4e10ba9b6608c1a279b6@10.76.5.169) 1.48ms referer=http://dlc-arceus:8888/lab
[W 2024-11-04 09:29:14.890 ServerApp] 404 GET /api/contents?content=1&1730712554911 (10.76.5.169): No such file or directory: 
[W 2024-11-04 09:29:14.890 ServerApp] wrote error: 'No such file or directory: '
    Traceback (most recent call last):
      File "/usr/local/lib/python3.11/site-packages/tornado/web.py", line 1786, in _execute
      File "/usr/local/lib/python3.11/site-packages/jupyter_server/services/contents/handlers.py", line 121, in get
      File "/usr/local/lib/python3.11/site-packages/jupyter_core/utils/__init__.py", line 182, in ensure_async
      File "/usr/local/lib/python3.11/site-packages/jupyter_server/services/contents/filemanager.py", line 877, in get
    tornado.web.HTTPError: HTTP 404: Not Found (No such file or directory: )
[W 2024-11-04 09:29:14.891 ServerApp] 404 GET /api/contents?content=1&1730712554911 (555fb6ac53bf4e10ba9b6608c1a279b6@10.76.5.169) 1.44ms referer=http://dlc-arceus:8888/lab
[W 2024-11-04 09:29:14.912 ServerApp] 404 GET /api/contents?content=1&1730712554932 (10.76.5.169): No such file or directory: 
[W 2024-11-04 09:29:14.914 ServerApp] wrote error: 'No such file or directory: '
    Traceback (most recent call last):
      File "/usr/local/lib/python3.11/site-packages/tornado/web.py", line 1786, in _execute
      File "/usr/local/lib/python3.11/site-packages/jupyter_server/services/contents/handlers.py", line 121, in get
      File "/usr/local/lib/python3.11/site-packages/jupyter_core/utils/__init__.py", line 182, in ensure_async
      File "/usr/local/lib/python3.11/site-packages/jupyter_server/services/contents/filemanager.py", line 877, in get
    tornado.web.HTTPError: HTTP 404: Not Found (No such file or directory: )
[W 2024-11-04 09:29:14.914 ServerApp] 404 GET /api/contents?content=1&1730712554932 (555fb6ac53bf4e10ba9b6608c1a279b6@10.76.5.169) 3.00ms referer=http://dlc-arceus:8888/lab
[W 2024-11-04 09:29:14.936 ServerApp] 404 GET /api/contents?content=1&1730712554956 (10.76.5.169): No such file or directory: 
[W 2024-11-04 09:29:14.936 ServerApp] wrote error: 'No such file or directory: '
    Traceback (most recent call last):
      File "/usr/local/lib/python3.11/site-packages/tornado/web.py", line 1786, in _execute
      File "/usr/local/lib/python3.11/site-packages/jupyter_server/services/contents/handlers.py", line 121, in get
      File "/usr/local/lib/python3.11/site-packages/jupyter_core/utils/__init__.py", line 182, in ensure_async
      File "/usr/local/lib/python3.11/site-packages/jupyter_server/services/contents/filemanager.py", line 877, in get
    tornado.web.HTTPError: HTTP 404: Not Found (No such file or directory: )
[W 2024-11-04 09:29:14.937 ServerApp] 404 GET /api/contents?content=1&1730712554956 (555fb6ac53bf4e10ba9b6608c1a279b6@10.76.5.169) 1.40ms referer=http://dlc-arceus:8888/lab
[W 2024-11-04 09:29:14.953 ServerApp] 404 GET /api/contents?content=1&1730712554976 (10.76.5.169): No such file or directory: 
[W 2024-11-04 09:29:14.954 ServerApp] wrote error: 'No such file or directory: '
    Traceback (most recent call last):
      File "/usr/local/lib/python3.11/site-packages/tornado/web.py", line 1786, in _execute
      File "/usr/local/lib/python3.11/site-packages/jupyter_server/services/contents/handlers.py", line 121, in get
      File "/usr/local/lib/python3.11/site-packages/jupyter_core/utils/__init__.py", line 182, in ensure_async
      File "/usr/local/lib/python3.11/site-packages/jupyter_server/services/contents/filemanager.py", line 877, in get
    tornado.web.HTTPError: HTTP 404: Not Found (No such file or directory: )
[W 2024-11-04 09:29:14.954 ServerApp] 404 GET /api/contents?content=1&1730712554976 (555fb6ac53bf4e10ba9b6608c1a279b6@10.76.5.169) 1.83ms referer=http://dlc-arceus:8888/lab
[W 2024-11-04 09:29:14.973 ServerApp] 404 GET /api/contents?content=1&1730712554995 (10.76.5.169): No such file or directory: 
[W 2024-11-04 09:29:14.977 ServerApp] wrote error: 'No such file or directory: '
    Traceback (most recent call last):
      File "/usr/local/lib/python3.11/site-packages/tornado/web.py", line 1786, in _execute
      File "/usr/local/lib/python3.11/site-packages/jupyter_server/services/contents/handlers.py", line 121, in get
      File "/usr/local/lib/python3.11/site-packages/jupyter_core/utils/__init__.py", line 182, in ensure_async
      File "/usr/local/lib/python3.11/site-packages/jupyter_server/services/contents/filemanager.py", line 877, in get
    tornado.web.HTTPError: HTTP 404: Not Found (No such file or directory: )
[W 2024-11-04 09:29:14.981 ServerApp] 404 GET /api/contents?content=1&1730712554995 (555fb6ac53bf4e10ba9b6608c1a279b6@10.76.5.169) 8.12ms referer=http://dlc-arceus:8888/lab
[W 2024-11-04 09:29:15.003 ServerApp] 404 GET /api/contents?content=1&1730712555022 (10.76.5.169): No such file or directory: 
[W 2024-11-04 09:29:15.003 ServerApp] wrote error: 'No such file or directory: '
    Traceback (most recent call last):
      File "/usr/local/lib/python3.11/site-packages/tornado/web.py", line 1786, in _execute
      File "/usr/local/lib/python3.11/site-packages/jupyter_server/services/contents/handlers.py", line 121, in get
      File "/usr/local/lib/python3.11/site-packages/jupyter_core/utils/__init__.py", line 182, in ensure_async
      File "/usr/local/lib/python3.11/site-packages/jupyter_server/services/contents/filemanager.py", line 877, in get
    tornado.web.HTTPError: HTTP 404: Not Found (No such file or directory: )
[W 2024-11-04 09:29:15.004 ServerApp] 404 GET /api/contents?content=1&1730712555022 (555fb6ac53bf4e10ba9b6608c1a279b6@10.76.5.169) 1.94ms referer=http://dlc-arceus:8888/lab
[W 2024-11-04 09:29:15.026 ServerApp] 404 GET /api/contents?content=1&1730712555045 (10.76.5.169): No such file or directory: 
[W 2024-11-04 09:29:15.043 ServerApp] wrote error: 'No such file or directory: '
    Traceback (most recent call last):
      File "/usr/local/lib/python3.11/site-packages/tornado/web.py", line 1786, in _execute
      File "/usr/local/lib/python3.11/site-packages/jupyter_server/services/contents/handlers.py", line 121, in get
      File "/usr/local/lib/python3.11/site-packages/jupyter_core/utils/__init__.py", line 182, in ensure_async
      File "/usr/local/lib/python3.11/site-packages/jupyter_server/services/contents/filemanager.py", line 877, in get
    tornado.web.HTTPError: HTTP 404: Not Found (No such file or directory: )
[W 2024-11-04 09:29:15.047 ServerApp] 404 GET /api/contents?content=1&1730712555045 (555fb6ac53bf4e10ba9b6608c1a279b6@10.76.5.169) 21.06ms referer=http://dlc-arceus:8888/lab
[W 2024-11-04 09:29:15.067 ServerApp] 404 GET /api/contents?content=1&1730712555088 (10.76.5.169): No such file or directory: 
[W 2024-11-04 09:29:15.067 ServerApp] wrote error: 'No such file or directory: '
    Traceback (most recent call last):
      File "/usr/local/lib/python3.11/site-packages/tornado/web.py", line 1786, in _execute
      File "/usr/local/lib/python3.11/site-packages/jupyter_server/services/contents/handlers.py", line 121, in get
      File "/usr/local/lib/python3.11/site-packages/jupyter_core/utils/__init__.py", line 182, in ensure_async
      File "/usr/local/lib/python3.11/site-packages/jupyter_server/services/contents/filemanager.py", line 877, in get
    tornado.web.HTTPError: HTTP 404: Not Found (No such file or directory: )
[W 2024-11-04 09:29:15.068 ServerApp] 404 GET /api/contents?content=1&1730712555088 (555fb6ac53bf4e10ba9b6608c1a279b6@10.76.5.169) 1.95ms referer=http://dlc-arceus:8888/lab
[W 2024-11-04 09:29:15.092 ServerApp] 404 GET /api/contents?content=1&1730712555110 (10.76.5.169): No such file or directory: 
[W 2024-11-04 09:29:15.092 ServerApp] wrote error: 'No such file or directory: '
    Traceback (most recent call last):
      File "/usr/local/lib/python3.11/site-packages/tornado/web.py", line 1786, in _execute
      File "/usr/local/lib/python3.11/site-packages/jupyter_server/services/contents/handlers.py", line 121, in get
      File "/usr/local/lib/python3.11/site-packages/jupyter_core/utils/__init__.py", line 182, in ensure_async
      File "/usr/local/lib/python3.11/site-packages/jupyter_server/services/contents/filemanager.py", line 877, in get
    tornado.web.HTTPError: HTTP 404: Not Found (No such file or directory: )
[W 2024-11-04 09:29:15.098 ServerApp] 404 GET /api/contents?content=1&1730712555110 (555fb6ac53bf4e10ba9b6608c1a279b6@10.76.5.169) 6.65ms referer=http://dlc-arceus:8888/lab
[W 2024-11-04 09:29:15.125 ServerApp] 404 GET /api/contents?content=1&1730712555142 (10.76.5.169): No such file or directory: 
[W 2024-11-04 09:29:15.126 ServerApp] wrote error: 'No such file or directory: '
    Traceback (most recent call last):
      File "/usr/local/lib/python3.11/site-packages/tornado/web.py", line 1786, in _execute
      File "/usr/local/lib/python3.11/site-packages/jupyter_server/services/contents/handlers.py", line 121, in get
      File "/usr/local/lib/python3.11/site-packages/jupyter_core/utils/__init__.py", line 182, in ensure_async
      File "/usr/local/lib/python3.11/site-packages/jupyter_server/services/contents/filemanager.py", line 877, in get
    tornado.web.HTTPError: HTTP 404: Not Found (No such file or directory: )
[W 2024-11-04 09:29:15.127 ServerApp] 404 GET /api/contents?content=1&1730712555142 (555fb6ac53bf4e10ba9b6608c1a279b6@10.76.5.169) 3.36ms referer=http://dlc-arceus:8888/lab
[W 2024-11-04 09:29:15.149 ServerApp] 404 GET /api/contents?content=1&1730712555169 (10.76.5.169): No such file or directory: 
[W 2024-11-04 09:29:15.150 ServerApp] wrote error: 'No such file or directory: '
    Traceback (most recent call last):
      File "/usr/local/lib/python3.11/site-packages/tornado/web.py", line 1786, in _execute
      File "/usr/local/lib/python3.11/site-packages/jupyter_server/services/contents/handlers.py", line 121, in get
      File "/usr/local/lib/python3.11/site-packages/jupyter_core/utils/__init__.py", line 182, in ensure_async
      File "/usr/local/lib/python3.11/site-packages/jupyter_server/services/contents/filemanager.py", line 877, in get
    tornado.web.HTTPError: HTTP 404: Not Found (No such file or directory: )
[W 2024-11-04 09:29:15.151 ServerApp] 404 GET /api/contents?content=1&1730712555169 (555fb6ac53bf4e10ba9b6608c1a279b6@10.76.5.169) 1.66ms referer=http://dlc-arceus:8888/lab
[W 2024-11-04 09:29:15.171 ServerApp] 404 GET /api/contents?content=1&1730712555192 (10.76.5.169): No such file or directory: 
[W 2024-11-04 09:29:15.172 ServerApp] wrote error: 'No such file or directory: '
    Traceback (most recent call last):
      File "/usr/local/lib/python3.11/site-packages/tornado/web.py", line 1786, in _execute
      File "/usr/local/lib/python3.11/site-packages/jupyter_server/services/contents/handlers.py", line 121, in get
      File "/usr/local/lib/python3.11/site-packages/jupyter_core/utils/__init__.py", line 182, in ensure_async
      File "/usr/local/lib/python3.11/site-packages/jupyter_server/services/contents/filemanager.py", line 877, in get
    tornado.web.HTTPError: HTTP 404: Not Found (No such file or directory: )
[W 2024-11-04 09:29:15.173 ServerApp] 404 GET /api/contents?content=1&1730712555192 (555fb6ac53bf4e10ba9b6608c1a279b6@10.76.5.169) 2.28ms referer=http://dlc-arceus:8888/lab
[W 2024-11-04 09:29:15.193 ServerApp] 404 GET /api/contents?content=1&1730712555214 (10.76.5.169): No such file or directory: 
[W 2024-11-04 09:29:15.198 ServerApp] wrote error: 'No such file or directory: '
    Traceback (most recent call last):
      File "/usr/local/lib/python3.11/site-packages/tornado/web.py", line 1786, in _execute
      File "/usr/local/lib/python3.11/site-packages/jupyter_server/services/contents/handlers.py", line 121, in get
      File "/usr/local/lib/python3.11/site-packages/jupyter_core/utils/__init__.py", line 182, in ensure_async
      File "/usr/local/lib/python3.11/site-packages/jupyter_server/services/contents/filemanager.py", line 877, in get
    tornado.web.HTTPError: HTTP 404: Not Found (No such file or directory: )
[W 2024-11-04 09:29:15.199 ServerApp] 404 GET /api/contents?content=1&1730712555214 (555fb6ac53bf4e10ba9b6608c1a279b6@10.76.5.169) 6.28ms referer=http://dlc-arceus:8888/lab
[W 2024-11-04 09:29:15.217 ServerApp] 404 GET /api/contents?content=1&1730712555238 (10.76.5.169): No such file or directory: 
[W 2024-11-04 09:29:15.217 ServerApp] wrote error: 'No such file or directory: '
    Traceback (most recent call last):
      File "/usr/local/lib/python3.11/site-packages/tornado/web.py", line 1786, in _execute
      File "/usr/local/lib/python3.11/site-packages/jupyter_server/services/contents/handlers.py", line 121, in get
      File "/usr/local/lib/python3.11/site-packages/jupyter_core/utils/__init__.py", line 182, in ensure_async
      File "/usr/local/lib/python3.11/site-packages/jupyter_server/services/contents/filemanager.py", line 877, in get
    tornado.web.HTTPError: HTTP 404: Not Found (No such file or directory: )
[W 2024-11-04 09:29:15.218 ServerApp] 404 GET /api/contents?content=1&1730712555238 (555fb6ac53bf4e10ba9b6608c1a279b6@10.76.5.169) 1.52ms referer=http://dlc-arceus:8888/lab
[W 2024-11-04 09:29:15.241 ServerApp] 404 GET /api/contents?content=1&1730712555261 (10.76.5.169): No such file or directory: 
[W 2024-11-04 09:29:15.242 ServerApp] wrote error: 'No such file or directory: '
    Traceback (most recent call last):
      File "/usr/local/lib/python3.11/site-packages/tornado/web.py", line 1786, in _execute
      File "/usr/local/lib/python3.11/site-packages/jupyter_server/services/contents/handlers.py", line 121, in get
      File "/usr/local/lib/python3.11/site-packages/jupyter_core/utils/__init__.py", line 182, in ensure_async
      File "/usr/local/lib/python3.11/site-packages/jupyter_server/services/contents/filemanager.py", line 877, in get
    tornado.web.HTTPError: HTTP 404: Not Found (No such file or directory: )
[W 2024-11-04 09:29:15.243 ServerApp] 404 GET /api/contents?content=1&1730712555261 (555fb6ac53bf4e10ba9b6608c1a279b6@10.76.5.169) 1.89ms referer=http://dlc-arceus:8888/lab
[W 2024-11-04 09:29:15.261 ServerApp] 404 GET /api/contents?content=1&1730712555283 (10.76.5.169): No such file or directory: 
[W 2024-11-04 09:29:15.262 ServerApp] wrote error: 'No such file or directory: '
    Traceback (most recent call last):
      File "/usr/local/lib/python3.11/site-packages/tornado/web.py", line 1786, in _execute
      File "/usr/local/lib/python3.11/site-packages/jupyter_server/services/contents/handlers.py", line 121, in get
      File "/usr/local/lib/python3.11/site-packages/jupyter_core/utils/__init__.py", line 182, in ensure_async
      File "/usr/local/lib/python3.11/site-packages/jupyter_server/services/contents/filemanager.py", line 877, in get
    tornado.web.HTTPError: HTTP 404: Not Found (No such file or directory: )
[W 2024-11-04 09:29:15.264 ServerApp] 404 GET /api/contents?content=1&1730712555283 (555fb6ac53bf4e10ba9b6608c1a279b6@10.76.5.169) 3.26ms referer=http://dlc-arceus:8888/lab
[W 2024-11-04 09:29:15.286 ServerApp] 404 GET /api/contents?content=1&1730712555306 (10.76.5.169): No such file or directory: 
[W 2024-11-04 09:29:15.286 ServerApp] wrote error: 'No such file or directory: '
    Traceback (most recent call last):
      File "/usr/local/lib/python3.11/site-packages/tornado/web.py", line 1786, in _execute
      File "/usr/local/lib/python3.11/site-packages/jupyter_server/services/contents/handlers.py", line 121, in get
      File "/usr/local/lib/python3.11/site-packages/jupyter_core/utils/__init__.py", line 182, in ensure_async
      File "/usr/local/lib/python3.11/site-packages/jupyter_server/services/contents/filemanager.py", line 877, in get
    tornado.web.HTTPError: HTTP 404: Not Found (No such file or directory: )
[W 2024-11-04 09:29:15.287 ServerApp] 404 GET /api/contents?content=1&1730712555306 (555fb6ac53bf4e10ba9b6608c1a279b6@10.76.5.169) 1.78ms referer=http://dlc-arceus:8888/lab
[W 2024-11-04 09:29:15.308 ServerApp] 404 GET /api/contents?content=1&1730712555328 (10.76.5.169): No such file or directory: 
[W 2024-11-04 09:29:15.308 ServerApp] wrote error: 'No such file or directory: '
    Traceback (most recent call last):
      File "/usr/local/lib/python3.11/site-packages/tornado/web.py", line 1786, in _execute
      File "/usr/local/lib/python3.11/site-packages/jupyter_server/services/contents/handlers.py", line 121, in get
      File "/usr/local/lib/python3.11/site-packages/jupyter_core/utils/__init__.py", line 182, in ensure_async
      File "/usr/local/lib/python3.11/site-packages/jupyter_server/services/contents/filemanager.py", line 877, in get
    tornado.web.HTTPError: HTTP 404: Not Found (No such file or directory: )
[W 2024-11-04 09:29:15.309 ServerApp] 404 GET /api/contents?content=1&1730712555328 (555fb6ac53bf4e10ba9b6608c1a279b6@10.76.5.169) 1.53ms referer=http://dlc-arceus:8888/lab
[W 2024-11-04 09:29:15.327 ServerApp] 404 GET /api/contents?content=1&1730712555349 (10.76.5.169): No such file or directory: 
[W 2024-11-04 09:29:15.328 ServerApp] wrote error: 'No such file or directory: '
    Traceback (most recent call last):
      File "/usr/local/lib/python3.11/site-packages/tornado/web.py", line 1786, in _execute
      File "/usr/local/lib/python3.11/site-packages/jupyter_server/services/contents/handlers.py", line 121, in get
      File "/usr/local/lib/python3.11/site-packages/jupyter_core/utils/__init__.py", line 182, in ensure_async
      File "/usr/local/lib/python3.11/site-packages/jupyter_server/services/contents/filemanager.py", line 877, in get
    tornado.web.HTTPError: HTTP 404: Not Found (No such file or directory: )
[W 2024-11-04 09:29:15.328 ServerApp] 404 GET /api/contents?content=1&1730712555349 (555fb6ac53bf4e10ba9b6608c1a279b6@10.76.5.169) 1.61ms referer=http://dlc-arceus:8888/lab
[W 2024-11-04 09:29:15.347 ServerApp] 404 GET /api/contents?content=1&1730712555369 (10.76.5.169): No such file or directory: 
[W 2024-11-04 09:29:15.348 ServerApp] wrote error: 'No such file or directory: '
    Traceback (most recent call last):
      File "/usr/local/lib/python3.11/site-packages/tornado/web.py", line 1786, in _execute
      File "/usr/local/lib/python3.11/site-packages/jupyter_server/services/contents/handlers.py", line 121, in get
      File "/usr/local/lib/python3.11/site-packages/jupyter_core/utils/__init__.py", line 182, in ensure_async
      File "/usr/local/lib/python3.11/site-packages/jupyter_server/services/contents/filemanager.py", line 877, in get
    tornado.web.HTTPError: HTTP 404: Not Found (No such file or directory: )
[W 2024-11-04 09:29:15.349 ServerApp] 404 GET /api/contents?content=1&1730712555369 (555fb6ac53bf4e10ba9b6608c1a279b6@10.76.5.169) 1.76ms referer=http://dlc-arceus:8888/lab
[W 2024-11-04 09:29:15.370 ServerApp] 404 GET /api/contents?content=1&1730712555389 (10.76.5.169): No such file or directory: 
[W 2024-11-04 09:29:15.371 ServerApp] wrote error: 'No such file or directory: '
    Traceback (most recent call last):
      File "/usr/local/lib/python3.11/site-packages/tornado/web.py", line 1786, in _execute
      File "/usr/local/lib/python3.11/site-packages/jupyter_server/services/contents/handlers.py", line 121, in get
      File "/usr/local/lib/python3.11/site-packages/jupyter_core/utils/__init__.py", line 182, in ensure_async
      File "/usr/local/lib/python3.11/site-packages/jupyter_server/services/contents/filemanager.py", line 877, in get
    tornado.web.HTTPError: HTTP 404: Not Found (No such file or directory: )
[W 2024-11-04 09:29:15.371 ServerApp] 404 GET /api/contents?content=1&1730712555389 (555fb6ac53bf4e10ba9b6608c1a279b6@10.76.5.169) 1.77ms referer=http://dlc-arceus:8888/lab
[W 2024-11-04 09:29:15.395 ServerApp] 404 GET /api/contents?content=1&1730712555413 (10.76.5.169): No such file or directory: 
[W 2024-11-04 09:29:15.395 ServerApp] wrote error: 'No such file or directory: '
    Traceback (most recent call last):
      File "/usr/local/lib/python3.11/site-packages/tornado/web.py", line 1786, in _execute
      File "/usr/local/lib/python3.11/site-packages/jupyter_server/services/contents/handlers.py", line 121, in get
      File "/usr/local/lib/python3.11/site-packages/jupyter_core/utils/__init__.py", line 182, in ensure_async
      File "/usr/local/lib/python3.11/site-packages/jupyter_server/services/contents/filemanager.py", line 877, in get
    tornado.web.HTTPError: HTTP 404: Not Found (No such file or directory: )
[W 2024-11-04 09:29:15.396 ServerApp] 404 GET /api/contents?content=1&1730712555413 (555fb6ac53bf4e10ba9b6608c1a279b6@10.76.5.169) 1.42ms referer=http://dlc-arceus:8888/lab
[W 2024-11-04 09:29:15.416 ServerApp] 404 GET /api/contents?content=1&1730712555438 (10.76.5.169): No such file or directory: 
[W 2024-11-04 09:29:15.417 ServerApp] wrote error: 'No such file or directory: '
    Traceback (most recent call last):
      File "/usr/local/lib/python3.11/site-packages/tornado/web.py", line 1786, in _execute
      File "/usr/local/lib/python3.11/site-packages/jupyter_server/services/contents/handlers.py", line 121, in get
      File "/usr/local/lib/python3.11/site-packages/jupyter_core/utils/__init__.py", line 182, in ensure_async
      File "/usr/local/lib/python3.11/site-packages/jupyter_server/services/contents/filemanager.py", line 877, in get
    tornado.web.HTTPError: HTTP 404: Not Found (No such file or directory: )
[W 2024-11-04 09:29:15.417 ServerApp] 404 GET /api/contents?content=1&1730712555438 (555fb6ac53bf4e10ba9b6608c1a279b6@10.76.5.169) 1.39ms referer=http://dlc-arceus:8888/lab
[W 2024-11-04 09:29:15.440 ServerApp] 404 GET /api/contents?content=1&1730712555458 (10.76.5.169): No such file or directory: 
[W 2024-11-04 09:29:15.440 ServerApp] wrote error: 'No such file or directory: '
    Traceback (most recent call last):
      File "/usr/local/lib/python3.11/site-packages/tornado/web.py", line 1786, in _execute
      File "/usr/local/lib/python3.11/site-packages/jupyter_server/services/contents/handlers.py", line 121, in get
      File "/usr/local/lib/python3.11/site-packages/jupyter_core/utils/__init__.py", line 182, in ensure_async
      File "/usr/local/lib/python3.11/site-packages/jupyter_server/services/contents/filemanager.py", line 877, in get
    tornado.web.HTTPError: HTTP 404: Not Found (No such file or directory: )
[W 2024-11-04 09:29:15.441 ServerApp] 404 GET /api/contents?content=1&1730712555458 (555fb6ac53bf4e10ba9b6608c1a279b6@10.76.5.169) 1.36ms referer=http://dlc-arceus:8888/lab
[W 2024-11-04 09:29:15.457 ServerApp] 404 GET /api/contents?content=1&1730712555480 (10.76.5.169): No such file or directory: 
[W 2024-11-04 09:29:15.457 ServerApp] wrote error: 'No such file or directory: '
    Traceback (most recent call last):
      File "/usr/local/lib/python3.11/site-packages/tornado/web.py", line 1786, in _execute
      File "/usr/local/lib/python3.11/site-packages/jupyter_server/services/contents/handlers.py", line 121, in get
      File "/usr/local/lib/python3.11/site-packages/jupyter_core/utils/__init__.py", line 182, in ensure_async
      File "/usr/local/lib/python3.11/site-packages/jupyter_server/services/contents/filemanager.py", line 877, in get
    tornado.web.HTTPError: HTTP 404: Not Found (No such file or directory: )
[W 2024-11-04 09:29:15.458 ServerApp] 404 GET /api/contents?content=1&1730712555480 (555fb6ac53bf4e10ba9b6608c1a279b6@10.76.5.169) 1.26ms referer=http://dlc-arceus:8888/lab
[W 2024-11-04 09:29:15.479 ServerApp] 404 GET /api/contents?content=1&1730712555500 (10.76.5.169): No such file or directory: 
[W 2024-11-04 09:29:15.479 ServerApp] wrote error: 'No such file or directory: '
    Traceback (most recent call last):
      File "/usr/local/lib/python3.11/site-packages/tornado/web.py", line 1786, in _execute
      File "/usr/local/lib/python3.11/site-packages/jupyter_server/services/contents/handlers.py", line 121, in get
      File "/usr/local/lib/python3.11/site-packages/jupyter_core/utils/__init__.py", line 182, in ensure_async
      File "/usr/local/lib/python3.11/site-packages/jupyter_server/services/contents/filemanager.py", line 877, in get
    tornado.web.HTTPError: HTTP 404: Not Found (No such file or directory: )
[W 2024-11-04 09:29:15.480 ServerApp] 404 GET /api/contents?content=1&1730712555500 (555fb6ac53bf4e10ba9b6608c1a279b6@10.76.5.169) 1.48ms referer=http://dlc-arceus:8888/lab
[W 2024-11-04 09:29:15.502 ServerApp] 404 GET /api/contents?content=1&1730712555521 (10.76.5.169): No such file or directory: 
[W 2024-11-04 09:29:15.503 ServerApp] wrote error: 'No such file or directory: '
    Traceback (most recent call last):
      File "/usr/local/lib/python3.11/site-packages/tornado/web.py", line 1786, in _execute
      File "/usr/local/lib/python3.11/site-packages/jupyter_server/services/contents/handlers.py", line 121, in get
      File "/usr/local/lib/python3.11/site-packages/jupyter_core/utils/__init__.py", line 182, in ensure_async
      File "/usr/local/lib/python3.11/site-packages/jupyter_server/services/contents/filemanager.py", line 877, in get
    tornado.web.HTTPError: HTTP 404: Not Found (No such file or directory: )
[W 2024-11-04 09:29:15.504 ServerApp] 404 GET /api/contents?content=1&1730712555521 (555fb6ac53bf4e10ba9b6608c1a279b6@10.76.5.169) 1.56ms referer=http://dlc-arceus:8888/lab
[W 2024-11-04 09:29:15.525 ServerApp] 404 GET /api/contents?content=1&1730712555546 (10.76.5.169): No such file or directory: 
[W 2024-11-04 09:29:15.525 ServerApp] wrote error: 'No such file or directory: '
    Traceback (most recent call last):
      File "/usr/local/lib/python3.11/site-packages/tornado/web.py", line 1786, in _execute
      File "/usr/local/lib/python3.11/site-packages/jupyter_server/services/contents/handlers.py", line 121, in get
      File "/usr/local/lib/python3.11/site-packages/jupyter_core/utils/__init__.py", line 182, in ensure_async
      File "/usr/local/lib/python3.11/site-packages/jupyter_server/services/contents/filemanager.py", line 877, in get
    tornado.web.HTTPError: HTTP 404: Not Found (No such file or directory: )
[W 2024-11-04 09:29:15.526 ServerApp] 404 GET /api/contents?content=1&1730712555546 (555fb6ac53bf4e10ba9b6608c1a279b6@10.76.5.169) 1.41ms referer=http://dlc-arceus:8888/lab
[W 2024-11-04 09:29:15.547 ServerApp] 404 GET /api/contents?content=1&1730712555567 (10.76.5.169): No such file or directory: 
[W 2024-11-04 09:29:15.548 ServerApp] wrote error: 'No such file or directory: '
    Traceback (most recent call last):
      File "/usr/local/lib/python3.11/site-packages/tornado/web.py", line 1786, in _execute
      File "/usr/local/lib/python3.11/site-packages/jupyter_server/services/contents/handlers.py", line 121, in get
      File "/usr/local/lib/python3.11/site-packages/jupyter_core/utils/__init__.py", line 182, in ensure_async
      File "/usr/local/lib/python3.11/site-packages/jupyter_server/services/contents/filemanager.py", line 877, in get
    tornado.web.HTTPError: HTTP 404: Not Found (No such file or directory: )
[W 2024-11-04 09:29:15.548 ServerApp] 404 GET /api/contents?content=1&1730712555567 (555fb6ac53bf4e10ba9b6608c1a279b6@10.76.5.169) 1.96ms referer=http://dlc-arceus:8888/lab
[W 2024-11-04 09:29:15.570 ServerApp] 404 GET /api/contents?content=1&1730712555590 (10.76.5.169): No such file or directory: 
[W 2024-11-04 09:29:15.571 ServerApp] wrote error: 'No such file or directory: '
    Traceback (most recent call last):
      File "/usr/local/lib/python3.11/site-packages/tornado/web.py", line 1786, in _execute
      File "/usr/local/lib/python3.11/site-packages/jupyter_server/services/contents/handlers.py", line 121, in get
      File "/usr/local/lib/python3.11/site-packages/jupyter_core/utils/__init__.py", line 182, in ensure_async
      File "/usr/local/lib/python3.11/site-packages/jupyter_server/services/contents/filemanager.py", line 877, in get
    tornado.web.HTTPError: HTTP 404: Not Found (No such file or directory: )
[W 2024-11-04 09:29:15.572 ServerApp] 404 GET /api/contents?content=1&1730712555590 (555fb6ac53bf4e10ba9b6608c1a279b6@10.76.5.169) 2.02ms referer=http://dlc-arceus:8888/lab
[W 2024-11-04 09:29:15.591 ServerApp] 404 GET /api/contents?content=1&1730712555612 (10.76.5.169): No such file or directory: 
[W 2024-11-04 09:29:15.592 ServerApp] wrote error: 'No such file or directory: '
    Traceback (most recent call last):
      File "/usr/local/lib/python3.11/site-packages/tornado/web.py", line 1786, in _execute
      File "/usr/local/lib/python3.11/site-packages/jupyter_server/services/contents/handlers.py", line 121, in get
      File "/usr/local/lib/python3.11/site-packages/jupyter_core/utils/__init__.py", line 182, in ensure_async
      File "/usr/local/lib/python3.11/site-packages/jupyter_server/services/contents/filemanager.py", line 877, in get
    tornado.web.HTTPError: HTTP 404: Not Found (No such file or directory: )
[W 2024-11-04 09:29:15.592 ServerApp] 404 GET /api/contents?content=1&1730712555612 (555fb6ac53bf4e10ba9b6608c1a279b6@10.76.5.169) 1.30ms referer=http://dlc-arceus:8888/lab
[W 2024-11-04 09:29:15.615 ServerApp] 404 GET /api/contents?content=1&1730712555634 (10.76.5.169): No such file or directory: 
[W 2024-11-04 09:29:15.616 ServerApp] wrote error: 'No such file or directory: '
    Traceback (most recent call last):
      File "/usr/local/lib/python3.11/site-packages/tornado/web.py", line 1786, in _execute
      File "/usr/local/lib/python3.11/site-packages/jupyter_server/services/contents/handlers.py", line 121, in get
      File "/usr/local/lib/python3.11/site-packages/jupyter_core/utils/__init__.py", line 182, in ensure_async
      File "/usr/local/lib/python3.11/site-packages/jupyter_server/services/contents/filemanager.py", line 877, in get
    tornado.web.HTTPError: HTTP 404: Not Found (No such file or directory: )
[W 2024-11-04 09:29:15.616 ServerApp] 404 GET /api/contents?content=1&1730712555634 (555fb6ac53bf4e10ba9b6608c1a279b6@10.76.5.169) 1.37ms referer=http://dlc-arceus:8888/lab
[W 2024-11-04 09:29:15.635 ServerApp] 404 GET /api/contents?content=1&1730712555656 (10.76.5.169): No such file or directory: 
[W 2024-11-04 09:29:15.636 ServerApp] wrote error: 'No such file or directory: '
    Traceback (most recent call last):
      File "/usr/local/lib/python3.11/site-packages/tornado/web.py", line 1786, in _execute
      File "/usr/local/lib/python3.11/site-packages/jupyter_server/services/contents/handlers.py", line 121, in get
      File "/usr/local/lib/python3.11/site-packages/jupyter_core/utils/__init__.py", line 182, in ensure_async
      File "/usr/local/lib/python3.11/site-packages/jupyter_server/services/contents/filemanager.py", line 877, in get
    tornado.web.HTTPError: HTTP 404: Not Found (No such file or directory: )
[W 2024-11-04 09:29:15.637 ServerApp] 404 GET /api/contents?content=1&1730712555656 (555fb6ac53bf4e10ba9b6608c1a279b6@10.76.5.169) 1.77ms referer=http://dlc-arceus:8888/lab
[W 2024-11-04 09:29:15.656 ServerApp] 404 GET /api/contents?content=1&1730712555678 (10.76.5.169): No such file or directory: 
[W 2024-11-04 09:29:15.657 ServerApp] wrote error: 'No such file or directory: '
    Traceback (most recent call last):
      File "/usr/local/lib/python3.11/site-packages/tornado/web.py", line 1786, in _execute
      File "/usr/local/lib/python3.11/site-packages/jupyter_server/services/contents/handlers.py", line 121, in get
      File "/usr/local/lib/python3.11/site-packages/jupyter_core/utils/__init__.py", line 182, in ensure_async
      File "/usr/local/lib/python3.11/site-packages/jupyter_server/services/contents/filemanager.py", line 877, in get
    tornado.web.HTTPError: HTTP 404: Not Found (No such file or directory: )
[W 2024-11-04 09:29:15.657 ServerApp] 404 GET /api/contents?content=1&1730712555678 (555fb6ac53bf4e10ba9b6608c1a279b6@10.76.5.169) 1.86ms referer=http://dlc-arceus:8888/lab
[W 2024-11-04 09:29:15.677 ServerApp] 404 GET /api/contents?content=1&1730712555698 (10.76.5.169): No such file or directory: 
[W 2024-11-04 09:29:15.677 ServerApp] wrote error: 'No such file or directory: '
    Traceback (most recent call last):
      File "/usr/local/lib/python3.11/site-packages/tornado/web.py", line 1786, in _execute
      File "/usr/local/lib/python3.11/site-packages/jupyter_server/services/contents/handlers.py", line 121, in get
      File "/usr/local/lib/python3.11/site-packages/jupyter_core/utils/__init__.py", line 182, in ensure_async
      File "/usr/local/lib/python3.11/site-packages/jupyter_server/services/contents/filemanager.py", line 877, in get
    tornado.web.HTTPError: HTTP 404: Not Found (No such file or directory: )
[W 2024-11-04 09:29:15.678 ServerApp] 404 GET /api/contents?content=1&1730712555698 (555fb6ac53bf4e10ba9b6608c1a279b6@10.76.5.169) 1.49ms referer=http://dlc-arceus:8888/lab
[W 2024-11-04 09:29:15.702 ServerApp] 404 GET /api/contents?content=1&1730712555721 (10.76.5.169): No such file or directory: 
[W 2024-11-04 09:29:15.703 ServerApp] wrote error: 'No such file or directory: '
    Traceback (most recent call last):
      File "/usr/local/lib/python3.11/site-packages/tornado/web.py", line 1786, in _execute
      File "/usr/local/lib/python3.11/site-packages/jupyter_server/services/contents/handlers.py", line 121, in get
      File "/usr/local/lib/python3.11/site-packages/jupyter_core/utils/__init__.py", line 182, in ensure_async
      File "/usr/local/lib/python3.11/site-packages/jupyter_server/services/contents/filemanager.py", line 877, in get
    tornado.web.HTTPError: HTTP 404: Not Found (No such file or directory: )
[W 2024-11-04 09:29:15.704 ServerApp] 404 GET /api/contents?content=1&1730712555721 (555fb6ac53bf4e10ba9b6608c1a279b6@10.76.5.169) 1.86ms referer=http://dlc-arceus:8888/lab
[W 2024-11-04 09:29:15.727 ServerApp] 404 GET /api/contents?content=1&1730712555745 (10.76.5.169): No such file or directory: 
[W 2024-11-04 09:29:15.727 ServerApp] wrote error: 'No such file or directory: '
    Traceback (most recent call last):
      File "/usr/local/lib/python3.11/site-packages/tornado/web.py", line 1786, in _execute
      File "/usr/local/lib/python3.11/site-packages/jupyter_server/services/contents/handlers.py", line 121, in get
      File "/usr/local/lib/python3.11/site-packages/jupyter_core/utils/__init__.py", line 182, in ensure_async
      File "/usr/local/lib/python3.11/site-packages/jupyter_server/services/contents/filemanager.py", line 877, in get
    tornado.web.HTTPError: HTTP 404: Not Found (No such file or directory: )
[W 2024-11-04 09:29:15.728 ServerApp] 404 GET /api/contents?content=1&1730712555745 (555fb6ac53bf4e10ba9b6608c1a279b6@10.76.5.169) 1.84ms referer=http://dlc-arceus:8888/lab
[W 2024-11-04 09:29:15.747 ServerApp] 404 GET /api/contents?content=1&1730712555769 (10.76.5.169): No such file or directory: 
[W 2024-11-04 09:29:15.748 ServerApp] wrote error: 'No such file or directory: '
    Traceback (most recent call last):
      File "/usr/local/lib/python3.11/site-packages/tornado/web.py", line 1786, in _execute
      File "/usr/local/lib/python3.11/site-packages/jupyter_server/services/contents/handlers.py", line 121, in get
      File "/usr/local/lib/python3.11/site-packages/jupyter_core/utils/__init__.py", line 182, in ensure_async
      File "/usr/local/lib/python3.11/site-packages/jupyter_server/services/contents/filemanager.py", line 877, in get
    tornado.web.HTTPError: HTTP 404: Not Found (No such file or directory: )
[W 2024-11-04 09:29:15.748 ServerApp] 404 GET /api/contents?content=1&1730712555769 (555fb6ac53bf4e10ba9b6608c1a279b6@10.76.5.169) 1.55ms referer=http://dlc-arceus:8888/lab
[W 2024-11-04 09:29:15.770 ServerApp] 404 GET /api/contents?content=1&1730712555791 (10.76.5.169): No such file or directory: 
[W 2024-11-04 09:29:15.771 ServerApp] wrote error: 'No such file or directory: '
    Traceback (most recent call last):
      File "/usr/local/lib/python3.11/site-packages/tornado/web.py", line 1786, in _execute
      File "/usr/local/lib/python3.11/site-packages/jupyter_server/services/contents/handlers.py", line 121, in get
      File "/usr/local/lib/python3.11/site-packages/jupyter_core/utils/__init__.py", line 182, in ensure_async
      File "/usr/local/lib/python3.11/site-packages/jupyter_server/services/contents/filemanager.py", line 877, in get
    tornado.web.HTTPError: HTTP 404: Not Found (No such file or directory: )
[W 2024-11-04 09:29:15.771 ServerApp] 404 GET /api/contents?content=1&1730712555791 (555fb6ac53bf4e10ba9b6608c1a279b6@10.76.5.169) 1.48ms referer=http://dlc-arceus:8888/lab
[W 2024-11-04 09:29:15.791 ServerApp] 404 GET /api/contents?content=1&1730712555812 (10.76.5.169): No such file or directory: 
[W 2024-11-04 09:29:15.792 ServerApp] wrote error: 'No such file or directory: '
    Traceback (most recent call last):
      File "/usr/local/lib/python3.11/site-packages/tornado/web.py", line 1786, in _execute
      File "/usr/local/lib/python3.11/site-packages/jupyter_server/services/contents/handlers.py", line 121, in get
      File "/usr/local/lib/python3.11/site-packages/jupyter_core/utils/__init__.py", line 182, in ensure_async
      File "/usr/local/lib/python3.11/site-packages/jupyter_server/services/contents/filemanager.py", line 877, in get
    tornado.web.HTTPError: HTTP 404: Not Found (No such file or directory: )
[W 2024-11-04 09:29:15.792 ServerApp] 404 GET /api/contents?content=1&1730712555812 (555fb6ac53bf4e10ba9b6608c1a279b6@10.76.5.169) 1.77ms referer=http://dlc-arceus:8888/lab
[W 2024-11-04 09:29:15.811 ServerApp] 404 GET /api/contents?content=1&1730712555833 (10.76.5.169): No such file or directory: 
[W 2024-11-04 09:29:15.812 ServerApp] wrote error: 'No such file or directory: '
    Traceback (most recent call last):
      File "/usr/local/lib/python3.11/site-packages/tornado/web.py", line 1786, in _execute
      File "/usr/local/lib/python3.11/site-packages/jupyter_server/services/contents/handlers.py", line 121, in get
      File "/usr/local/lib/python3.11/site-packages/jupyter_core/utils/__init__.py", line 182, in ensure_async
      File "/usr/local/lib/python3.11/site-packages/jupyter_server/services/contents/filemanager.py", line 877, in get
    tornado.web.HTTPError: HTTP 404: Not Found (No such file or directory: )
[W 2024-11-04 09:29:15.812 ServerApp] 404 GET /api/contents?content=1&1730712555833 (555fb6ac53bf4e10ba9b6608c1a279b6@10.76.5.169) 1.40ms referer=http://dlc-arceus:8888/lab
[W 2024-11-04 09:29:15.834 ServerApp] 404 GET /api/contents?content=1&1730712555854 (10.76.5.169): No such file or directory: 
[W 2024-11-04 09:29:15.835 ServerApp] wrote error: 'No such file or directory: '
    Traceback (most recent call last):
      File "/usr/local/lib/python3.11/site-packages/tornado/web.py", line 1786, in _execute
      File "/usr/local/lib/python3.11/site-packages/jupyter_server/services/contents/handlers.py", line 121, in get
      File "/usr/local/lib/python3.11/site-packages/jupyter_core/utils/__init__.py", line 182, in ensure_async
      File "/usr/local/lib/python3.11/site-packages/jupyter_server/services/contents/filemanager.py", line 877, in get
    tornado.web.HTTPError: HTTP 404: Not Found (No such file or directory: )
[W 2024-11-04 09:29:15.835 ServerApp] 404 GET /api/contents?content=1&1730712555854 (555fb6ac53bf4e10ba9b6608c1a279b6@10.76.5.169) 1.67ms referer=http://dlc-arceus:8888/lab
[W 2024-11-04 09:29:15.855 ServerApp] 404 GET /api/contents?content=1&1730712555876 (10.76.5.169): No such file or directory: 
[W 2024-11-04 09:29:15.856 ServerApp] wrote error: 'No such file or directory: '
    Traceback (most recent call last):
      File "/usr/local/lib/python3.11/site-packages/tornado/web.py", line 1786, in _execute
      File "/usr/local/lib/python3.11/site-packages/jupyter_server/services/contents/handlers.py", line 121, in get
      File "/usr/local/lib/python3.11/site-packages/jupyter_core/utils/__init__.py", line 182, in ensure_async
      File "/usr/local/lib/python3.11/site-packages/jupyter_server/services/contents/filemanager.py", line 877, in get
    tornado.web.HTTPError: HTTP 404: Not Found (No such file or directory: )
[W 2024-11-04 09:29:15.856 ServerApp] 404 GET /api/contents?content=1&1730712555876 (555fb6ac53bf4e10ba9b6608c1a279b6@10.76.5.169) 1.33ms referer=http://dlc-arceus:8888/lab
[W 2024-11-04 09:29:15.875 ServerApp] 404 GET /api/contents?content=1&1730712555897 (10.76.5.169): No such file or directory: 
[W 2024-11-04 09:29:15.876 ServerApp] wrote error: 'No such file or directory: '
    Traceback (most recent call last):
      File "/usr/local/lib/python3.11/site-packages/tornado/web.py", line 1786, in _execute
      File "/usr/local/lib/python3.11/site-packages/jupyter_server/services/contents/handlers.py", line 121, in get
      File "/usr/local/lib/python3.11/site-packages/jupyter_core/utils/__init__.py", line 182, in ensure_async
      File "/usr/local/lib/python3.11/site-packages/jupyter_server/services/contents/filemanager.py", line 877, in get
    tornado.web.HTTPError: HTTP 404: Not Found (No such file or directory: )
[W 2024-11-04 09:29:15.876 ServerApp] 404 GET /api/contents?content=1&1730712555897 (555fb6ac53bf4e10ba9b6608c1a279b6@10.76.5.169) 1.31ms referer=http://dlc-arceus:8888/lab
[W 2024-11-04 09:29:15.899 ServerApp] 404 GET /api/contents?content=1&1730712555918 (10.76.5.169): No such file or directory: 
[W 2024-11-04 09:29:15.900 ServerApp] wrote error: 'No such file or directory: '
    Traceback (most recent call last):
      File "/usr/local/lib/python3.11/site-packages/tornado/web.py", line 1786, in _execute
      File "/usr/local/lib/python3.11/site-packages/jupyter_server/services/contents/handlers.py", line 121, in get
      File "/usr/local/lib/python3.11/site-packages/jupyter_core/utils/__init__.py", line 182, in ensure_async
      File "/usr/local/lib/python3.11/site-packages/jupyter_server/services/contents/filemanager.py", line 877, in get
    tornado.web.HTTPError: HTTP 404: Not Found (No such file or directory: )
[W 2024-11-04 09:29:15.900 ServerApp] 404 GET /api/contents?content=1&1730712555918 (555fb6ac53bf4e10ba9b6608c1a279b6@10.76.5.169) 1.46ms referer=http://dlc-arceus:8888/lab
[W 2024-11-04 09:29:15.921 ServerApp] 404 GET /api/contents?content=1&1730712555943 (10.76.5.169): No such file or directory: 
[W 2024-11-04 09:29:15.922 ServerApp] wrote error: 'No such file or directory: '
    Traceback (most recent call last):
      File "/usr/local/lib/python3.11/site-packages/tornado/web.py", line 1786, in _execute
      File "/usr/local/lib/python3.11/site-packages/jupyter_server/services/contents/handlers.py", line 121, in get
      File "/usr/local/lib/python3.11/site-packages/jupyter_core/utils/__init__.py", line 182, in ensure_async
      File "/usr/local/lib/python3.11/site-packages/jupyter_server/services/contents/filemanager.py", line 877, in get
    tornado.web.HTTPError: HTTP 404: Not Found (No such file or directory: )
[W 2024-11-04 09:29:15.922 ServerApp] 404 GET /api/contents?content=1&1730712555943 (555fb6ac53bf4e10ba9b6608c1a279b6@10.76.5.169) 1.53ms referer=http://dlc-arceus:8888/lab
[W 2024-11-04 09:29:15.942 ServerApp] 404 GET /api/contents?content=1&1730712555962 (10.76.5.169): No such file or directory: 
[W 2024-11-04 09:29:15.942 ServerApp] wrote error: 'No such file or directory: '
    Traceback (most recent call last):
      File "/usr/local/lib/python3.11/site-packages/tornado/web.py", line 1786, in _execute
      File "/usr/local/lib/python3.11/site-packages/jupyter_server/services/contents/handlers.py", line 121, in get
      File "/usr/local/lib/python3.11/site-packages/jupyter_core/utils/__init__.py", line 182, in ensure_async
      File "/usr/local/lib/python3.11/site-packages/jupyter_server/services/contents/filemanager.py", line 877, in get
    tornado.web.HTTPError: HTTP 404: Not Found (No such file or directory: )
[W 2024-11-04 09:29:15.943 ServerApp] 404 GET /api/contents?content=1&1730712555962 (555fb6ac53bf4e10ba9b6608c1a279b6@10.76.5.169) 1.82ms referer=http://dlc-arceus:8888/lab
[W 2024-11-04 09:29:15.962 ServerApp] 404 GET /api/contents?content=1&1730712555981 (10.76.5.169): No such file or directory: 
[W 2024-11-04 09:29:15.962 ServerApp] wrote error: 'No such file or directory: '
    Traceback (most recent call last):
      File "/usr/local/lib/python3.11/site-packages/tornado/web.py", line 1786, in _execute
      File "/usr/local/lib/python3.11/site-packages/jupyter_server/services/contents/handlers.py", line 121, in get
      File "/usr/local/lib/python3.11/site-packages/jupyter_core/utils/__init__.py", line 182, in ensure_async
      File "/usr/local/lib/python3.11/site-packages/jupyter_server/services/contents/filemanager.py", line 877, in get
    tornado.web.HTTPError: HTTP 404: Not Found (No such file or directory: )
[W 2024-11-04 09:29:15.963 ServerApp] 404 GET /api/contents?content=1&1730712555981 (555fb6ac53bf4e10ba9b6608c1a279b6@10.76.5.169) 1.92ms referer=http://dlc-arceus:8888/lab
[W 2024-11-04 09:29:15.989 ServerApp] 404 GET /api/contents?content=1&1730712556011 (10.76.5.169): No such file or directory: 
[W 2024-11-04 09:29:15.990 ServerApp] wrote error: 'No such file or directory: '
    Traceback (most recent call last):
      File "/usr/local/lib/python3.11/site-packages/tornado/web.py", line 1786, in _execute
      File "/usr/local/lib/python3.11/site-packages/jupyter_server/services/contents/handlers.py", line 121, in get
      File "/usr/local/lib/python3.11/site-packages/jupyter_core/utils/__init__.py", line 182, in ensure_async
      File "/usr/local/lib/python3.11/site-packages/jupyter_server/services/contents/filemanager.py", line 877, in get
    tornado.web.HTTPError: HTTP 404: Not Found (No such file or directory: )
[W 2024-11-04 09:29:15.991 ServerApp] 404 GET /api/contents?content=1&1730712556011 (555fb6ac53bf4e10ba9b6608c1a279b6@10.76.5.169) 1.91ms referer=http://dlc-arceus:8888/lab
[W 2024-11-04 09:29:16.009 ServerApp] 404 GET /api/contents?content=1&1730712556031 (10.76.5.169): No such file or directory: 
[W 2024-11-04 09:29:16.010 ServerApp] wrote error: 'No such file or directory: '
    Traceback (most recent call last):
      File "/usr/local/lib/python3.11/site-packages/tornado/web.py", line 1786, in _execute
      File "/usr/local/lib/python3.11/site-packages/jupyter_server/services/contents/handlers.py", line 121, in get
      File "/usr/local/lib/python3.11/site-packages/jupyter_core/utils/__init__.py", line 182, in ensure_async
      File "/usr/local/lib/python3.11/site-packages/jupyter_server/services/contents/filemanager.py", line 877, in get
    tornado.web.HTTPError: HTTP 404: Not Found (No such file or directory: )
[W 2024-11-04 09:29:16.011 ServerApp] 404 GET /api/contents?content=1&1730712556031 (555fb6ac53bf4e10ba9b6608c1a279b6@10.76.5.169) 1.79ms referer=http://dlc-arceus:8888/lab
[W 2024-11-04 09:29:16.033 ServerApp] 404 GET /api/contents?content=1&1730712556054 (10.76.5.169): No such file or directory: 
[W 2024-11-04 09:29:16.034 ServerApp] wrote error: 'No such file or directory: '
    Traceback (most recent call last):
      File "/usr/local/lib/python3.11/site-packages/tornado/web.py", line 1786, in _execute
      File "/usr/local/lib/python3.11/site-packages/jupyter_server/services/contents/handlers.py", line 121, in get
      File "/usr/local/lib/python3.11/site-packages/jupyter_core/utils/__init__.py", line 182, in ensure_async
      File "/usr/local/lib/python3.11/site-packages/jupyter_server/services/contents/filemanager.py", line 877, in get
    tornado.web.HTTPError: HTTP 404: Not Found (No such file or directory: )
[W 2024-11-04 09:29:16.035 ServerApp] 404 GET /api/contents?content=1&1730712556054 (555fb6ac53bf4e10ba9b6608c1a279b6@10.76.5.169) 1.54ms referer=http://dlc-arceus:8888/lab
[W 2024-11-04 09:29:16.056 ServerApp] 404 GET /api/contents?content=1&1730712556077 (10.76.5.169): No such file or directory: 
[W 2024-11-04 09:29:16.057 ServerApp] wrote error: 'No such file or directory: '
    Traceback (most recent call last):
      File "/usr/local/lib/python3.11/site-packages/tornado/web.py", line 1786, in _execute
      File "/usr/local/lib/python3.11/site-packages/jupyter_server/services/contents/handlers.py", line 121, in get
      File "/usr/local/lib/python3.11/site-packages/jupyter_core/utils/__init__.py", line 182, in ensure_async
      File "/usr/local/lib/python3.11/site-packages/jupyter_server/services/contents/filemanager.py", line 877, in get
    tornado.web.HTTPError: HTTP 404: Not Found (No such file or directory: )
[W 2024-11-04 09:29:16.058 ServerApp] 404 GET /api/contents?content=1&1730712556077 (555fb6ac53bf4e10ba9b6608c1a279b6@10.76.5.169) 2.03ms referer=http://dlc-arceus:8888/lab
[W 2024-11-04 09:29:16.077 ServerApp] 404 GET /api/contents?content=1&1730712556099 (10.76.5.169): No such file or directory: 
[W 2024-11-04 09:29:16.077 ServerApp] wrote error: 'No such file or directory: '
    Traceback (most recent call last):
      File "/usr/local/lib/python3.11/site-packages/tornado/web.py", line 1786, in _execute
      File "/usr/local/lib/python3.11/site-packages/jupyter_server/services/contents/handlers.py", line 121, in get
      File "/usr/local/lib/python3.11/site-packages/jupyter_core/utils/__init__.py", line 182, in ensure_async
      File "/usr/local/lib/python3.11/site-packages/jupyter_server/services/contents/filemanager.py", line 877, in get
    tornado.web.HTTPError: HTTP 404: Not Found (No such file or directory: )
[W 2024-11-04 09:29:16.078 ServerApp] 404 GET /api/contents?content=1&1730712556099 (555fb6ac53bf4e10ba9b6608c1a279b6@10.76.5.169) 1.65ms referer=http://dlc-arceus:8888/lab
[W 2024-11-04 09:29:16.098 ServerApp] 404 GET /api/contents?content=1&1730712556119 (10.76.5.169): No such file or directory: 
[W 2024-11-04 09:29:16.099 ServerApp] wrote error: 'No such file or directory: '
    Traceback (most recent call last):
      File "/usr/local/lib/python3.11/site-packages/tornado/web.py", line 1786, in _execute
      File "/usr/local/lib/python3.11/site-packages/jupyter_server/services/contents/handlers.py", line 121, in get
      File "/usr/local/lib/python3.11/site-packages/jupyter_core/utils/__init__.py", line 182, in ensure_async
      File "/usr/local/lib/python3.11/site-packages/jupyter_server/services/contents/filemanager.py", line 877, in get
    tornado.web.HTTPError: HTTP 404: Not Found (No such file or directory: )
[W 2024-11-04 09:29:16.100 ServerApp] 404 GET /api/contents?content=1&1730712556119 (555fb6ac53bf4e10ba9b6608c1a279b6@10.76.5.169) 1.99ms referer=http://dlc-arceus:8888/lab
[W 2024-11-04 09:29:16.116 ServerApp] 404 GET /api/contents?content=1&1730712556138 (10.76.5.169): No such file or directory: 
[W 2024-11-04 09:29:16.116 ServerApp] wrote error: 'No such file or directory: '
    Traceback (most recent call last):
      File "/usr/local/lib/python3.11/site-packages/tornado/web.py", line 1786, in _execute
      File "/usr/local/lib/python3.11/site-packages/jupyter_server/services/contents/handlers.py", line 121, in get
      File "/usr/local/lib/python3.11/site-packages/jupyter_core/utils/__init__.py", line 182, in ensure_async
      File "/usr/local/lib/python3.11/site-packages/jupyter_server/services/contents/filemanager.py", line 877, in get
    tornado.web.HTTPError: HTTP 404: Not Found (No such file or directory: )
[W 2024-11-04 09:29:16.117 ServerApp] 404 GET /api/contents?content=1&1730712556138 (555fb6ac53bf4e10ba9b6608c1a279b6@10.76.5.169) 1.41ms referer=http://dlc-arceus:8888/lab
[W 2024-11-04 09:29:16.132 ServerApp] 404 GET /api/contents?content=1&1730712556155 (10.76.5.169): No such file or directory: 
[W 2024-11-04 09:29:16.133 ServerApp] wrote error: 'No such file or directory: '
    Traceback (most recent call last):
      File "/usr/local/lib/python3.11/site-packages/tornado/web.py", line 1786, in _execute
      File "/usr/local/lib/python3.11/site-packages/jupyter_server/services/contents/handlers.py", line 121, in get
      File "/usr/local/lib/python3.11/site-packages/jupyter_core/utils/__init__.py", line 182, in ensure_async
      File "/usr/local/lib/python3.11/site-packages/jupyter_server/services/contents/filemanager.py", line 877, in get
    tornado.web.HTTPError: HTTP 404: Not Found (No such file or directory: )
[W 2024-11-04 09:29:16.134 ServerApp] 404 GET /api/contents?content=1&1730712556155 (555fb6ac53bf4e10ba9b6608c1a279b6@10.76.5.169) 1.48ms referer=http://dlc-arceus:8888/lab
[W 2024-11-04 09:29:16.152 ServerApp] 404 GET /api/contents?content=1&1730712556172 (10.76.5.169): No such file or directory: 
[W 2024-11-04 09:29:16.152 ServerApp] wrote error: 'No such file or directory: '
    Traceback (most recent call last):
      File "/usr/local/lib/python3.11/site-packages/tornado/web.py", line 1786, in _execute
      File "/usr/local/lib/python3.11/site-packages/jupyter_server/services/contents/handlers.py", line 121, in get
      File "/usr/local/lib/python3.11/site-packages/jupyter_core/utils/__init__.py", line 182, in ensure_async
      File "/usr/local/lib/python3.11/site-packages/jupyter_server/services/contents/filemanager.py", line 877, in get
    tornado.web.HTTPError: HTTP 404: Not Found (No such file or directory: )
[W 2024-11-04 09:29:16.153 ServerApp] 404 GET /api/contents?content=1&1730712556172 (555fb6ac53bf4e10ba9b6608c1a279b6@10.76.5.169) 1.57ms referer=http://dlc-arceus:8888/lab
[W 2024-11-04 09:29:16.172 ServerApp] 404 GET /api/contents?content=1&1730712556193 (10.76.5.169): No such file or directory: 
[W 2024-11-04 09:29:16.173 ServerApp] wrote error: 'No such file or directory: '
    Traceback (most recent call last):
      File "/usr/local/lib/python3.11/site-packages/tornado/web.py", line 1786, in _execute
      File "/usr/local/lib/python3.11/site-packages/jupyter_server/services/contents/handlers.py", line 121, in get
      File "/usr/local/lib/python3.11/site-packages/jupyter_core/utils/__init__.py", line 182, in ensure_async
      File "/usr/local/lib/python3.11/site-packages/jupyter_server/services/contents/filemanager.py", line 877, in get
    tornado.web.HTTPError: HTTP 404: Not Found (No such file or directory: )
[W 2024-11-04 09:29:16.173 ServerApp] 404 GET /api/contents?content=1&1730712556193 (555fb6ac53bf4e10ba9b6608c1a279b6@10.76.5.169) 1.81ms referer=http://dlc-arceus:8888/lab
[W 2024-11-04 09:29:16.194 ServerApp] 404 GET /api/contents?content=1&1730712556214 (10.76.5.169): No such file or directory: 
[W 2024-11-04 09:29:16.194 ServerApp] wrote error: 'No such file or directory: '
    Traceback (most recent call last):
      File "/usr/local/lib/python3.11/site-packages/tornado/web.py", line 1786, in _execute
      File "/usr/local/lib/python3.11/site-packages/jupyter_server/services/contents/handlers.py", line 121, in get
      File "/usr/local/lib/python3.11/site-packages/jupyter_core/utils/__init__.py", line 182, in ensure_async
      File "/usr/local/lib/python3.11/site-packages/jupyter_server/services/contents/filemanager.py", line 877, in get
    tornado.web.HTTPError: HTTP 404: Not Found (No such file or directory: )
[W 2024-11-04 09:29:16.195 ServerApp] 404 GET /api/contents?content=1&1730712556214 (555fb6ac53bf4e10ba9b6608c1a279b6@10.76.5.169) 1.55ms referer=http://dlc-arceus:8888/lab
[W 2024-11-04 09:29:16.216 ServerApp] 404 GET /api/contents?content=1&1730712556236 (10.76.5.169): No such file or directory: 
[W 2024-11-04 09:29:16.216 ServerApp] wrote error: 'No such file or directory: '
    Traceback (most recent call last):
      File "/usr/local/lib/python3.11/site-packages/tornado/web.py", line 1786, in _execute
      File "/usr/local/lib/python3.11/site-packages/jupyter_server/services/contents/handlers.py", line 121, in get
      File "/usr/local/lib/python3.11/site-packages/jupyter_core/utils/__init__.py", line 182, in ensure_async
      File "/usr/local/lib/python3.11/site-packages/jupyter_server/services/contents/filemanager.py", line 877, in get
    tornado.web.HTTPError: HTTP 404: Not Found (No such file or directory: )
[W 2024-11-04 09:29:16.217 ServerApp] 404 GET /api/contents?content=1&1730712556236 (555fb6ac53bf4e10ba9b6608c1a279b6@10.76.5.169) 1.47ms referer=http://dlc-arceus:8888/lab
[W 2024-11-04 09:29:16.239 ServerApp] 404 GET /api/contents?content=1&1730712556259 (10.76.5.169): No such file or directory: 
[W 2024-11-04 09:29:16.239 ServerApp] wrote error: 'No such file or directory: '
    Traceback (most recent call last):
      File "/usr/local/lib/python3.11/site-packages/tornado/web.py", line 1786, in _execute
      File "/usr/local/lib/python3.11/site-packages/jupyter_server/services/contents/handlers.py", line 121, in get
      File "/usr/local/lib/python3.11/site-packages/jupyter_core/utils/__init__.py", line 182, in ensure_async
      File "/usr/local/lib/python3.11/site-packages/jupyter_server/services/contents/filemanager.py", line 877, in get
    tornado.web.HTTPError: HTTP 404: Not Found (No such file or directory: )
[W 2024-11-04 09:29:16.240 ServerApp] 404 GET /api/contents?content=1&1730712556259 (555fb6ac53bf4e10ba9b6608c1a279b6@10.76.5.169) 1.58ms referer=http://dlc-arceus:8888/lab
[W 2024-11-04 09:29:16.261 ServerApp] 404 GET /api/contents?content=1&1730712556282 (10.76.5.169): No such file or directory: 
[W 2024-11-04 09:29:16.262 ServerApp] wrote error: 'No such file or directory: '
    Traceback (most recent call last):
      File "/usr/local/lib/python3.11/site-packages/tornado/web.py", line 1786, in _execute
      File "/usr/local/lib/python3.11/site-packages/jupyter_server/services/contents/handlers.py", line 121, in get
      File "/usr/local/lib/python3.11/site-packages/jupyter_core/utils/__init__.py", line 182, in ensure_async
      File "/usr/local/lib/python3.11/site-packages/jupyter_server/services/contents/filemanager.py", line 877, in get
    tornado.web.HTTPError: HTTP 404: Not Found (No such file or directory: )
[W 2024-11-04 09:29:16.262 ServerApp] 404 GET /api/contents?content=1&1730712556282 (555fb6ac53bf4e10ba9b6608c1a279b6@10.76.5.169) 1.60ms referer=http://dlc-arceus:8888/lab
[W 2024-11-04 09:29:16.285 ServerApp] 404 GET /api/contents?content=1&1730712556304 (10.76.5.169): No such file or directory: 
[W 2024-11-04 09:29:16.285 ServerApp] wrote error: 'No such file or directory: '
    Traceback (most recent call last):
      File "/usr/local/lib/python3.11/site-packages/tornado/web.py", line 1786, in _execute
      File "/usr/local/lib/python3.11/site-packages/jupyter_server/services/contents/handlers.py", line 121, in get
      File "/usr/local/lib/python3.11/site-packages/jupyter_core/utils/__init__.py", line 182, in ensure_async
      File "/usr/local/lib/python3.11/site-packages/jupyter_server/services/contents/filemanager.py", line 877, in get
    tornado.web.HTTPError: HTTP 404: Not Found (No such file or directory: )
[W 2024-11-04 09:29:16.286 ServerApp] 404 GET /api/contents?content=1&1730712556304 (555fb6ac53bf4e10ba9b6608c1a279b6@10.76.5.169) 1.78ms referer=http://dlc-arceus:8888/lab
[W 2024-11-04 09:29:16.307 ServerApp] 404 GET /api/contents?content=1&1730712556326 (10.76.5.169): No such file or directory: 
[W 2024-11-04 09:29:16.308 ServerApp] wrote error: 'No such file or directory: '
    Traceback (most recent call last):
      File "/usr/local/lib/python3.11/site-packages/tornado/web.py", line 1786, in _execute
      File "/usr/local/lib/python3.11/site-packages/jupyter_server/services/contents/handlers.py", line 121, in get
      File "/usr/local/lib/python3.11/site-packages/jupyter_core/utils/__init__.py", line 182, in ensure_async
      File "/usr/local/lib/python3.11/site-packages/jupyter_server/services/contents/filemanager.py", line 877, in get
    tornado.web.HTTPError: HTTP 404: Not Found (No such file or directory: )
[W 2024-11-04 09:29:16.308 ServerApp] 404 GET /api/contents?content=1&1730712556326 (555fb6ac53bf4e10ba9b6608c1a279b6@10.76.5.169) 1.91ms referer=http://dlc-arceus:8888/lab
[W 2024-11-04 09:29:16.330 ServerApp] 404 GET /api/contents?content=1&1730712556349 (10.76.5.169): No such file or directory: 
[W 2024-11-04 09:29:16.330 ServerApp] wrote error: 'No such file or directory: '
    Traceback (most recent call last):
      File "/usr/local/lib/python3.11/site-packages/tornado/web.py", line 1786, in _execute
      File "/usr/local/lib/python3.11/site-packages/jupyter_server/services/contents/handlers.py", line 121, in get
      File "/usr/local/lib/python3.11/site-packages/jupyter_core/utils/__init__.py", line 182, in ensure_async
      File "/usr/local/lib/python3.11/site-packages/jupyter_server/services/contents/filemanager.py", line 877, in get
    tornado.web.HTTPError: HTTP 404: Not Found (No such file or directory: )
[W 2024-11-04 09:29:16.331 ServerApp] 404 GET /api/contents?content=1&1730712556349 (555fb6ac53bf4e10ba9b6608c1a279b6@10.76.5.169) 1.64ms referer=http://dlc-arceus:8888/lab
[W 2024-11-04 09:29:16.354 ServerApp] 404 GET /api/contents?content=1&1730712556375 (10.76.5.169): No such file or directory: 
[W 2024-11-04 09:29:16.355 ServerApp] wrote error: 'No such file or directory: '
    Traceback (most recent call last):
      File "/usr/local/lib/python3.11/site-packages/tornado/web.py", line 1786, in _execute
      File "/usr/local/lib/python3.11/site-packages/jupyter_server/services/contents/handlers.py", line 121, in get
      File "/usr/local/lib/python3.11/site-packages/jupyter_core/utils/__init__.py", line 182, in ensure_async
      File "/usr/local/lib/python3.11/site-packages/jupyter_server/services/contents/filemanager.py", line 877, in get
    tornado.web.HTTPError: HTTP 404: Not Found (No such file or directory: )
[W 2024-11-04 09:29:16.355 ServerApp] 404 GET /api/contents?content=1&1730712556375 (555fb6ac53bf4e10ba9b6608c1a279b6@10.76.5.169) 1.72ms referer=http://dlc-arceus:8888/lab
[W 2024-11-04 09:29:16.376 ServerApp] 404 GET /api/contents?content=1&1730712556396 (10.76.5.169): No such file or directory: 
[W 2024-11-04 09:29:16.376 ServerApp] wrote error: 'No such file or directory: '
    Traceback (most recent call last):
      File "/usr/local/lib/python3.11/site-packages/tornado/web.py", line 1786, in _execute
      File "/usr/local/lib/python3.11/site-packages/jupyter_server/services/contents/handlers.py", line 121, in get
      File "/usr/local/lib/python3.11/site-packages/jupyter_core/utils/__init__.py", line 182, in ensure_async
      File "/usr/local/lib/python3.11/site-packages/jupyter_server/services/contents/filemanager.py", line 877, in get
    tornado.web.HTTPError: HTTP 404: Not Found (No such file or directory: )
[W 2024-11-04 09:29:16.377 ServerApp] 404 GET /api/contents?content=1&1730712556396 (555fb6ac53bf4e10ba9b6608c1a279b6@10.76.5.169) 1.61ms referer=http://dlc-arceus:8888/lab
[W 2024-11-04 09:29:16.399 ServerApp] 404 GET /api/contents?content=1&1730712556418 (10.76.5.169): No such file or directory: 
[W 2024-11-04 09:29:16.403 ServerApp] wrote error: 'No such file or directory: '
    Traceback (most recent call last):
      File "/usr/local/lib/python3.11/site-packages/tornado/web.py", line 1786, in _execute
      File "/usr/local/lib/python3.11/site-packages/jupyter_server/services/contents/handlers.py", line 121, in get
      File "/usr/local/lib/python3.11/site-packages/jupyter_core/utils/__init__.py", line 182, in ensure_async
      File "/usr/local/lib/python3.11/site-packages/jupyter_server/services/contents/filemanager.py", line 877, in get
    tornado.web.HTTPError: HTTP 404: Not Found (No such file or directory: )
[W 2024-11-04 09:29:16.404 ServerApp] 404 GET /api/contents?content=1&1730712556418 (555fb6ac53bf4e10ba9b6608c1a279b6@10.76.5.169) 4.96ms referer=http://dlc-arceus:8888/lab
[W 2024-11-04 09:29:16.424 ServerApp] 404 GET /api/contents?content=1&1730712556445 (10.76.5.169): No such file or directory: 
[W 2024-11-04 09:29:16.425 ServerApp] wrote error: 'No such file or directory: '
    Traceback (most recent call last):
      File "/usr/local/lib/python3.11/site-packages/tornado/web.py", line 1786, in _execute
      File "/usr/local/lib/python3.11/site-packages/jupyter_server/services/contents/handlers.py", line 121, in get
      File "/usr/local/lib/python3.11/site-packages/jupyter_core/utils/__init__.py", line 182, in ensure_async
      File "/usr/local/lib/python3.11/site-packages/jupyter_server/services/contents/filemanager.py", line 877, in get
    tornado.web.HTTPError: HTTP 404: Not Found (No such file or directory: )
[W 2024-11-04 09:29:16.425 ServerApp] 404 GET /api/contents?content=1&1730712556445 (555fb6ac53bf4e10ba9b6608c1a279b6@10.76.5.169) 1.68ms referer=http://dlc-arceus:8888/lab
[W 2024-11-04 09:29:16.442 ServerApp] 404 GET /api/contents?content=1&1730712556464 (10.76.5.169): No such file or directory: 
[W 2024-11-04 09:29:16.443 ServerApp] wrote error: 'No such file or directory: '
    Traceback (most recent call last):
      File "/usr/local/lib/python3.11/site-packages/tornado/web.py", line 1786, in _execute
      File "/usr/local/lib/python3.11/site-packages/jupyter_server/services/contents/handlers.py", line 121, in get
      File "/usr/local/lib/python3.11/site-packages/jupyter_core/utils/__init__.py", line 182, in ensure_async
      File "/usr/local/lib/python3.11/site-packages/jupyter_server/services/contents/filemanager.py", line 877, in get
    tornado.web.HTTPError: HTTP 404: Not Found (No such file or directory: )
[W 2024-11-04 09:29:16.443 ServerApp] 404 GET /api/contents?content=1&1730712556464 (555fb6ac53bf4e10ba9b6608c1a279b6@10.76.5.169) 1.73ms referer=http://dlc-arceus:8888/lab
[W 2024-11-04 09:29:16.459 ServerApp] 404 GET /api/contents?content=1&1730712556481 (10.76.5.169): No such file or directory: 
[W 2024-11-04 09:29:16.459 ServerApp] wrote error: 'No such file or directory: '
    Traceback (most recent call last):
      File "/usr/local/lib/python3.11/site-packages/tornado/web.py", line 1786, in _execute
      File "/usr/local/lib/python3.11/site-packages/jupyter_server/services/contents/handlers.py", line 121, in get
      File "/usr/local/lib/python3.11/site-packages/jupyter_core/utils/__init__.py", line 182, in ensure_async
      File "/usr/local/lib/python3.11/site-packages/jupyter_server/services/contents/filemanager.py", line 877, in get
    tornado.web.HTTPError: HTTP 404: Not Found (No such file or directory: )
[W 2024-11-04 09:29:16.460 ServerApp] 404 GET /api/contents?content=1&1730712556481 (555fb6ac53bf4e10ba9b6608c1a279b6@10.76.5.169) 1.44ms referer=http://dlc-arceus:8888/lab
[W 2024-11-04 09:29:16.479 ServerApp] 404 GET /api/contents?content=1&1730712556500 (10.76.5.169): No such file or directory: 
[W 2024-11-04 09:29:16.479 ServerApp] wrote error: 'No such file or directory: '
    Traceback (most recent call last):
      File "/usr/local/lib/python3.11/site-packages/tornado/web.py", line 1786, in _execute
      File "/usr/local/lib/python3.11/site-packages/jupyter_server/services/contents/handlers.py", line 121, in get
      File "/usr/local/lib/python3.11/site-packages/jupyter_core/utils/__init__.py", line 182, in ensure_async
      File "/usr/local/lib/python3.11/site-packages/jupyter_server/services/contents/filemanager.py", line 877, in get
    tornado.web.HTTPError: HTTP 404: Not Found (No such file or directory: )
[W 2024-11-04 09:29:16.480 ServerApp] 404 GET /api/contents?content=1&1730712556500 (555fb6ac53bf4e10ba9b6608c1a279b6@10.76.5.169) 1.49ms referer=http://dlc-arceus:8888/lab
[W 2024-11-04 09:29:16.501 ServerApp] 404 GET /api/contents?content=1&1730712556521 (10.76.5.169): No such file or directory: 
[W 2024-11-04 09:29:16.512 ServerApp] wrote error: 'No such file or directory: '
    Traceback (most recent call last):
      File "/usr/local/lib/python3.11/site-packages/tornado/web.py", line 1786, in _execute
      File "/usr/local/lib/python3.11/site-packages/jupyter_server/services/contents/handlers.py", line 121, in get
      File "/usr/local/lib/python3.11/site-packages/jupyter_core/utils/__init__.py", line 182, in ensure_async
      File "/usr/local/lib/python3.11/site-packages/jupyter_server/services/contents/filemanager.py", line 877, in get
    tornado.web.HTTPError: HTTP 404: Not Found (No such file or directory: )
[W 2024-11-04 09:29:16.513 ServerApp] 404 GET /api/contents?content=1&1730712556521 (555fb6ac53bf4e10ba9b6608c1a279b6@10.76.5.169) 12.50ms referer=http://dlc-arceus:8888/lab
[W 2024-11-04 09:29:16.534 ServerApp] 404 GET /api/contents?content=1&1730712556554 (10.76.5.169): No such file or directory: 
[W 2024-11-04 09:29:16.535 ServerApp] wrote error: 'No such file or directory: '
    Traceback (most recent call last):
      File "/usr/local/lib/python3.11/site-packages/tornado/web.py", line 1786, in _execute
      File "/usr/local/lib/python3.11/site-packages/jupyter_server/services/contents/handlers.py", line 121, in get
      File "/usr/local/lib/python3.11/site-packages/jupyter_core/utils/__init__.py", line 182, in ensure_async
      File "/usr/local/lib/python3.11/site-packages/jupyter_server/services/contents/filemanager.py", line 877, in get
    tornado.web.HTTPError: HTTP 404: Not Found (No such file or directory: )
[W 2024-11-04 09:29:16.536 ServerApp] 404 GET /api/contents?content=1&1730712556554 (555fb6ac53bf4e10ba9b6608c1a279b6@10.76.5.169) 1.83ms referer=http://dlc-arceus:8888/lab
[W 2024-11-04 09:29:16.557 ServerApp] 404 GET /api/contents?content=1&1730712556578 (10.76.5.169): No such file or directory: 
[W 2024-11-04 09:29:16.557 ServerApp] wrote error: 'No such file or directory: '
    Traceback (most recent call last):
      File "/usr/local/lib/python3.11/site-packages/tornado/web.py", line 1786, in _execute
      File "/usr/local/lib/python3.11/site-packages/jupyter_server/services/contents/handlers.py", line 121, in get
      File "/usr/local/lib/python3.11/site-packages/jupyter_core/utils/__init__.py", line 182, in ensure_async
      File "/usr/local/lib/python3.11/site-packages/jupyter_server/services/contents/filemanager.py", line 877, in get
    tornado.web.HTTPError: HTTP 404: Not Found (No such file or directory: )
[W 2024-11-04 09:29:16.558 ServerApp] 404 GET /api/contents?content=1&1730712556578 (555fb6ac53bf4e10ba9b6608c1a279b6@10.76.5.169) 1.62ms referer=http://dlc-arceus:8888/lab
[W 2024-11-04 09:29:16.579 ServerApp] 404 GET /api/contents?content=1&1730712556601 (10.76.5.169): No such file or directory: 
[W 2024-11-04 09:29:16.580 ServerApp] wrote error: 'No such file or directory: '
    Traceback (most recent call last):
      File "/usr/local/lib/python3.11/site-packages/tornado/web.py", line 1786, in _execute
      File "/usr/local/lib/python3.11/site-packages/jupyter_server/services/contents/handlers.py", line 121, in get
      File "/usr/local/lib/python3.11/site-packages/jupyter_core/utils/__init__.py", line 182, in ensure_async
      File "/usr/local/lib/python3.11/site-packages/jupyter_server/services/contents/filemanager.py", line 877, in get
    tornado.web.HTTPError: HTTP 404: Not Found (No such file or directory: )
[W 2024-11-04 09:29:16.581 ServerApp] 404 GET /api/contents?content=1&1730712556601 (555fb6ac53bf4e10ba9b6608c1a279b6@10.76.5.169) 1.86ms referer=http://dlc-arceus:8888/lab
[W 2024-11-04 09:29:16.602 ServerApp] 404 GET /api/contents?content=1&1730712556621 (10.76.5.169): No such file or directory: 
[W 2024-11-04 09:29:16.603 ServerApp] wrote error: 'No such file or directory: '
    Traceback (most recent call last):
      File "/usr/local/lib/python3.11/site-packages/tornado/web.py", line 1786, in _execute
      File "/usr/local/lib/python3.11/site-packages/jupyter_server/services/contents/handlers.py", line 121, in get
      File "/usr/local/lib/python3.11/site-packages/jupyter_core/utils/__init__.py", line 182, in ensure_async
      File "/usr/local/lib/python3.11/site-packages/jupyter_server/services/contents/filemanager.py", line 877, in get
    tornado.web.HTTPError: HTTP 404: Not Found (No such file or directory: )
[W 2024-11-04 09:29:16.604 ServerApp] 404 GET /api/contents?content=1&1730712556621 (555fb6ac53bf4e10ba9b6608c1a279b6@10.76.5.169) 2.24ms referer=http://dlc-arceus:8888/lab
[W 2024-11-04 09:29:16.624 ServerApp] 404 GET /api/contents?content=1&1730712556645 (10.76.5.169): No such file or directory: 
[W 2024-11-04 09:29:16.627 ServerApp] wrote error: 'No such file or directory: '
    Traceback (most recent call last):
      File "/usr/local/lib/python3.11/site-packages/tornado/web.py", line 1786, in _execute
      File "/usr/local/lib/python3.11/site-packages/jupyter_server/services/contents/handlers.py", line 121, in get
      File "/usr/local/lib/python3.11/site-packages/jupyter_core/utils/__init__.py", line 182, in ensure_async
      File "/usr/local/lib/python3.11/site-packages/jupyter_server/services/contents/filemanager.py", line 877, in get
    tornado.web.HTTPError: HTTP 404: Not Found (No such file or directory: )
[W 2024-11-04 09:29:16.631 ServerApp] 404 GET /api/contents?content=1&1730712556645 (555fb6ac53bf4e10ba9b6608c1a279b6@10.76.5.169) 7.08ms referer=http://dlc-arceus:8888/lab
[W 2024-11-04 09:29:16.652 ServerApp] 404 GET /api/contents?content=1&1730712556673 (10.76.5.169): No such file or directory: 
[W 2024-11-04 09:29:16.652 ServerApp] wrote error: 'No such file or directory: '
    Traceback (most recent call last):
      File "/usr/local/lib/python3.11/site-packages/tornado/web.py", line 1786, in _execute
      File "/usr/local/lib/python3.11/site-packages/jupyter_server/services/contents/handlers.py", line 121, in get
      File "/usr/local/lib/python3.11/site-packages/jupyter_core/utils/__init__.py", line 182, in ensure_async
      File "/usr/local/lib/python3.11/site-packages/jupyter_server/services/contents/filemanager.py", line 877, in get
    tornado.web.HTTPError: HTTP 404: Not Found (No such file or directory: )
[W 2024-11-04 09:29:16.653 ServerApp] 404 GET /api/contents?content=1&1730712556673 (555fb6ac53bf4e10ba9b6608c1a279b6@10.76.5.169) 1.74ms referer=http://dlc-arceus:8888/lab
[W 2024-11-04 09:29:16.674 ServerApp] 404 GET /api/contents?content=1&1730712556693 (10.76.5.169): No such file or directory: 
[W 2024-11-04 09:29:16.675 ServerApp] wrote error: 'No such file or directory: '
    Traceback (most recent call last):
      File "/usr/local/lib/python3.11/site-packages/tornado/web.py", line 1786, in _execute
      File "/usr/local/lib/python3.11/site-packages/jupyter_server/services/contents/handlers.py", line 121, in get
      File "/usr/local/lib/python3.11/site-packages/jupyter_core/utils/__init__.py", line 182, in ensure_async
      File "/usr/local/lib/python3.11/site-packages/jupyter_server/services/contents/filemanager.py", line 877, in get
    tornado.web.HTTPError: HTTP 404: Not Found (No such file or directory: )
[W 2024-11-04 09:29:16.677 ServerApp] 404 GET /api/contents?content=1&1730712556693 (555fb6ac53bf4e10ba9b6608c1a279b6@10.76.5.169) 3.07ms referer=http://dlc-arceus:8888/lab
[W 2024-11-04 09:29:16.698 ServerApp] 404 GET /api/contents?content=1&1730712556717 (10.76.5.169): No such file or directory: 
[W 2024-11-04 09:29:16.698 ServerApp] wrote error: 'No such file or directory: '
    Traceback (most recent call last):
      File "/usr/local/lib/python3.11/site-packages/tornado/web.py", line 1786, in _execute
      File "/usr/local/lib/python3.11/site-packages/jupyter_server/services/contents/handlers.py", line 121, in get
      File "/usr/local/lib/python3.11/site-packages/jupyter_core/utils/__init__.py", line 182, in ensure_async
      File "/usr/local/lib/python3.11/site-packages/jupyter_server/services/contents/filemanager.py", line 877, in get
    tornado.web.HTTPError: HTTP 404: Not Found (No such file or directory: )
[W 2024-11-04 09:29:16.699 ServerApp] 404 GET /api/contents?content=1&1730712556717 (555fb6ac53bf4e10ba9b6608c1a279b6@10.76.5.169) 1.77ms referer=http://dlc-arceus:8888/lab
[W 2024-11-04 09:29:16.720 ServerApp] 404 GET /api/contents?content=1&1730712556741 (10.76.5.169): No such file or directory: 
[W 2024-11-04 09:29:16.724 ServerApp] wrote error: 'No such file or directory: '
    Traceback (most recent call last):
      File "/usr/local/lib/python3.11/site-packages/tornado/web.py", line 1786, in _execute
      File "/usr/local/lib/python3.11/site-packages/jupyter_server/services/contents/handlers.py", line 121, in get
      File "/usr/local/lib/python3.11/site-packages/jupyter_core/utils/__init__.py", line 182, in ensure_async
      File "/usr/local/lib/python3.11/site-packages/jupyter_server/services/contents/filemanager.py", line 877, in get
    tornado.web.HTTPError: HTTP 404: Not Found (No such file or directory: )
[W 2024-11-04 09:29:16.724 ServerApp] 404 GET /api/contents?content=1&1730712556741 (555fb6ac53bf4e10ba9b6608c1a279b6@10.76.5.169) 4.38ms referer=http://dlc-arceus:8888/lab
[W 2024-11-04 09:29:16.745 ServerApp] 404 GET /api/contents?content=1&1730712556765 (10.76.5.169): No such file or directory: 
[W 2024-11-04 09:29:16.745 ServerApp] wrote error: 'No such file or directory: '
    Traceback (most recent call last):
      File "/usr/local/lib/python3.11/site-packages/tornado/web.py", line 1786, in _execute
      File "/usr/local/lib/python3.11/site-packages/jupyter_server/services/contents/handlers.py", line 121, in get
      File "/usr/local/lib/python3.11/site-packages/jupyter_core/utils/__init__.py", line 182, in ensure_async
      File "/usr/local/lib/python3.11/site-packages/jupyter_server/services/contents/filemanager.py", line 877, in get
    tornado.web.HTTPError: HTTP 404: Not Found (No such file or directory: )
[W 2024-11-04 09:29:16.746 ServerApp] 404 GET /api/contents?content=1&1730712556765 (555fb6ac53bf4e10ba9b6608c1a279b6@10.76.5.169) 1.42ms referer=http://dlc-arceus:8888/lab
[W 2024-11-04 09:29:16.768 ServerApp] 404 GET /api/contents?content=1&1730712556787 (10.76.5.169): No such file or directory: 
[W 2024-11-04 09:29:16.768 ServerApp] wrote error: 'No such file or directory: '
    Traceback (most recent call last):
      File "/usr/local/lib/python3.11/site-packages/tornado/web.py", line 1786, in _execute
      File "/usr/local/lib/python3.11/site-packages/jupyter_server/services/contents/handlers.py", line 121, in get
      File "/usr/local/lib/python3.11/site-packages/jupyter_core/utils/__init__.py", line 182, in ensure_async
      File "/usr/local/lib/python3.11/site-packages/jupyter_server/services/contents/filemanager.py", line 877, in get
    tornado.web.HTTPError: HTTP 404: Not Found (No such file or directory: )
[W 2024-11-04 09:29:16.769 ServerApp] 404 GET /api/contents?content=1&1730712556787 (555fb6ac53bf4e10ba9b6608c1a279b6@10.76.5.169) 1.45ms referer=http://dlc-arceus:8888/lab
[W 2024-11-04 09:29:16.791 ServerApp] 404 GET /api/contents?content=1&1730712556810 (10.76.5.169): No such file or directory: 
[W 2024-11-04 09:29:16.792 ServerApp] wrote error: 'No such file or directory: '
    Traceback (most recent call last):
      File "/usr/local/lib/python3.11/site-packages/tornado/web.py", line 1786, in _execute
      File "/usr/local/lib/python3.11/site-packages/jupyter_server/services/contents/handlers.py", line 121, in get
      File "/usr/local/lib/python3.11/site-packages/jupyter_core/utils/__init__.py", line 182, in ensure_async
      File "/usr/local/lib/python3.11/site-packages/jupyter_server/services/contents/filemanager.py", line 877, in get
    tornado.web.HTTPError: HTTP 404: Not Found (No such file or directory: )
[W 2024-11-04 09:29:16.792 ServerApp] 404 GET /api/contents?content=1&1730712556810 (555fb6ac53bf4e10ba9b6608c1a279b6@10.76.5.169) 1.47ms referer=http://dlc-arceus:8888/lab
[W 2024-11-04 09:29:16.813 ServerApp] 404 GET /api/contents?content=1&1730712556832 (10.76.5.169): No such file or directory: 
[W 2024-11-04 09:29:16.813 ServerApp] wrote error: 'No such file or directory: '
    Traceback (most recent call last):
      File "/usr/local/lib/python3.11/site-packages/tornado/web.py", line 1786, in _execute
      File "/usr/local/lib/python3.11/site-packages/jupyter_server/services/contents/handlers.py", line 121, in get
      File "/usr/local/lib/python3.11/site-packages/jupyter_core/utils/__init__.py", line 182, in ensure_async
      File "/usr/local/lib/python3.11/site-packages/jupyter_server/services/contents/filemanager.py", line 877, in get
    tornado.web.HTTPError: HTTP 404: Not Found (No such file or directory: )
[W 2024-11-04 09:29:16.814 ServerApp] 404 GET /api/contents?content=1&1730712556832 (555fb6ac53bf4e10ba9b6608c1a279b6@10.76.5.169) 1.86ms referer=http://dlc-arceus:8888/lab
[W 2024-11-04 09:29:16.835 ServerApp] 404 GET /api/contents?content=1&1730712556855 (10.76.5.169): No such file or directory: 
[W 2024-11-04 09:29:16.835 ServerApp] wrote error: 'No such file or directory: '
    Traceback (most recent call last):
      File "/usr/local/lib/python3.11/site-packages/tornado/web.py", line 1786, in _execute
      File "/usr/local/lib/python3.11/site-packages/jupyter_server/services/contents/handlers.py", line 121, in get
      File "/usr/local/lib/python3.11/site-packages/jupyter_core/utils/__init__.py", line 182, in ensure_async
      File "/usr/local/lib/python3.11/site-packages/jupyter_server/services/contents/filemanager.py", line 877, in get
    tornado.web.HTTPError: HTTP 404: Not Found (No such file or directory: )
[W 2024-11-04 09:29:16.836 ServerApp] 404 GET /api/contents?content=1&1730712556855 (555fb6ac53bf4e10ba9b6608c1a279b6@10.76.5.169) 1.70ms referer=http://dlc-arceus:8888/lab
[W 2024-11-04 09:29:16.857 ServerApp] 404 GET /api/contents?content=1&1730712556876 (10.76.5.169): No such file or directory: 
[W 2024-11-04 09:29:16.857 ServerApp] wrote error: 'No such file or directory: '
    Traceback (most recent call last):
      File "/usr/local/lib/python3.11/site-packages/tornado/web.py", line 1786, in _execute
      File "/usr/local/lib/python3.11/site-packages/jupyter_server/services/contents/handlers.py", line 121, in get
      File "/usr/local/lib/python3.11/site-packages/jupyter_core/utils/__init__.py", line 182, in ensure_async
      File "/usr/local/lib/python3.11/site-packages/jupyter_server/services/contents/filemanager.py", line 877, in get
    tornado.web.HTTPError: HTTP 404: Not Found (No such file or directory: )
[W 2024-11-04 09:29:16.858 ServerApp] 404 GET /api/contents?content=1&1730712556876 (555fb6ac53bf4e10ba9b6608c1a279b6@10.76.5.169) 1.74ms referer=http://dlc-arceus:8888/lab
[W 2024-11-04 09:29:16.881 ServerApp] 404 GET /api/contents?content=1&1730712556899 (10.76.5.169): No such file or directory: 
[W 2024-11-04 09:29:16.882 ServerApp] wrote error: 'No such file or directory: '
    Traceback (most recent call last):
      File "/usr/local/lib/python3.11/site-packages/tornado/web.py", line 1786, in _execute
      File "/usr/local/lib/python3.11/site-packages/jupyter_server/services/contents/handlers.py", line 121, in get
      File "/usr/local/lib/python3.11/site-packages/jupyter_core/utils/__init__.py", line 182, in ensure_async
      File "/usr/local/lib/python3.11/site-packages/jupyter_server/services/contents/filemanager.py", line 877, in get
    tornado.web.HTTPError: HTTP 404: Not Found (No such file or directory: )
[W 2024-11-04 09:29:16.882 ServerApp] 404 GET /api/contents?content=1&1730712556899 (555fb6ac53bf4e10ba9b6608c1a279b6@10.76.5.169) 1.67ms referer=http://dlc-arceus:8888/lab
[W 2024-11-04 09:29:16.903 ServerApp] 404 GET /api/contents?content=1&1730712556925 (10.76.5.169): No such file or directory: 
[W 2024-11-04 09:29:16.904 ServerApp] wrote error: 'No such file or directory: '
    Traceback (most recent call last):
      File "/usr/local/lib/python3.11/site-packages/tornado/web.py", line 1786, in _execute
      File "/usr/local/lib/python3.11/site-packages/jupyter_server/services/contents/handlers.py", line 121, in get
      File "/usr/local/lib/python3.11/site-packages/jupyter_core/utils/__init__.py", line 182, in ensure_async
      File "/usr/local/lib/python3.11/site-packages/jupyter_server/services/contents/filemanager.py", line 877, in get
    tornado.web.HTTPError: HTTP 404: Not Found (No such file or directory: )
[W 2024-11-04 09:29:16.905 ServerApp] 404 GET /api/contents?content=1&1730712556925 (555fb6ac53bf4e10ba9b6608c1a279b6@10.76.5.169) 2.50ms referer=http://dlc-arceus:8888/lab
[W 2024-11-04 09:29:16.925 ServerApp] 404 GET /api/contents?content=1&1730712556946 (10.76.5.169): No such file or directory: 
[W 2024-11-04 09:29:16.925 ServerApp] wrote error: 'No such file or directory: '
    Traceback (most recent call last):
      File "/usr/local/lib/python3.11/site-packages/tornado/web.py", line 1786, in _execute
      File "/usr/local/lib/python3.11/site-packages/jupyter_server/services/contents/handlers.py", line 121, in get
      File "/usr/local/lib/python3.11/site-packages/jupyter_core/utils/__init__.py", line 182, in ensure_async
      File "/usr/local/lib/python3.11/site-packages/jupyter_server/services/contents/filemanager.py", line 877, in get
    tornado.web.HTTPError: HTTP 404: Not Found (No such file or directory: )
[W 2024-11-04 09:29:16.926 ServerApp] 404 GET /api/contents?content=1&1730712556946 (555fb6ac53bf4e10ba9b6608c1a279b6@10.76.5.169) 1.43ms referer=http://dlc-arceus:8888/lab
[W 2024-11-04 09:29:16.942 ServerApp] 404 GET /api/contents?content=1&1730712556964 (10.76.5.169): No such file or directory: 
[W 2024-11-04 09:29:16.943 ServerApp] wrote error: 'No such file or directory: '
    Traceback (most recent call last):
      File "/usr/local/lib/python3.11/site-packages/tornado/web.py", line 1786, in _execute
      File "/usr/local/lib/python3.11/site-packages/jupyter_server/services/contents/handlers.py", line 121, in get
      File "/usr/local/lib/python3.11/site-packages/jupyter_core/utils/__init__.py", line 182, in ensure_async
      File "/usr/local/lib/python3.11/site-packages/jupyter_server/services/contents/filemanager.py", line 877, in get
    tornado.web.HTTPError: HTTP 404: Not Found (No such file or directory: )
[W 2024-11-04 09:29:16.944 ServerApp] 404 GET /api/contents?content=1&1730712556964 (555fb6ac53bf4e10ba9b6608c1a279b6@10.76.5.169) 2.19ms referer=http://dlc-arceus:8888/lab
[W 2024-11-04 09:29:16.960 ServerApp] 404 GET /api/contents?content=1&1730712556982 (10.76.5.169): No such file or directory: 
[W 2024-11-04 09:29:16.961 ServerApp] wrote error: 'No such file or directory: '
    Traceback (most recent call last):
      File "/usr/local/lib/python3.11/site-packages/tornado/web.py", line 1786, in _execute
      File "/usr/local/lib/python3.11/site-packages/jupyter_server/services/contents/handlers.py", line 121, in get
      File "/usr/local/lib/python3.11/site-packages/jupyter_core/utils/__init__.py", line 182, in ensure_async
      File "/usr/local/lib/python3.11/site-packages/jupyter_server/services/contents/filemanager.py", line 877, in get
    tornado.web.HTTPError: HTTP 404: Not Found (No such file or directory: )
[W 2024-11-04 09:29:16.962 ServerApp] 404 GET /api/contents?content=1&1730712556982 (555fb6ac53bf4e10ba9b6608c1a279b6@10.76.5.169) 1.52ms referer=http://dlc-arceus:8888/lab
[W 2024-11-04 09:29:16.982 ServerApp] 404 GET /api/contents?content=1&1730712557003 (10.76.5.169): No such file or directory: 
[W 2024-11-04 09:29:16.983 ServerApp] wrote error: 'No such file or directory: '
    Traceback (most recent call last):
      File "/usr/local/lib/python3.11/site-packages/tornado/web.py", line 1786, in _execute
      File "/usr/local/lib/python3.11/site-packages/jupyter_server/services/contents/handlers.py", line 121, in get
      File "/usr/local/lib/python3.11/site-packages/jupyter_core/utils/__init__.py", line 182, in ensure_async
      File "/usr/local/lib/python3.11/site-packages/jupyter_server/services/contents/filemanager.py", line 877, in get
    tornado.web.HTTPError: HTTP 404: Not Found (No such file or directory: )
[W 2024-11-04 09:29:16.984 ServerApp] 404 GET /api/contents?content=1&1730712557003 (555fb6ac53bf4e10ba9b6608c1a279b6@10.76.5.169) 1.56ms referer=http://dlc-arceus:8888/lab
[W 2024-11-04 09:29:17.004 ServerApp] 404 GET /api/contents?content=1&1730712557025 (10.76.5.169): No such file or directory: 
[W 2024-11-04 09:29:17.005 ServerApp] wrote error: 'No such file or directory: '
    Traceback (most recent call last):
      File "/usr/local/lib/python3.11/site-packages/tornado/web.py", line 1786, in _execute
      File "/usr/local/lib/python3.11/site-packages/jupyter_server/services/contents/handlers.py", line 121, in get
      File "/usr/local/lib/python3.11/site-packages/jupyter_core/utils/__init__.py", line 182, in ensure_async
      File "/usr/local/lib/python3.11/site-packages/jupyter_server/services/contents/filemanager.py", line 877, in get
    tornado.web.HTTPError: HTTP 404: Not Found (No such file or directory: )
[W 2024-11-04 09:29:17.005 ServerApp] 404 GET /api/contents?content=1&1730712557025 (555fb6ac53bf4e10ba9b6608c1a279b6@10.76.5.169) 1.43ms referer=http://dlc-arceus:8888/lab
[W 2024-11-04 09:29:17.024 ServerApp] 404 GET /api/contents?content=1&1730712557046 (10.76.5.169): No such file or directory: 
[W 2024-11-04 09:29:17.025 ServerApp] wrote error: 'No such file or directory: '
    Traceback (most recent call last):
      File "/usr/local/lib/python3.11/site-packages/tornado/web.py", line 1786, in _execute
      File "/usr/local/lib/python3.11/site-packages/jupyter_server/services/contents/handlers.py", line 121, in get
      File "/usr/local/lib/python3.11/site-packages/jupyter_core/utils/__init__.py", line 182, in ensure_async
      File "/usr/local/lib/python3.11/site-packages/jupyter_server/services/contents/filemanager.py", line 877, in get
    tornado.web.HTTPError: HTTP 404: Not Found (No such file or directory: )
[W 2024-11-04 09:29:17.026 ServerApp] 404 GET /api/contents?content=1&1730712557046 (555fb6ac53bf4e10ba9b6608c1a279b6@10.76.5.169) 2.14ms referer=http://dlc-arceus:8888/lab
[W 2024-11-04 09:29:17.049 ServerApp] 404 GET /api/contents?content=1&1730712557069 (10.76.5.169): No such file or directory: 
[W 2024-11-04 09:29:17.049 ServerApp] wrote error: 'No such file or directory: '
    Traceback (most recent call last):
      File "/usr/local/lib/python3.11/site-packages/tornado/web.py", line 1786, in _execute
      File "/usr/local/lib/python3.11/site-packages/jupyter_server/services/contents/handlers.py", line 121, in get
      File "/usr/local/lib/python3.11/site-packages/jupyter_core/utils/__init__.py", line 182, in ensure_async
      File "/usr/local/lib/python3.11/site-packages/jupyter_server/services/contents/filemanager.py", line 877, in get
    tornado.web.HTTPError: HTTP 404: Not Found (No such file or directory: )
[W 2024-11-04 09:29:17.050 ServerApp] 404 GET /api/contents?content=1&1730712557069 (555fb6ac53bf4e10ba9b6608c1a279b6@10.76.5.169) 1.57ms referer=http://dlc-arceus:8888/lab
[W 2024-11-04 09:29:17.071 ServerApp] 404 GET /api/contents?content=1&1730712557091 (10.76.5.169): No such file or directory: 
[W 2024-11-04 09:29:17.072 ServerApp] wrote error: 'No such file or directory: '
    Traceback (most recent call last):
      File "/usr/local/lib/python3.11/site-packages/tornado/web.py", line 1786, in _execute
      File "/usr/local/lib/python3.11/site-packages/jupyter_server/services/contents/handlers.py", line 121, in get
      File "/usr/local/lib/python3.11/site-packages/jupyter_core/utils/__init__.py", line 182, in ensure_async
      File "/usr/local/lib/python3.11/site-packages/jupyter_server/services/contents/filemanager.py", line 877, in get
    tornado.web.HTTPError: HTTP 404: Not Found (No such file or directory: )
[W 2024-11-04 09:29:17.073 ServerApp] 404 GET /api/contents?content=1&1730712557091 (555fb6ac53bf4e10ba9b6608c1a279b6@10.76.5.169) 1.78ms referer=http://dlc-arceus:8888/lab
[W 2024-11-04 09:29:17.093 ServerApp] 404 GET /api/contents?content=1&1730712557114 (10.76.5.169): No such file or directory: 
[W 2024-11-04 09:29:17.093 ServerApp] wrote error: 'No such file or directory: '
    Traceback (most recent call last):
      File "/usr/local/lib/python3.11/site-packages/tornado/web.py", line 1786, in _execute
      File "/usr/local/lib/python3.11/site-packages/jupyter_server/services/contents/handlers.py", line 121, in get
      File "/usr/local/lib/python3.11/site-packages/jupyter_core/utils/__init__.py", line 182, in ensure_async
      File "/usr/local/lib/python3.11/site-packages/jupyter_server/services/contents/filemanager.py", line 877, in get
    tornado.web.HTTPError: HTTP 404: Not Found (No such file or directory: )
[W 2024-11-04 09:29:17.094 ServerApp] 404 GET /api/contents?content=1&1730712557114 (555fb6ac53bf4e10ba9b6608c1a279b6@10.76.5.169) 1.35ms referer=http://dlc-arceus:8888/lab
[W 2024-11-04 09:29:17.114 ServerApp] 404 GET /api/contents?content=1&1730712557135 (10.76.5.169): No such file or directory: 
[W 2024-11-04 09:29:17.114 ServerApp] wrote error: 'No such file or directory: '
    Traceback (most recent call last):
      File "/usr/local/lib/python3.11/site-packages/tornado/web.py", line 1786, in _execute
      File "/usr/local/lib/python3.11/site-packages/jupyter_server/services/contents/handlers.py", line 121, in get
      File "/usr/local/lib/python3.11/site-packages/jupyter_core/utils/__init__.py", line 182, in ensure_async
      File "/usr/local/lib/python3.11/site-packages/jupyter_server/services/contents/filemanager.py", line 877, in get
    tornado.web.HTTPError: HTTP 404: Not Found (No such file or directory: )
[W 2024-11-04 09:29:17.115 ServerApp] 404 GET /api/contents?content=1&1730712557135 (555fb6ac53bf4e10ba9b6608c1a279b6@10.76.5.169) 1.57ms referer=http://dlc-arceus:8888/lab
[W 2024-11-04 09:29:17.135 ServerApp] 404 GET /api/contents?content=1&1730712557156 (10.76.5.169): No such file or directory: 
[W 2024-11-04 09:29:17.135 ServerApp] wrote error: 'No such file or directory: '
    Traceback (most recent call last):
      File "/usr/local/lib/python3.11/site-packages/tornado/web.py", line 1786, in _execute
      File "/usr/local/lib/python3.11/site-packages/jupyter_server/services/contents/handlers.py", line 121, in get
      File "/usr/local/lib/python3.11/site-packages/jupyter_core/utils/__init__.py", line 182, in ensure_async
      File "/usr/local/lib/python3.11/site-packages/jupyter_server/services/contents/filemanager.py", line 877, in get
    tornado.web.HTTPError: HTTP 404: Not Found (No such file or directory: )
[W 2024-11-04 09:29:17.136 ServerApp] 404 GET /api/contents?content=1&1730712557156 (555fb6ac53bf4e10ba9b6608c1a279b6@10.76.5.169) 1.47ms referer=http://dlc-arceus:8888/lab
[W 2024-11-04 09:29:17.156 ServerApp] 404 GET /api/contents?content=1&1730712557178 (10.76.5.169): No such file or directory: 
[W 2024-11-04 09:29:17.156 ServerApp] wrote error: 'No such file or directory: '
    Traceback (most recent call last):
      File "/usr/local/lib/python3.11/site-packages/tornado/web.py", line 1786, in _execute
      File "/usr/local/lib/python3.11/site-packages/jupyter_server/services/contents/handlers.py", line 121, in get
      File "/usr/local/lib/python3.11/site-packages/jupyter_core/utils/__init__.py", line 182, in ensure_async
      File "/usr/local/lib/python3.11/site-packages/jupyter_server/services/contents/filemanager.py", line 877, in get
    tornado.web.HTTPError: HTTP 404: Not Found (No such file or directory: )
[W 2024-11-04 09:29:17.157 ServerApp] 404 GET /api/contents?content=1&1730712557178 (555fb6ac53bf4e10ba9b6608c1a279b6@10.76.5.169) 1.66ms referer=http://dlc-arceus:8888/lab
[W 2024-11-04 09:29:17.177 ServerApp] 404 GET /api/contents?content=1&1730712557198 (10.76.5.169): No such file or directory: 
[W 2024-11-04 09:29:17.178 ServerApp] wrote error: 'No such file or directory: '
    Traceback (most recent call last):
      File "/usr/local/lib/python3.11/site-packages/tornado/web.py", line 1786, in _execute
      File "/usr/local/lib/python3.11/site-packages/jupyter_server/services/contents/handlers.py", line 121, in get
      File "/usr/local/lib/python3.11/site-packages/jupyter_core/utils/__init__.py", line 182, in ensure_async
      File "/usr/local/lib/python3.11/site-packages/jupyter_server/services/contents/filemanager.py", line 877, in get
    tornado.web.HTTPError: HTTP 404: Not Found (No such file or directory: )
[W 2024-11-04 09:29:17.178 ServerApp] 404 GET /api/contents?content=1&1730712557198 (555fb6ac53bf4e10ba9b6608c1a279b6@10.76.5.169) 1.48ms referer=http://dlc-arceus:8888/lab
[W 2024-11-04 09:29:17.194 ServerApp] 404 GET /api/contents?content=1&1730712557217 (10.76.5.169): No such file or directory: 
[W 2024-11-04 09:29:17.194 ServerApp] wrote error: 'No such file or directory: '
    Traceback (most recent call last):
      File "/usr/local/lib/python3.11/site-packages/tornado/web.py", line 1786, in _execute
      File "/usr/local/lib/python3.11/site-packages/jupyter_server/services/contents/handlers.py", line 121, in get
      File "/usr/local/lib/python3.11/site-packages/jupyter_core/utils/__init__.py", line 182, in ensure_async
      File "/usr/local/lib/python3.11/site-packages/jupyter_server/services/contents/filemanager.py", line 877, in get
    tornado.web.HTTPError: HTTP 404: Not Found (No such file or directory: )
[W 2024-11-04 09:29:17.195 ServerApp] 404 GET /api/contents?content=1&1730712557217 (555fb6ac53bf4e10ba9b6608c1a279b6@10.76.5.169) 1.55ms referer=http://dlc-arceus:8888/lab
[W 2024-11-04 09:29:17.213 ServerApp] 404 GET /api/contents?content=1&1730712557235 (10.76.5.169): No such file or directory: 
[W 2024-11-04 09:29:17.213 ServerApp] wrote error: 'No such file or directory: '
    Traceback (most recent call last):
      File "/usr/local/lib/python3.11/site-packages/tornado/web.py", line 1786, in _execute
      File "/usr/local/lib/python3.11/site-packages/jupyter_server/services/contents/handlers.py", line 121, in get
      File "/usr/local/lib/python3.11/site-packages/jupyter_core/utils/__init__.py", line 182, in ensure_async
      File "/usr/local/lib/python3.11/site-packages/jupyter_server/services/contents/filemanager.py", line 877, in get
    tornado.web.HTTPError: HTTP 404: Not Found (No such file or directory: )
[W 2024-11-04 09:29:17.214 ServerApp] 404 GET /api/contents?content=1&1730712557235 (555fb6ac53bf4e10ba9b6608c1a279b6@10.76.5.169) 1.59ms referer=http://dlc-arceus:8888/lab
[W 2024-11-04 09:29:17.230 ServerApp] 404 GET /api/contents?content=1&1730712557252 (10.76.5.169): No such file or directory: 
[W 2024-11-04 09:29:17.231 ServerApp] wrote error: 'No such file or directory: '
    Traceback (most recent call last):
      File "/usr/local/lib/python3.11/site-packages/tornado/web.py", line 1786, in _execute
      File "/usr/local/lib/python3.11/site-packages/jupyter_server/services/contents/handlers.py", line 121, in get
      File "/usr/local/lib/python3.11/site-packages/jupyter_core/utils/__init__.py", line 182, in ensure_async
      File "/usr/local/lib/python3.11/site-packages/jupyter_server/services/contents/filemanager.py", line 877, in get
    tornado.web.HTTPError: HTTP 404: Not Found (No such file or directory: )
[W 2024-11-04 09:29:17.232 ServerApp] 404 GET /api/contents?content=1&1730712557252 (555fb6ac53bf4e10ba9b6608c1a279b6@10.76.5.169) 1.87ms referer=http://dlc-arceus:8888/lab
[W 2024-11-04 09:29:17.250 ServerApp] 404 GET /api/contents?content=1&1730712557272 (10.76.5.169): No such file or directory: 
[W 2024-11-04 09:29:17.251 ServerApp] wrote error: 'No such file or directory: '
    Traceback (most recent call last):
      File "/usr/local/lib/python3.11/site-packages/tornado/web.py", line 1786, in _execute
      File "/usr/local/lib/python3.11/site-packages/jupyter_server/services/contents/handlers.py", line 121, in get
      File "/usr/local/lib/python3.11/site-packages/jupyter_core/utils/__init__.py", line 182, in ensure_async
      File "/usr/local/lib/python3.11/site-packages/jupyter_server/services/contents/filemanager.py", line 877, in get
    tornado.web.HTTPError: HTTP 404: Not Found (No such file or directory: )
[W 2024-11-04 09:29:17.252 ServerApp] 404 GET /api/contents?content=1&1730712557272 (555fb6ac53bf4e10ba9b6608c1a279b6@10.76.5.169) 1.59ms referer=http://dlc-arceus:8888/lab
[W 2024-11-04 09:29:17.273 ServerApp] 404 GET /api/contents?content=1&1730712557294 (10.76.5.169): No such file or directory: 
[W 2024-11-04 09:29:17.273 ServerApp] wrote error: 'No such file or directory: '
    Traceback (most recent call last):
      File "/usr/local/lib/python3.11/site-packages/tornado/web.py", line 1786, in _execute
      File "/usr/local/lib/python3.11/site-packages/jupyter_server/services/contents/handlers.py", line 121, in get
      File "/usr/local/lib/python3.11/site-packages/jupyter_core/utils/__init__.py", line 182, in ensure_async
      File "/usr/local/lib/python3.11/site-packages/jupyter_server/services/contents/filemanager.py", line 877, in get
    tornado.web.HTTPError: HTTP 404: Not Found (No such file or directory: )
[W 2024-11-04 09:29:17.274 ServerApp] 404 GET /api/contents?content=1&1730712557294 (555fb6ac53bf4e10ba9b6608c1a279b6@10.76.5.169) 1.43ms referer=http://dlc-arceus:8888/lab
[W 2024-11-04 09:29:17.297 ServerApp] 404 GET /api/contents?content=1&1730712557318 (10.76.5.169): No such file or directory: 
[W 2024-11-04 09:29:17.298 ServerApp] wrote error: 'No such file or directory: '
    Traceback (most recent call last):
      File "/usr/local/lib/python3.11/site-packages/tornado/web.py", line 1786, in _execute
      File "/usr/local/lib/python3.11/site-packages/jupyter_server/services/contents/handlers.py", line 121, in get
      File "/usr/local/lib/python3.11/site-packages/jupyter_core/utils/__init__.py", line 182, in ensure_async
      File "/usr/local/lib/python3.11/site-packages/jupyter_server/services/contents/filemanager.py", line 877, in get
    tornado.web.HTTPError: HTTP 404: Not Found (No such file or directory: )
[W 2024-11-04 09:29:17.299 ServerApp] 404 GET /api/contents?content=1&1730712557318 (555fb6ac53bf4e10ba9b6608c1a279b6@10.76.5.169) 1.78ms referer=http://dlc-arceus:8888/lab
[W 2024-11-04 09:29:17.319 ServerApp] 404 GET /api/contents?content=1&1730712557340 (10.76.5.169): No such file or directory: 
[W 2024-11-04 09:29:17.320 ServerApp] wrote error: 'No such file or directory: '
    Traceback (most recent call last):
      File "/usr/local/lib/python3.11/site-packages/tornado/web.py", line 1786, in _execute
      File "/usr/local/lib/python3.11/site-packages/jupyter_server/services/contents/handlers.py", line 121, in get
      File "/usr/local/lib/python3.11/site-packages/jupyter_core/utils/__init__.py", line 182, in ensure_async
      File "/usr/local/lib/python3.11/site-packages/jupyter_server/services/contents/filemanager.py", line 877, in get
    tornado.web.HTTPError: HTTP 404: Not Found (No such file or directory: )
[W 2024-11-04 09:29:17.321 ServerApp] 404 GET /api/contents?content=1&1730712557340 (555fb6ac53bf4e10ba9b6608c1a279b6@10.76.5.169) 1.96ms referer=http://dlc-arceus:8888/lab
[W 2024-11-04 09:29:17.343 ServerApp] 404 GET /api/contents?content=1&1730712557363 (10.76.5.169): No such file or directory: 
[W 2024-11-04 09:29:17.343 ServerApp] wrote error: 'No such file or directory: '
    Traceback (most recent call last):
      File "/usr/local/lib/python3.11/site-packages/tornado/web.py", line 1786, in _execute
      File "/usr/local/lib/python3.11/site-packages/jupyter_server/services/contents/handlers.py", line 121, in get
      File "/usr/local/lib/python3.11/site-packages/jupyter_core/utils/__init__.py", line 182, in ensure_async
      File "/usr/local/lib/python3.11/site-packages/jupyter_server/services/contents/filemanager.py", line 877, in get
    tornado.web.HTTPError: HTTP 404: Not Found (No such file or directory: )
[W 2024-11-04 09:29:17.344 ServerApp] 404 GET /api/contents?content=1&1730712557363 (555fb6ac53bf4e10ba9b6608c1a279b6@10.76.5.169) 1.74ms referer=http://dlc-arceus:8888/lab
[W 2024-11-04 09:29:17.364 ServerApp] 404 GET /api/contents?content=1&1730712557385 (10.76.5.169): No such file or directory: 
[W 2024-11-04 09:29:17.364 ServerApp] wrote error: 'No such file or directory: '
    Traceback (most recent call last):
      File "/usr/local/lib/python3.11/site-packages/tornado/web.py", line 1786, in _execute
      File "/usr/local/lib/python3.11/site-packages/jupyter_server/services/contents/handlers.py", line 121, in get
      File "/usr/local/lib/python3.11/site-packages/jupyter_core/utils/__init__.py", line 182, in ensure_async
      File "/usr/local/lib/python3.11/site-packages/jupyter_server/services/contents/filemanager.py", line 877, in get
    tornado.web.HTTPError: HTTP 404: Not Found (No such file or directory: )
[W 2024-11-04 09:29:17.366 ServerApp] 404 GET /api/contents?content=1&1730712557385 (555fb6ac53bf4e10ba9b6608c1a279b6@10.76.5.169) 1.85ms referer=http://dlc-arceus:8888/lab
[W 2024-11-04 09:29:17.386 ServerApp] 404 GET /api/contents?content=1&1730712557407 (10.76.5.169): No such file or directory: 
[W 2024-11-04 09:29:17.387 ServerApp] wrote error: 'No such file or directory: '
    Traceback (most recent call last):
      File "/usr/local/lib/python3.11/site-packages/tornado/web.py", line 1786, in _execute
      File "/usr/local/lib/python3.11/site-packages/jupyter_server/services/contents/handlers.py", line 121, in get
      File "/usr/local/lib/python3.11/site-packages/jupyter_core/utils/__init__.py", line 182, in ensure_async
      File "/usr/local/lib/python3.11/site-packages/jupyter_server/services/contents/filemanager.py", line 877, in get
    tornado.web.HTTPError: HTTP 404: Not Found (No such file or directory: )
[W 2024-11-04 09:29:17.387 ServerApp] 404 GET /api/contents?content=1&1730712557407 (555fb6ac53bf4e10ba9b6608c1a279b6@10.76.5.169) 1.53ms referer=http://dlc-arceus:8888/lab
[W 2024-11-04 09:29:17.408 ServerApp] 404 GET /api/contents?content=1&1730712557428 (10.76.5.169): No such file or directory: 
[W 2024-11-04 09:29:17.412 ServerApp] wrote error: 'No such file or directory: '
    Traceback (most recent call last):
      File "/usr/local/lib/python3.11/site-packages/tornado/web.py", line 1786, in _execute
      File "/usr/local/lib/python3.11/site-packages/jupyter_server/services/contents/handlers.py", line 121, in get
      File "/usr/local/lib/python3.11/site-packages/jupyter_core/utils/__init__.py", line 182, in ensure_async
      File "/usr/local/lib/python3.11/site-packages/jupyter_server/services/contents/filemanager.py", line 877, in get
    tornado.web.HTTPError: HTTP 404: Not Found (No such file or directory: )
[W 2024-11-04 09:29:17.413 ServerApp] 404 GET /api/contents?content=1&1730712557428 (555fb6ac53bf4e10ba9b6608c1a279b6@10.76.5.169) 4.90ms referer=http://dlc-arceus:8888/lab
[W 2024-11-04 09:29:17.437 ServerApp] 404 GET /api/contents?content=1&1730712557455 (10.76.5.169): No such file or directory: 
[W 2024-11-04 09:29:17.438 ServerApp] wrote error: 'No such file or directory: '
    Traceback (most recent call last):
      File "/usr/local/lib/python3.11/site-packages/tornado/web.py", line 1786, in _execute
      File "/usr/local/lib/python3.11/site-packages/jupyter_server/services/contents/handlers.py", line 121, in get
      File "/usr/local/lib/python3.11/site-packages/jupyter_core/utils/__init__.py", line 182, in ensure_async
      File "/usr/local/lib/python3.11/site-packages/jupyter_server/services/contents/filemanager.py", line 877, in get
    tornado.web.HTTPError: HTTP 404: Not Found (No such file or directory: )
[W 2024-11-04 09:29:17.442 ServerApp] 404 GET /api/contents?content=1&1730712557455 (555fb6ac53bf4e10ba9b6608c1a279b6@10.76.5.169) 5.74ms referer=http://dlc-arceus:8888/lab
[W 2024-11-04 09:29:17.466 ServerApp] 404 GET /api/contents?content=1&1730712557489 (10.76.5.169): No such file or directory: 
[W 2024-11-04 09:29:17.467 ServerApp] wrote error: 'No such file or directory: '
    Traceback (most recent call last):
      File "/usr/local/lib/python3.11/site-packages/tornado/web.py", line 1786, in _execute
      File "/usr/local/lib/python3.11/site-packages/jupyter_server/services/contents/handlers.py", line 121, in get
      File "/usr/local/lib/python3.11/site-packages/jupyter_core/utils/__init__.py", line 182, in ensure_async
      File "/usr/local/lib/python3.11/site-packages/jupyter_server/services/contents/filemanager.py", line 877, in get
    tornado.web.HTTPError: HTTP 404: Not Found (No such file or directory: )
[W 2024-11-04 09:29:17.482 ServerApp] 404 GET /api/contents?content=1&1730712557489 (555fb6ac53bf4e10ba9b6608c1a279b6@10.76.5.169) 15.90ms referer=http://dlc-arceus:8888/lab
[W 2024-11-04 09:29:17.503 ServerApp] 404 GET /api/contents?content=1&1730712557523 (10.76.5.169): No such file or directory: 
[W 2024-11-04 09:29:17.504 ServerApp] wrote error: 'No such file or directory: '
    Traceback (most recent call last):
      File "/usr/local/lib/python3.11/site-packages/tornado/web.py", line 1786, in _execute
      File "/usr/local/lib/python3.11/site-packages/jupyter_server/services/contents/handlers.py", line 121, in get
      File "/usr/local/lib/python3.11/site-packages/jupyter_core/utils/__init__.py", line 182, in ensure_async
      File "/usr/local/lib/python3.11/site-packages/jupyter_server/services/contents/filemanager.py", line 877, in get
    tornado.web.HTTPError: HTTP 404: Not Found (No such file or directory: )
[W 2024-11-04 09:29:17.505 ServerApp] 404 GET /api/contents?content=1&1730712557523 (555fb6ac53bf4e10ba9b6608c1a279b6@10.76.5.169) 1.70ms referer=http://dlc-arceus:8888/lab
[W 2024-11-04 09:29:17.524 ServerApp] 404 GET /api/contents?content=1&1730712557545 (10.76.5.169): No such file or directory: 
[W 2024-11-04 09:29:17.524 ServerApp] wrote error: 'No such file or directory: '
    Traceback (most recent call last):
      File "/usr/local/lib/python3.11/site-packages/tornado/web.py", line 1786, in _execute
      File "/usr/local/lib/python3.11/site-packages/jupyter_server/services/contents/handlers.py", line 121, in get
      File "/usr/local/lib/python3.11/site-packages/jupyter_core/utils/__init__.py", line 182, in ensure_async
      File "/usr/local/lib/python3.11/site-packages/jupyter_server/services/contents/filemanager.py", line 877, in get
    tornado.web.HTTPError: HTTP 404: Not Found (No such file or directory: )
[W 2024-11-04 09:29:17.527 ServerApp] 404 GET /api/contents?content=1&1730712557545 (555fb6ac53bf4e10ba9b6608c1a279b6@10.76.5.169) 3.62ms referer=http://dlc-arceus:8888/lab
[W 2024-11-04 09:29:17.549 ServerApp] 404 GET /api/contents?content=1&1730712557569 (10.76.5.169): No such file or directory: 
[W 2024-11-04 09:29:17.554 ServerApp] wrote error: 'No such file or directory: '
    Traceback (most recent call last):
      File "/usr/local/lib/python3.11/site-packages/tornado/web.py", line 1786, in _execute
      File "/usr/local/lib/python3.11/site-packages/jupyter_server/services/contents/handlers.py", line 121, in get
      File "/usr/local/lib/python3.11/site-packages/jupyter_core/utils/__init__.py", line 182, in ensure_async
      File "/usr/local/lib/python3.11/site-packages/jupyter_server/services/contents/filemanager.py", line 877, in get
    tornado.web.HTTPError: HTTP 404: Not Found (No such file or directory: )
[W 2024-11-04 09:29:17.555 ServerApp] 404 GET /api/contents?content=1&1730712557569 (555fb6ac53bf4e10ba9b6608c1a279b6@10.76.5.169) 6.31ms referer=http://dlc-arceus:8888/lab
[W 2024-11-04 09:29:17.574 ServerApp] 404 GET /api/contents?content=1&1730712557596 (10.76.5.169): No such file or directory: 
[W 2024-11-04 09:29:17.578 ServerApp] wrote error: 'No such file or directory: '
    Traceback (most recent call last):
      File "/usr/local/lib/python3.11/site-packages/tornado/web.py", line 1786, in _execute
      File "/usr/local/lib/python3.11/site-packages/jupyter_server/services/contents/handlers.py", line 121, in get
      File "/usr/local/lib/python3.11/site-packages/jupyter_core/utils/__init__.py", line 182, in ensure_async
      File "/usr/local/lib/python3.11/site-packages/jupyter_server/services/contents/filemanager.py", line 877, in get
    tornado.web.HTTPError: HTTP 404: Not Found (No such file or directory: )
[W 2024-11-04 09:29:17.579 ServerApp] 404 GET /api/contents?content=1&1730712557596 (555fb6ac53bf4e10ba9b6608c1a279b6@10.76.5.169) 5.46ms referer=http://dlc-arceus:8888/lab
[W 2024-11-04 09:29:17.603 ServerApp] 404 GET /api/contents?content=1&1730712557621 (10.76.5.169): No such file or directory: 
[W 2024-11-04 09:29:17.603 ServerApp] wrote error: 'No such file or directory: '
    Traceback (most recent call last):
      File "/usr/local/lib/python3.11/site-packages/tornado/web.py", line 1786, in _execute
      File "/usr/local/lib/python3.11/site-packages/jupyter_server/services/contents/handlers.py", line 121, in get
      File "/usr/local/lib/python3.11/site-packages/jupyter_core/utils/__init__.py", line 182, in ensure_async
      File "/usr/local/lib/python3.11/site-packages/jupyter_server/services/contents/filemanager.py", line 877, in get
    tornado.web.HTTPError: HTTP 404: Not Found (No such file or directory: )
[W 2024-11-04 09:29:17.604 ServerApp] 404 GET /api/contents?content=1&1730712557621 (555fb6ac53bf4e10ba9b6608c1a279b6@10.76.5.169) 1.51ms referer=http://dlc-arceus:8888/lab
[W 2024-11-04 09:29:17.624 ServerApp] 404 GET /api/contents?content=1&1730712557644 (10.76.5.169): No such file or directory: 
[W 2024-11-04 09:29:17.624 ServerApp] wrote error: 'No such file or directory: '
    Traceback (most recent call last):
      File "/usr/local/lib/python3.11/site-packages/tornado/web.py", line 1786, in _execute
      File "/usr/local/lib/python3.11/site-packages/jupyter_server/services/contents/handlers.py", line 121, in get
      File "/usr/local/lib/python3.11/site-packages/jupyter_core/utils/__init__.py", line 182, in ensure_async
      File "/usr/local/lib/python3.11/site-packages/jupyter_server/services/contents/filemanager.py", line 877, in get
    tornado.web.HTTPError: HTTP 404: Not Found (No such file or directory: )
[W 2024-11-04 09:29:17.625 ServerApp] 404 GET /api/contents?content=1&1730712557644 (555fb6ac53bf4e10ba9b6608c1a279b6@10.76.5.169) 1.50ms referer=http://dlc-arceus:8888/lab
[W 2024-11-04 09:29:17.643 ServerApp] 404 GET /api/contents?content=1&1730712557665 (10.76.5.169): No such file or directory: 
[W 2024-11-04 09:29:17.644 ServerApp] wrote error: 'No such file or directory: '
    Traceback (most recent call last):
      File "/usr/local/lib/python3.11/site-packages/tornado/web.py", line 1786, in _execute
      File "/usr/local/lib/python3.11/site-packages/jupyter_server/services/contents/handlers.py", line 121, in get
      File "/usr/local/lib/python3.11/site-packages/jupyter_core/utils/__init__.py", line 182, in ensure_async
      File "/usr/local/lib/python3.11/site-packages/jupyter_server/services/contents/filemanager.py", line 877, in get
    tornado.web.HTTPError: HTTP 404: Not Found (No such file or directory: )
[W 2024-11-04 09:29:17.645 ServerApp] 404 GET /api/contents?content=1&1730712557665 (555fb6ac53bf4e10ba9b6608c1a279b6@10.76.5.169) 1.51ms referer=http://dlc-arceus:8888/lab
[W 2024-11-04 09:29:17.667 ServerApp] 404 GET /api/contents?content=1&1730712557687 (10.76.5.169): No such file or directory: 
[W 2024-11-04 09:29:17.668 ServerApp] wrote error: 'No such file or directory: '
    Traceback (most recent call last):
      File "/usr/local/lib/python3.11/site-packages/tornado/web.py", line 1786, in _execute
      File "/usr/local/lib/python3.11/site-packages/jupyter_server/services/contents/handlers.py", line 121, in get
      File "/usr/local/lib/python3.11/site-packages/jupyter_core/utils/__init__.py", line 182, in ensure_async
      File "/usr/local/lib/python3.11/site-packages/jupyter_server/services/contents/filemanager.py", line 877, in get
    tornado.web.HTTPError: HTTP 404: Not Found (No such file or directory: )
[W 2024-11-04 09:29:17.670 ServerApp] 404 GET /api/contents?content=1&1730712557687 (555fb6ac53bf4e10ba9b6608c1a279b6@10.76.5.169) 3.02ms referer=http://dlc-arceus:8888/lab
[W 2024-11-04 09:29:17.693 ServerApp] 404 GET /api/contents?content=1&1730712557710 (10.76.5.169): No such file or directory: 
[W 2024-11-04 09:29:17.693 ServerApp] wrote error: 'No such file or directory: '
    Traceback (most recent call last):
      File "/usr/local/lib/python3.11/site-packages/tornado/web.py", line 1786, in _execute
      File "/usr/local/lib/python3.11/site-packages/jupyter_server/services/contents/handlers.py", line 121, in get
      File "/usr/local/lib/python3.11/site-packages/jupyter_core/utils/__init__.py", line 182, in ensure_async
      File "/usr/local/lib/python3.11/site-packages/jupyter_server/services/contents/filemanager.py", line 877, in get
    tornado.web.HTTPError: HTTP 404: Not Found (No such file or directory: )
[W 2024-11-04 09:29:17.694 ServerApp] 404 GET /api/contents?content=1&1730712557710 (555fb6ac53bf4e10ba9b6608c1a279b6@10.76.5.169) 1.37ms referer=http://dlc-arceus:8888/lab
[W 2024-11-04 09:29:17.714 ServerApp] 404 GET /api/contents?content=1&1730712557735 (10.76.5.169): No such file or directory: 
[W 2024-11-04 09:29:17.715 ServerApp] wrote error: 'No such file or directory: '
    Traceback (most recent call last):
      File "/usr/local/lib/python3.11/site-packages/tornado/web.py", line 1786, in _execute
      File "/usr/local/lib/python3.11/site-packages/jupyter_server/services/contents/handlers.py", line 121, in get
      File "/usr/local/lib/python3.11/site-packages/jupyter_core/utils/__init__.py", line 182, in ensure_async
      File "/usr/local/lib/python3.11/site-packages/jupyter_server/services/contents/filemanager.py", line 877, in get
    tornado.web.HTTPError: HTTP 404: Not Found (No such file or directory: )
[W 2024-11-04 09:29:17.715 ServerApp] 404 GET /api/contents?content=1&1730712557735 (555fb6ac53bf4e10ba9b6608c1a279b6@10.76.5.169) 1.73ms referer=http://dlc-arceus:8888/lab
[W 2024-11-04 09:29:17.738 ServerApp] 404 GET /api/contents?content=1&1730712557758 (10.76.5.169): No such file or directory: 
[W 2024-11-04 09:29:17.739 ServerApp] wrote error: 'No such file or directory: '
    Traceback (most recent call last):
      File "/usr/local/lib/python3.11/site-packages/tornado/web.py", line 1786, in _execute
      File "/usr/local/lib/python3.11/site-packages/jupyter_server/services/contents/handlers.py", line 121, in get
      File "/usr/local/lib/python3.11/site-packages/jupyter_core/utils/__init__.py", line 182, in ensure_async
      File "/usr/local/lib/python3.11/site-packages/jupyter_server/services/contents/filemanager.py", line 877, in get
    tornado.web.HTTPError: HTTP 404: Not Found (No such file or directory: )
[W 2024-11-04 09:29:17.740 ServerApp] 404 GET /api/contents?content=1&1730712557758 (555fb6ac53bf4e10ba9b6608c1a279b6@10.76.5.169) 1.68ms referer=http://dlc-arceus:8888/lab
[W 2024-11-04 09:29:17.761 ServerApp] 404 GET /api/contents?content=1&1730712557781 (10.76.5.169): No such file or directory: 
[W 2024-11-04 09:29:17.761 ServerApp] wrote error: 'No such file or directory: '
    Traceback (most recent call last):
      File "/usr/local/lib/python3.11/site-packages/tornado/web.py", line 1786, in _execute
      File "/usr/local/lib/python3.11/site-packages/jupyter_server/services/contents/handlers.py", line 121, in get
      File "/usr/local/lib/python3.11/site-packages/jupyter_core/utils/__init__.py", line 182, in ensure_async
      File "/usr/local/lib/python3.11/site-packages/jupyter_server/services/contents/filemanager.py", line 877, in get
    tornado.web.HTTPError: HTTP 404: Not Found (No such file or directory: )
[W 2024-11-04 09:29:17.762 ServerApp] 404 GET /api/contents?content=1&1730712557781 (555fb6ac53bf4e10ba9b6608c1a279b6@10.76.5.169) 1.82ms referer=http://dlc-arceus:8888/lab
[W 2024-11-04 09:29:17.783 ServerApp] 404 GET /api/contents?content=1&1730712557804 (10.76.5.169): No such file or directory: 
[W 2024-11-04 09:29:17.787 ServerApp] wrote error: 'No such file or directory: '
    Traceback (most recent call last):
      File "/usr/local/lib/python3.11/site-packages/tornado/web.py", line 1786, in _execute
      File "/usr/local/lib/python3.11/site-packages/jupyter_server/services/contents/handlers.py", line 121, in get
      File "/usr/local/lib/python3.11/site-packages/jupyter_core/utils/__init__.py", line 182, in ensure_async
      File "/usr/local/lib/python3.11/site-packages/jupyter_server/services/contents/filemanager.py", line 877, in get
    tornado.web.HTTPError: HTTP 404: Not Found (No such file or directory: )
[W 2024-11-04 09:29:17.788 ServerApp] 404 GET /api/contents?content=1&1730712557804 (555fb6ac53bf4e10ba9b6608c1a279b6@10.76.5.169) 5.36ms referer=http://dlc-arceus:8888/lab
[W 2024-11-04 09:29:17.808 ServerApp] 404 GET /api/contents?content=1&1730712557829 (10.76.5.169): No such file or directory: 
[W 2024-11-04 09:29:17.811 ServerApp] wrote error: 'No such file or directory: '
    Traceback (most recent call last):
      File "/usr/local/lib/python3.11/site-packages/tornado/web.py", line 1786, in _execute
      File "/usr/local/lib/python3.11/site-packages/jupyter_server/services/contents/handlers.py", line 121, in get
      File "/usr/local/lib/python3.11/site-packages/jupyter_core/utils/__init__.py", line 182, in ensure_async
      File "/usr/local/lib/python3.11/site-packages/jupyter_server/services/contents/filemanager.py", line 877, in get
    tornado.web.HTTPError: HTTP 404: Not Found (No such file or directory: )
[W 2024-11-04 09:29:17.811 ServerApp] 404 GET /api/contents?content=1&1730712557829 (555fb6ac53bf4e10ba9b6608c1a279b6@10.76.5.169) 3.59ms referer=http://dlc-arceus:8888/lab
[W 2024-11-04 09:29:17.832 ServerApp] 404 GET /api/contents?content=1&1730712557853 (10.76.5.169): No such file or directory: 
[W 2024-11-04 09:29:17.834 ServerApp] wrote error: 'No such file or directory: '
    Traceback (most recent call last):
      File "/usr/local/lib/python3.11/site-packages/tornado/web.py", line 1786, in _execute
      File "/usr/local/lib/python3.11/site-packages/jupyter_server/services/contents/handlers.py", line 121, in get
      File "/usr/local/lib/python3.11/site-packages/jupyter_core/utils/__init__.py", line 182, in ensure_async
      File "/usr/local/lib/python3.11/site-packages/jupyter_server/services/contents/filemanager.py", line 877, in get
    tornado.web.HTTPError: HTTP 404: Not Found (No such file or directory: )
[W 2024-11-04 09:29:17.836 ServerApp] 404 GET /api/contents?content=1&1730712557853 (555fb6ac53bf4e10ba9b6608c1a279b6@10.76.5.169) 3.53ms referer=http://dlc-arceus:8888/lab
[W 2024-11-04 09:29:17.856 ServerApp] 404 GET /api/contents?content=1&1730712557876 (10.76.5.169): No such file or directory: 
[W 2024-11-04 09:29:17.856 ServerApp] wrote error: 'No such file or directory: '
    Traceback (most recent call last):
      File "/usr/local/lib/python3.11/site-packages/tornado/web.py", line 1786, in _execute
      File "/usr/local/lib/python3.11/site-packages/jupyter_server/services/contents/handlers.py", line 121, in get
      File "/usr/local/lib/python3.11/site-packages/jupyter_core/utils/__init__.py", line 182, in ensure_async
      File "/usr/local/lib/python3.11/site-packages/jupyter_server/services/contents/filemanager.py", line 877, in get
    tornado.web.HTTPError: HTTP 404: Not Found (No such file or directory: )
[W 2024-11-04 09:29:17.857 ServerApp] 404 GET /api/contents?content=1&1730712557876 (555fb6ac53bf4e10ba9b6608c1a279b6@10.76.5.169) 1.53ms referer=http://dlc-arceus:8888/lab
[W 2024-11-04 09:29:17.876 ServerApp] 404 GET /api/contents?content=1&1730712557897 (10.76.5.169): No such file or directory: 
[W 2024-11-04 09:29:17.877 ServerApp] wrote error: 'No such file or directory: '
    Traceback (most recent call last):
      File "/usr/local/lib/python3.11/site-packages/tornado/web.py", line 1786, in _execute
      File "/usr/local/lib/python3.11/site-packages/jupyter_server/services/contents/handlers.py", line 121, in get
      File "/usr/local/lib/python3.11/site-packages/jupyter_core/utils/__init__.py", line 182, in ensure_async
      File "/usr/local/lib/python3.11/site-packages/jupyter_server/services/contents/filemanager.py", line 877, in get
    tornado.web.HTTPError: HTTP 404: Not Found (No such file or directory: )
[W 2024-11-04 09:29:17.878 ServerApp] 404 GET /api/contents?content=1&1730712557897 (555fb6ac53bf4e10ba9b6608c1a279b6@10.76.5.169) 1.87ms referer=http://dlc-arceus:8888/lab
[W 2024-11-04 09:29:17.899 ServerApp] 404 GET /api/contents?content=1&1730712557920 (10.76.5.169): No such file or directory: 
[W 2024-11-04 09:29:17.899 ServerApp] wrote error: 'No such file or directory: '
    Traceback (most recent call last):
      File "/usr/local/lib/python3.11/site-packages/tornado/web.py", line 1786, in _execute
      File "/usr/local/lib/python3.11/site-packages/jupyter_server/services/contents/handlers.py", line 121, in get
      File "/usr/local/lib/python3.11/site-packages/jupyter_core/utils/__init__.py", line 182, in ensure_async
      File "/usr/local/lib/python3.11/site-packages/jupyter_server/services/contents/filemanager.py", line 877, in get
    tornado.web.HTTPError: HTTP 404: Not Found (No such file or directory: )
[W 2024-11-04 09:29:17.900 ServerApp] 404 GET /api/contents?content=1&1730712557920 (555fb6ac53bf4e10ba9b6608c1a279b6@10.76.5.169) 2.14ms referer=http://dlc-arceus:8888/lab
[W 2024-11-04 09:29:17.921 ServerApp] 404 GET /api/contents?content=1&1730712557943 (10.76.5.169): No such file or directory: 
[W 2024-11-04 09:29:17.922 ServerApp] wrote error: 'No such file or directory: '
    Traceback (most recent call last):
      File "/usr/local/lib/python3.11/site-packages/tornado/web.py", line 1786, in _execute
      File "/usr/local/lib/python3.11/site-packages/jupyter_server/services/contents/handlers.py", line 121, in get
      File "/usr/local/lib/python3.11/site-packages/jupyter_core/utils/__init__.py", line 182, in ensure_async
      File "/usr/local/lib/python3.11/site-packages/jupyter_server/services/contents/filemanager.py", line 877, in get
    tornado.web.HTTPError: HTTP 404: Not Found (No such file or directory: )
[W 2024-11-04 09:29:17.924 ServerApp] 404 GET /api/contents?content=1&1730712557943 (555fb6ac53bf4e10ba9b6608c1a279b6@10.76.5.169) 2.65ms referer=http://dlc-arceus:8888/lab
[W 2024-11-04 09:29:17.941 ServerApp] 404 GET /api/contents?content=1&1730712557963 (10.76.5.169): No such file or directory: 
[W 2024-11-04 09:29:17.942 ServerApp] wrote error: 'No such file or directory: '
    Traceback (most recent call last):
      File "/usr/local/lib/python3.11/site-packages/tornado/web.py", line 1786, in _execute
      File "/usr/local/lib/python3.11/site-packages/jupyter_server/services/contents/handlers.py", line 121, in get
      File "/usr/local/lib/python3.11/site-packages/jupyter_core/utils/__init__.py", line 182, in ensure_async
      File "/usr/local/lib/python3.11/site-packages/jupyter_server/services/contents/filemanager.py", line 877, in get
    tornado.web.HTTPError: HTTP 404: Not Found (No such file or directory: )
[W 2024-11-04 09:29:17.943 ServerApp] 404 GET /api/contents?content=1&1730712557963 (555fb6ac53bf4e10ba9b6608c1a279b6@10.76.5.169) 2.28ms referer=http://dlc-arceus:8888/lab
[W 2024-11-04 09:29:17.959 ServerApp] 404 GET /api/contents?content=1&1730712557982 (10.76.5.169): No such file or directory: 
[W 2024-11-04 09:29:17.959 ServerApp] wrote error: 'No such file or directory: '
    Traceback (most recent call last):
      File "/usr/local/lib/python3.11/site-packages/tornado/web.py", line 1786, in _execute
      File "/usr/local/lib/python3.11/site-packages/jupyter_server/services/contents/handlers.py", line 121, in get
      File "/usr/local/lib/python3.11/site-packages/jupyter_core/utils/__init__.py", line 182, in ensure_async
      File "/usr/local/lib/python3.11/site-packages/jupyter_server/services/contents/filemanager.py", line 877, in get
    tornado.web.HTTPError: HTTP 404: Not Found (No such file or directory: )
[W 2024-11-04 09:29:17.960 ServerApp] 404 GET /api/contents?content=1&1730712557982 (555fb6ac53bf4e10ba9b6608c1a279b6@10.76.5.169) 1.25ms referer=http://dlc-arceus:8888/lab
[W 2024-11-04 09:29:17.981 ServerApp] 404 GET /api/contents?content=1&1730712558001 (10.76.5.169): No such file or directory: 
[W 2024-11-04 09:29:17.982 ServerApp] wrote error: 'No such file or directory: '
    Traceback (most recent call last):
      File "/usr/local/lib/python3.11/site-packages/tornado/web.py", line 1786, in _execute
      File "/usr/local/lib/python3.11/site-packages/jupyter_server/services/contents/handlers.py", line 121, in get
      File "/usr/local/lib/python3.11/site-packages/jupyter_core/utils/__init__.py", line 182, in ensure_async
      File "/usr/local/lib/python3.11/site-packages/jupyter_server/services/contents/filemanager.py", line 877, in get
    tornado.web.HTTPError: HTTP 404: Not Found (No such file or directory: )
[W 2024-11-04 09:29:17.982 ServerApp] 404 GET /api/contents?content=1&1730712558001 (555fb6ac53bf4e10ba9b6608c1a279b6@10.76.5.169) 2.01ms referer=http://dlc-arceus:8888/lab
[W 2024-11-04 09:29:17.997 ServerApp] 404 GET /api/contents?content=1&1730712558021 (10.76.5.169): No such file or directory: 
[W 2024-11-04 09:29:17.998 ServerApp] wrote error: 'No such file or directory: '
    Traceback (most recent call last):
      File "/usr/local/lib/python3.11/site-packages/tornado/web.py", line 1786, in _execute
      File "/usr/local/lib/python3.11/site-packages/jupyter_server/services/contents/handlers.py", line 121, in get
      File "/usr/local/lib/python3.11/site-packages/jupyter_core/utils/__init__.py", line 182, in ensure_async
      File "/usr/local/lib/python3.11/site-packages/jupyter_server/services/contents/filemanager.py", line 877, in get
    tornado.web.HTTPError: HTTP 404: Not Found (No such file or directory: )
[W 2024-11-04 09:29:18.003 ServerApp] 404 GET /api/contents?content=1&1730712558021 (555fb6ac53bf4e10ba9b6608c1a279b6@10.76.5.169) 5.93ms referer=http://dlc-arceus:8888/lab
[W 2024-11-04 09:29:18.020 ServerApp] 404 GET /api/contents?content=1&1730712558042 (10.76.5.169): No such file or directory: 
[W 2024-11-04 09:29:18.020 ServerApp] wrote error: 'No such file or directory: '
    Traceback (most recent call last):
      File "/usr/local/lib/python3.11/site-packages/tornado/web.py", line 1786, in _execute
      File "/usr/local/lib/python3.11/site-packages/jupyter_server/services/contents/handlers.py", line 121, in get
      File "/usr/local/lib/python3.11/site-packages/jupyter_core/utils/__init__.py", line 182, in ensure_async
      File "/usr/local/lib/python3.11/site-packages/jupyter_server/services/contents/filemanager.py", line 877, in get
    tornado.web.HTTPError: HTTP 404: Not Found (No such file or directory: )
[W 2024-11-04 09:29:18.021 ServerApp] 404 GET /api/contents?content=1&1730712558042 (555fb6ac53bf4e10ba9b6608c1a279b6@10.76.5.169) 1.60ms referer=http://dlc-arceus:8888/lab
[W 2024-11-04 09:29:18.037 ServerApp] 404 GET /api/contents?content=1&1730712558060 (10.76.5.169): No such file or directory: 
[W 2024-11-04 09:29:18.037 ServerApp] wrote error: 'No such file or directory: '
    Traceback (most recent call last):
      File "/usr/local/lib/python3.11/site-packages/tornado/web.py", line 1786, in _execute
      File "/usr/local/lib/python3.11/site-packages/jupyter_server/services/contents/handlers.py", line 121, in get
      File "/usr/local/lib/python3.11/site-packages/jupyter_core/utils/__init__.py", line 182, in ensure_async
      File "/usr/local/lib/python3.11/site-packages/jupyter_server/services/contents/filemanager.py", line 877, in get
    tornado.web.HTTPError: HTTP 404: Not Found (No such file or directory: )
[W 2024-11-04 09:29:18.044 ServerApp] 404 GET /api/contents?content=1&1730712558060 (555fb6ac53bf4e10ba9b6608c1a279b6@10.76.5.169) 6.92ms referer=http://dlc-arceus:8888/lab
[W 2024-11-04 09:29:18.064 ServerApp] 404 GET /api/contents?content=1&1730712558085 (10.76.5.169): No such file or directory: 
[W 2024-11-04 09:29:18.064 ServerApp] wrote error: 'No such file or directory: '
    Traceback (most recent call last):
      File "/usr/local/lib/python3.11/site-packages/tornado/web.py", line 1786, in _execute
      File "/usr/local/lib/python3.11/site-packages/jupyter_server/services/contents/handlers.py", line 121, in get
      File "/usr/local/lib/python3.11/site-packages/jupyter_core/utils/__init__.py", line 182, in ensure_async
      File "/usr/local/lib/python3.11/site-packages/jupyter_server/services/contents/filemanager.py", line 877, in get
    tornado.web.HTTPError: HTTP 404: Not Found (No such file or directory: )
[W 2024-11-04 09:29:18.065 ServerApp] 404 GET /api/contents?content=1&1730712558085 (555fb6ac53bf4e10ba9b6608c1a279b6@10.76.5.169) 1.72ms referer=http://dlc-arceus:8888/lab
[W 2024-11-04 09:29:18.083 ServerApp] 404 GET /api/contents?content=1&1730712558105 (10.76.5.169): No such file or directory: 
[W 2024-11-04 09:29:18.084 ServerApp] wrote error: 'No such file or directory: '
    Traceback (most recent call last):
      File "/usr/local/lib/python3.11/site-packages/tornado/web.py", line 1786, in _execute
      File "/usr/local/lib/python3.11/site-packages/jupyter_server/services/contents/handlers.py", line 121, in get
      File "/usr/local/lib/python3.11/site-packages/jupyter_core/utils/__init__.py", line 182, in ensure_async
      File "/usr/local/lib/python3.11/site-packages/jupyter_server/services/contents/filemanager.py", line 877, in get
    tornado.web.HTTPError: HTTP 404: Not Found (No such file or directory: )
[W 2024-11-04 09:29:18.085 ServerApp] 404 GET /api/contents?content=1&1730712558105 (555fb6ac53bf4e10ba9b6608c1a279b6@10.76.5.169) 2.18ms referer=http://dlc-arceus:8888/lab
[W 2024-11-04 09:29:18.103 ServerApp] 404 GET /api/contents?content=1&1730712558124 (10.76.5.169): No such file or directory: 
[W 2024-11-04 09:29:18.103 ServerApp] wrote error: 'No such file or directory: '
    Traceback (most recent call last):
      File "/usr/local/lib/python3.11/site-packages/tornado/web.py", line 1786, in _execute
      File "/usr/local/lib/python3.11/site-packages/jupyter_server/services/contents/handlers.py", line 121, in get
      File "/usr/local/lib/python3.11/site-packages/jupyter_core/utils/__init__.py", line 182, in ensure_async
      File "/usr/local/lib/python3.11/site-packages/jupyter_server/services/contents/filemanager.py", line 877, in get
    tornado.web.HTTPError: HTTP 404: Not Found (No such file or directory: )
[W 2024-11-04 09:29:18.104 ServerApp] 404 GET /api/contents?content=1&1730712558124 (555fb6ac53bf4e10ba9b6608c1a279b6@10.76.5.169) 1.42ms referer=http://dlc-arceus:8888/lab
[W 2024-11-04 09:29:18.123 ServerApp] 404 GET /api/contents?content=1&1730712558145 (10.76.5.169): No such file or directory: 
[W 2024-11-04 09:29:18.124 ServerApp] wrote error: 'No such file or directory: '
    Traceback (most recent call last):
      File "/usr/local/lib/python3.11/site-packages/tornado/web.py", line 1786, in _execute
      File "/usr/local/lib/python3.11/site-packages/jupyter_server/services/contents/handlers.py", line 121, in get
      File "/usr/local/lib/python3.11/site-packages/jupyter_core/utils/__init__.py", line 182, in ensure_async
      File "/usr/local/lib/python3.11/site-packages/jupyter_server/services/contents/filemanager.py", line 877, in get
    tornado.web.HTTPError: HTTP 404: Not Found (No such file or directory: )
[W 2024-11-04 09:29:18.131 ServerApp] 404 GET /api/contents?content=1&1730712558145 (555fb6ac53bf4e10ba9b6608c1a279b6@10.76.5.169) 8.28ms referer=http://dlc-arceus:8888/lab
[W 2024-11-04 09:29:18.148 ServerApp] 404 GET /api/contents?content=1&1730712558171 (10.76.5.169): No such file or directory: 
[W 2024-11-04 09:29:18.149 ServerApp] wrote error: 'No such file or directory: '
    Traceback (most recent call last):
      File "/usr/local/lib/python3.11/site-packages/tornado/web.py", line 1786, in _execute
      File "/usr/local/lib/python3.11/site-packages/jupyter_server/services/contents/handlers.py", line 121, in get
      File "/usr/local/lib/python3.11/site-packages/jupyter_core/utils/__init__.py", line 182, in ensure_async
      File "/usr/local/lib/python3.11/site-packages/jupyter_server/services/contents/filemanager.py", line 877, in get
    tornado.web.HTTPError: HTTP 404: Not Found (No such file or directory: )
[W 2024-11-04 09:29:18.150 ServerApp] 404 GET /api/contents?content=1&1730712558171 (555fb6ac53bf4e10ba9b6608c1a279b6@10.76.5.169) 2.07ms referer=http://dlc-arceus:8888/lab
[W 2024-11-04 09:29:18.167 ServerApp] 404 GET /api/contents?content=1&1730712558188 (10.76.5.169): No such file or directory: 
[W 2024-11-04 09:29:18.168 ServerApp] wrote error: 'No such file or directory: '
    Traceback (most recent call last):
      File "/usr/local/lib/python3.11/site-packages/tornado/web.py", line 1786, in _execute
      File "/usr/local/lib/python3.11/site-packages/jupyter_server/services/contents/handlers.py", line 121, in get
      File "/usr/local/lib/python3.11/site-packages/jupyter_core/utils/__init__.py", line 182, in ensure_async
      File "/usr/local/lib/python3.11/site-packages/jupyter_server/services/contents/filemanager.py", line 877, in get
    tornado.web.HTTPError: HTTP 404: Not Found (No such file or directory: )
[W 2024-11-04 09:29:18.168 ServerApp] 404 GET /api/contents?content=1&1730712558188 (555fb6ac53bf4e10ba9b6608c1a279b6@10.76.5.169) 1.66ms referer=http://dlc-arceus:8888/lab
[W 2024-11-04 09:29:18.187 ServerApp] 404 GET /api/contents?content=1&1730712558209 (10.76.5.169): No such file or directory: 
[W 2024-11-04 09:29:18.188 ServerApp] wrote error: 'No such file or directory: '
    Traceback (most recent call last):
      File "/usr/local/lib/python3.11/site-packages/tornado/web.py", line 1786, in _execute
      File "/usr/local/lib/python3.11/site-packages/jupyter_server/services/contents/handlers.py", line 121, in get
      File "/usr/local/lib/python3.11/site-packages/jupyter_core/utils/__init__.py", line 182, in ensure_async
      File "/usr/local/lib/python3.11/site-packages/jupyter_server/services/contents/filemanager.py", line 877, in get
    tornado.web.HTTPError: HTTP 404: Not Found (No such file or directory: )
[W 2024-11-04 09:29:18.189 ServerApp] 404 GET /api/contents?content=1&1730712558209 (555fb6ac53bf4e10ba9b6608c1a279b6@10.76.5.169) 2.10ms referer=http://dlc-arceus:8888/lab
[W 2024-11-04 09:29:18.208 ServerApp] 404 GET /api/contents?content=1&1730712558229 (10.76.5.169): No such file or directory: 
[W 2024-11-04 09:29:18.210 ServerApp] wrote error: 'No such file or directory: '
    Traceback (most recent call last):
      File "/usr/local/lib/python3.11/site-packages/tornado/web.py", line 1786, in _execute
      File "/usr/local/lib/python3.11/site-packages/jupyter_server/services/contents/handlers.py", line 121, in get
      File "/usr/local/lib/python3.11/site-packages/jupyter_core/utils/__init__.py", line 182, in ensure_async
      File "/usr/local/lib/python3.11/site-packages/jupyter_server/services/contents/filemanager.py", line 877, in get
    tornado.web.HTTPError: HTTP 404: Not Found (No such file or directory: )
[W 2024-11-04 09:29:18.211 ServerApp] 404 GET /api/contents?content=1&1730712558229 (555fb6ac53bf4e10ba9b6608c1a279b6@10.76.5.169) 3.13ms referer=http://dlc-arceus:8888/lab
[W 2024-11-04 09:29:18.232 ServerApp] 404 GET /api/contents?content=1&1730712558252 (10.76.5.169): No such file or directory: 
[W 2024-11-04 09:29:18.233 ServerApp] wrote error: 'No such file or directory: '
    Traceback (most recent call last):
      File "/usr/local/lib/python3.11/site-packages/tornado/web.py", line 1786, in _execute
      File "/usr/local/lib/python3.11/site-packages/jupyter_server/services/contents/handlers.py", line 121, in get
      File "/usr/local/lib/python3.11/site-packages/jupyter_core/utils/__init__.py", line 182, in ensure_async
      File "/usr/local/lib/python3.11/site-packages/jupyter_server/services/contents/filemanager.py", line 877, in get
    tornado.web.HTTPError: HTTP 404: Not Found (No such file or directory: )
[W 2024-11-04 09:29:18.234 ServerApp] 404 GET /api/contents?content=1&1730712558252 (555fb6ac53bf4e10ba9b6608c1a279b6@10.76.5.169) 1.53ms referer=http://dlc-arceus:8888/lab
